Workbook

Sheet หลักสูตร
A1: ประทับเวลา | B1: ที่อยู่อีเมล | C1: 1. ด้านวัตถุประสงค์และเนื้อหาวิชาต่างๆ | D1: 2. ด้านความสอดคล้องของเนื้อหาวิชาในหลักสูตร | E1: 3. ด้านนำความรู้ไปใช้ประโยชน์ | F1: 4. ด้านการจัดกิจกรรมต่างๆ ในหลักสูตร | G1: 5. ด้านความพร้อมในการจัดหลักสูตรผ่านสื่อ (รูปแบบ E- Learning) | H1: 6. ด้านระบบสารสนเทศ (เช่น โปรแกรม ZOOM, Google Meet, Google classroom) | I1: ข้อเสนอแนะอื่นๆ
A2: 46181.409 | B2: bnco0979@signalschool.ac.th | C2: มีความเข้าใจวัตถุประสงค์และเนื้อหาวิชาต่างๆที่บรรจุอยู่ในหลักสูตร | D2: เนื้อหาของวิชาในหลักสูตรมีความสอดคล้องกันและมีความทันสมัย | E2: ระยะเวลาในการฝึกปฏิบัติเพียงพอและสามารถนำความรู้ไปใช้ประโยชน์ในการปฏิบัติงานได้จริง | F2: การจัดกิจกรรมต่างๆ ในหลักสูตรมีความเหมาะสมอย่างมาก | G2: มีการเตรียมความพร้อมในการใช้งานระบบสารสนเทศให้แก่ผู้เรียนอย่างเหมาะสมและเพียงพอ | H2: ระบบสารสนเทศที่ใช้ในการเรียนการสอนมีความเสถียรมาก ไม่มีปัญหาในการเรียนการสอน | I2: เนื้อหาดีมาก
A3: 46181.417 | B3: bnco0909@signalschool.ac.th | C3: มีความเข้าใจวัตถุประสงค์และเนื้อหาวิชาต่างๆที่บรรจุอยู่ในหลักสูตร | D3: เนื้อหาของวิชาในหลักสูตรมีความสอดคล้องกันและมีความทันสมัย | E3: ระยะเวลาในการฝึกปฏิบัติเพียงพอและสามารถนำความรู้ไปใช้ประโยชน์ในการปฏิบัติงานได้จริง | F3: การจัดกิจกรรมต่างๆ ในหลักสูตรมีความเหมาะสมอย่างมาก | G3: มีการเตรียมความพร้อมในการใช้งานระบบสารสนเทศให้แก่ผู้เรียนอย่างเหมาะสมและเพียงพอ | H3: ระบบสารสนเทศที่ใช้ในการเรียนการสอนมีความเสถียรมาก ไม่มีปัญหาในการเรียนการสอน
A4: 46182.36 | B4: bnco0904@signalschool.ac.th | C4: มีความเข้าใจวัตถุประสงค์และเนื้อหาวิชาต่างๆที่บรรจุอยู่ในหลักสูตร | D4: เนื้อหาของวิชาในหลักสูตรมีความสอดคล้องกันและมีความทันสมัย | E4: ระยะเวลาในการฝึกปฏิบัติเพียงพอและสามารถนำความรู้ไปใช้ประโยชน์ในการปฏิบัติงานได้จริง | F4: การจัดกิจกรรมต่างๆ ในหลักสูตรมีความเหมาะสมอย่างมาก | G4: มีการเตรียมความพร้อมในการใช้งานระบบสารสนเทศให้แก่ผู้เรียนอย่างเหมาะสมและเพียงพอ | H4: ระบบสารสนเทศที่ใช้ในการเรียนการสอนมีความเสถียรมาก ไม่มีปัญหาในการเรียนการสอน
A5: 46189.427 | B5: bnco0936@signalschool.ac.th | C5: มีความเข้าใจวัตถุประสงค์และเนื้อหาวิชาต่างๆที่บรรจุอยู่ในหลักสูตร | D5: เนื้อหาของวิชาในหลักสูตรมีความสอดคล้องกันและมีความทันสมัย | E5: ระยะเวลาในการฝึกปฏิบัติเพียงพอและสามารถนำความรู้ไปใช้ประโยชน์ในการปฏิบัติงานได้จริง | F5: การจัดกิจกรรมต่างๆ ในหลักสูตรมีความเหมาะสมอย่างมาก | G5: มีการเตรียมความพร้อมในการใช้งานระบบสารสนเทศให้แก่ผู้เรียนอย่างเหมาะสมและเพียงพอ | H5: ระบบสารสนเทศที่ใช้ในการเรียนการสอนมีความเสถียร "แต่ยังมีปัญหา" ในการเรียนการสอนอยู่บ้าง
A6: 46198.058 | B6: bnco0944@signalschool.ac.th | C6: มีความเข้าใจวัตถุประสงค์และเนื้อหาวิชาต่างๆที่บรรจุอยู่ในหลักสูตร | D6: เนื้อหาของวิชาในหลักสูตรมีความสอดคล้องกันและมีความทันสมัย | E6: ระยะเวลาในการฝึกปฏิบัติเพียงพอและสามารถนำความรู้ไปใช้ประโยชน์ในการปฏิบัติงานได้จริง | F6: การจัดกิจกรรมต่างๆ ในหลักสูตรมีความเหมาะสมอย่างมาก | G6: มีการเตรียมความพร้อมในการใช้งานระบบสารสนเทศให้แก่ผู้เรียนอย่างเหมาะสมและเพียงพอ | H6: ระบบสารสนเทศที่ใช้ในการเรียนการสอนมีความเสถียรมาก ไม่มีปัญหาในการเรียนการสอน
A7: 46203.706 | B7: bnco0910@signalschool.ac.th | C7: มีความเข้าใจวัตถุประสงค์และเนื้อหาวิชาต่างๆที่บรรจุอยู่ในหลักสูตร | D7: เนื้อหาของวิชาในหลักสูตรมีความสอดคล้องกันและมีความทันสมัย | E7: ระยะเวลาในการฝึกปฏิบัติเพียงพอและสามารถนำความรู้ไปใช้ประโยชน์ในการปฏิบัติงานได้จริง | F7: การจัดกิจกรรมต่างๆ ในหลักสูตรมีความเหมาะสมอย่างมาก | G7: มีการเตรียมความพร้อมในการใช้งานระบบสารสนเทศให้แก่ผู้เรียนอย่างเหมาะสมและเพียงพอ | H7: ระบบสารสนเทศที่ใช้ในการเรียนการสอนมีความเสถียรมาก ไม่มีปัญหาในการเรียนการสอน
A8: 46206.604 | B8: bnco0920@signalschool.ac.th | C8: มีความเข้าใจวัตถุประสงค์และเนื้อหาวิชาต่างๆที่บรรจุอยู่ในหลักสูตร | D8: เนื้อหาของวิชาในหลักสูตรมีความสอดคล้องกันและมีความทันสมัย | E8: ระยะเวลาในการฝึกปฏิบัติเพียงพอและสามารถนำความรู้ไปใช้ประโยชน์ในการปฏิบัติงานได้จริง | F8: การจัดกิจกรรมต่างๆ ในหลักสูตรมีความเหมาะสมอย่างมาก | G8: มีการเตรียมความพร้อมในการใช้งานระบบสารสนเทศให้แก่ผู้เรียนอย่างเหมาะสมและเพียงพอ | H8: ระบบสารสนเทศที่ใช้ในการเรียนการสอนมีความเสถียรมาก ไม่มีปัญหาในการเรียนการสอน | I8: /
A9: 46212.595 | B9: bnco0906@signalschool.ac.th | C9: "ไม่มีความเข้าใจ" วัตถุประสงค์แต่เข้าใจเนื้อหาวิชาต่างๆที่บรรจุอยู่ในหลักสูตร | D9: เนื้อหาของวิชาในหลักสูตรมีความสอดคล้องกัน "แต่ไม่มีความทันสมัย" | E9: ระยะเวลาในการฝึกปฏิบัติ "ไม่เพียงพอ" แต่สามารถนำความรู้ไปใช้ประโยชน์ในการปฏิบัติงานได้บางส่วน | F9: การจัดกิจกรรมต่างๆ ในหลักสูตรมีความเหมาะสม | G9: มีการเตรียมความพร้อมในการใช้งานระบบสารสนเทศให้แก่ผู้เรียนอย่างเหมาะสม "แต่ไม่เพียงพอ" | H9: ระบบสารสนเทศที่ใช้ในการเรียนการสอนมีความเสถียร "แต่ยังมีปัญหา" ในการเรียนการสอนอยู่บ้าง
A10: 46212.623 | B10: bnco0955@signalschool.ac.th | C10: มีความเข้าใจวัตถุประสงค์และเนื้อหาวิชาต่างๆที่บรรจุอยู่ในหลักสูตร | D10: เนื้อหาของวิชาในหลักสูตรมีความสอดคล้องกันและมีความทันสมัย | E10: ระยะเวลาในการฝึกปฏิบัติเพียงพอและสามารถนำความรู้ไปใช้ประโยชน์ในการปฏิบัติงานได้จริง | F10: การจัดกิจกรรมต่างๆ ในหลักสูตรมีความเหมาะสมอย่างมาก | G10: มีการเตรียมความพร้อมในการใช้งานระบบสารสนเทศให้แก่ผู้เรียนอย่างเหมาะสมและเพียงพอ | H10: ระบบสารสนเทศที่ใช้ในการเรียนการสอนมีความเสถียรมาก ไม่มีปัญหาในการเรียนการสอน
A11: 46212.624 | B11: bnco0958@signalschool.ac.th | C11: มีความเข้าใจวัตถุประสงค์และเนื้อหาวิชาต่างๆที่บรรจุอยู่ในหลักสูตร | D11: เนื้อหาของวิชาในหลักสูตรมีความสอดคล้องกันและมีความทันสมัย | E11: ระยะเวลาในการฝึกปฏิบัติ "ไม่เพียงพอ" แต่สามารถนำความรู้ไปใช้ประโยชน์ในการปฏิบัติงานได้บางส่วน | F11: การจัดกิจกรรมต่างๆ ในหลักสูตรมีความเหมาะสม | G11: มีการเตรียมความพร้อมในการใช้งานระบบสารสนเทศให้แก่ผู้เรียนอย่างเหมาะสมและเพียงพอ | H11: ระบบสารสนเทศที่ใช้ในการเรียนการสอนมีความเสถียร "แต่ยังมีปัญหา" ในการเรียนการสอนอยู่บ้าง
A12: 46212.627 | B12: bnco0924@signalschool.ac.th | C12: มีความเข้าใจวัตถุประสงค์และเนื้อหาวิชาต่างๆที่บรรจุอยู่ในหลักสูตร | D12: เนื้อหาของวิชาในหลักสูตรมีความสอดคล้องกันและมีความทันสมัย | E12: ระยะเวลาในการฝึกปฏิบัติเพียงพอและสามารถนำความรู้ไปใช้ประโยชน์ในการปฏิบัติงานได้จริง | F12: การจัดกิจกรรมต่างๆ ในหลักสูตรมีความเหมาะสมอย่างมาก | G12: มีการเตรียมความพร้อมในการใช้งานระบบสารสนเทศให้แก่ผู้เรียนอย่างเหมาะสมและเพียงพอ | H12: ระบบสารสนเทศที่ใช้ในการเรียนการสอนมีความเสถียรมาก ไม่มีปัญหาในการเรียนการสอน
A13: 46212.631 | B13: bnco0926@signalschool.ac.th | C13: มีความเข้าใจวัตถุประสงค์และเนื้อหาวิชาต่างๆที่บรรจุอยู่ในหลักสูตร | D13: เนื้อหาของวิชาในหลักสูตรมีความสอดคล้องกันและมีความทันสมัย | E13: ระยะเวลาในการฝึกปฏิบัติเพียงพอและสามารถนำความรู้ไปใช้ประโยชน์ในการปฏิบัติงานได้จริง | F13: การจัดกิจกรรมต่างๆ ในหลักสูตรมีความเหมาะสมอย่างมาก | G13: มีการเตรียมความพร้อมในการใช้งานระบบสารสนเทศให้แก่ผู้เรียนอย่างเหมาะสมและเพียงพอ | H13: ระบบสารสนเทศที่ใช้ในการเรียนการสอนมีความเสถียรมาก ไม่มีปัญหาในการเรียนการสอน
A14: 46212.631 | B14: bnco0908@signalschool.ac.th | C14: มีความเข้าใจวัตถุประสงค์และเนื้อหาวิชาต่างๆที่บรรจุอยู่ในหลักสูตร | D14: เนื้อหาของวิชาในหลักสูตรมีความสอดคล้องกันและมีความทันสมัย | E14: ระยะเวลาในการฝึกปฏิบัติเพียงพอและสามารถนำความรู้ไปใช้ประโยชน์ในการปฏิบัติงานได้จริง | F14: การจัดกิจกรรมต่างๆ ในหลักสูตรมีความเหมาะสมอย่างมาก | G14: มีการเตรียมความพร้อมในการใช้งานระบบสารสนเทศให้แก่ผู้เรียนอย่างเหมาะสมและเพียงพอ | H14: ระบบสารสนเทศที่ใช้ในการเรียนการสอนมีความเสถียรมาก ไม่มีปัญหาในการเรียนการสอน
A15: 46212.632 | B15: bnco0943@signalschool.ac.th | C15: มีความเข้าใจวัตถุประสงค์และเนื้อหาวิชาต่างๆที่บรรจุอยู่ในหลักสูตร | D15: เนื้อหาของวิชาในหลักสูตรมีความสอดคล้องกันและมีความทันสมัย | E15: ระยะเวลาในการฝึกปฏิบัติเพียงพอและสามารถนำความรู้ไปใช้ประโยชน์ในการปฏิบัติงานได้จริง | F15: การจัดกิจกรรมต่างๆ ในหลักสูตรมีความเหมาะสมอย่างมาก | G15: มีการเตรียมความพร้อมในการใช้งานระบบสารสนเทศให้แก่ผู้เรียนอย่างเหมาะสมและเพียงพอ | H15: ระบบสารสนเทศที่ใช้ในการเรียนการสอนมีความเสถียรมาก ไม่มีปัญหาในการเรียนการสอน
A16: 46212.632 | B16: bnco0967@signalschool.ac.th | C16: มีความเข้าใจวัตถุประสงค์และเนื้อหาวิชาต่างๆที่บรรจุอยู่ในหลักสูตร | D16: เนื้อหาของวิชาในหลักสูตรมีความสอดคล้องกันและมีความทันสมัย | E16: ระยะเวลาในการฝึกปฏิบัติเพียงพอและสามารถนำความรู้ไปใช้ประโยชน์ในการปฏิบัติงานได้จริง | F16: การจัดกิจกรรมต่างๆ ในหลักสูตรมีความเหมาะสมอย่างมาก | G16: มีการเตรียมความพร้อมในการใช้งานระบบสารสนเทศให้แก่ผู้เรียนอย่างเหมาะสมและเพียงพอ | H16: ระบบสารสนเทศที่ใช้ในการเรียนการสอนมีความเสถียรมาก ไม่มีปัญหาในการเรียนการสอน
A17: 46212.632 | B17: bnco0978@signalschool.ac.th | C17: มีความเข้าใจวัตถุประสงค์และเนื้อหาวิชาต่างๆที่บรรจุอยู่ในหลักสูตร | D17: เนื้อหาของวิชาในหลักสูตรมีความสอดคล้องกันและมีความทันสมัย | E17: ระยะเวลาในการฝึกปฏิบัติเพียงพอและสามารถนำความรู้ไปใช้ประโยชน์ในการปฏิบัติงานได้จริง | F17: การจัดกิจกรรมต่างๆ ในหลักสูตรมีความเหมาะสมอย่างมาก | G17: มีการเตรียมความพร้อมในการใช้งานระบบสารสนเทศให้แก่ผู้เรียนอย่างเหมาะสมและเพียงพอ | H17: ระบบสารสนเทศที่ใช้ในการเรียนการสอนมีความเสถียรมาก ไม่มีปัญหาในการเรียนการสอน
A18: 46212.632 | B18: bnco0932@signalschool.ac.th | C18: มีความเข้าใจวัตถุประสงค์และเนื้อหาวิชาต่างๆที่บรรจุอยู่ในหลักสูตร | D18: เนื้อหาของวิชาในหลักสูตรมีความสอดคล้องกันและมีความทันสมัย | E18: ระยะเวลาในการฝึกปฏิบัติเพียงพอและสามารถนำความรู้ไปใช้ประโยชน์ในการปฏิบัติงานได้จริง | F18: การจัดกิจกรรมต่างๆ ในหลักสูตรมีความเหมาะสมอย่างมาก | G18: มีการเตรียมความพร้อมในการใช้งานระบบสารสนเทศให้แก่ผู้เรียนอย่างเหมาะสมและเพียงพอ | H18: ระบบสารสนเทศที่ใช้ในการเรียนการสอนมีความเสถียรมาก ไม่มีปัญหาในการเรียนการสอน
A19: 46212.632 | B19: bnco0911@signalschool.ac.th | C19: มีความเข้าใจวัตถุประสงค์และเนื้อหาวิชาต่างๆที่บรรจุอยู่ในหลักสูตร | D19: เนื้อหาของวิชาในหลักสูตรมีความสอดคล้องกันและมีความทันสมัย | E19: ระยะเวลาในการฝึกปฏิบัติเพียงพอและสามารถนำความรู้ไปใช้ประโยชน์ในการปฏิบัติงานได้จริง | F19: การจัดกิจกรรมต่างๆ ในหลักสูตรมีความเหมาะสมอย่างมาก | G19: มีการเตรียมความพร้อมในการใช้งานระบบสารสนเทศให้แก่ผู้เรียนอย่างเหมาะสมและเพียงพอ | H19: ระบบสารสนเทศที่ใช้ในการเรียนการสอนมีความเสถียรมาก ไม่มีปัญหาในการเรียนการสอน
A20: 46212.632 | B20: bnco0902@signalschool.ac.th | C20: มีความเข้าใจวัตถุประสงค์และเนื้อหาวิชาต่างๆที่บรรจุอยู่ในหลักสูตร | D20: เนื้อหาของวิชาในหลักสูตรมีความสอดคล้องกันและมีความทันสมัย | E20: ระยะเวลาในการฝึกปฏิบัติเพียงพอและสามารถนำความรู้ไปใช้ประโยชน์ในการปฏิบัติงานได้จริง | F20: การจัดกิจกรรมต่างๆ ในหลักสูตรมีความเหมาะสมอย่างมาก | G20: มีการเตรียมความพร้อมในการใช้งานระบบสารสนเทศให้แก่ผู้เรียนอย่างเหมาะสมและเพียงพอ | H20: ระบบสารสนเทศที่ใช้ในการเรียนการสอนมีความเสถียรมาก ไม่มีปัญหาในการเรียนการสอน
... A27: 46212.633 | B27: bnco0925@signalschool.ac.th | C27: มีความเข้าใจวัตถุประสงค์และเนื้อหาวิชาต่างๆที่บรรจุอยู่ในหลักสูตร | D27: เนื้อหาของวิชาในหลักสูตรมีความสอดคล้องกันและมีความทันสมัย | E27: ระยะเวลาในการฝึกปฏิบัติเพียงพอและสามารถนำความรู้ไปใช้ประโยชน์ในการปฏิบัติงานได้จริง | F27: การจัดกิจกรรมต่างๆ ในหลักสูตรมีความเหมาะสมอย่างมาก | G27: มีการเตรียมความพร้อมในการใช้งานระบบสารสนเทศให้แก่ผู้เรียนอย่างเหมาะสมและเพียงพอ | H27: ระบบสารสนเทศที่ใช้ในการเรียนการสอนมีความเสถียรมาก ไม่มีปัญหาในการเรียนการสอน
A28: 46212.633 | B28: bnco0957@signalschool.ac.th | C28: มีความเข้าใจวัตถุประสงค์และเนื้อหาวิชาต่างๆที่บรรจุอยู่ในหลักสูตร | D28: เนื้อหาของวิชาในหลักสูตรมีความสอดคล้องกันและมีความทันสมัย | E28: ระยะเวลาในการฝึกปฏิบัติเพียงพอและสามารถนำความรู้ไปใช้ประโยชน์ในการปฏิบัติงานได้จริง | F28: การจัดกิจกรรมต่างๆ ในหลักสูตรมีความเหมาะสมอย่างมาก | G28: มีการเตรียมความพร้อมในการใช้งานระบบสารสนเทศให้แก่ผู้เรียนอย่างเหมาะสมและเพียงพอ | H28: ระบบสารสนเทศที่ใช้ในการเรียนการสอนมีความเสถียรมาก ไม่มีปัญหาในการเรียนการสอน | I28: -
A29: 46212.633 | B29: bnco0970@signalschool.ac.th | C29: มีความเข้าใจวัตถุประสงค์และเนื้อหาวิชาต่างๆที่บรรจุอยู่ในหลักสูตร | D29: เนื้อหาของวิชาในหลักสูตรมีความสอดคล้องกันและมีความทันสมัย | E29: ระยะเวลาในการฝึกปฏิบัติเพียงพอและสามารถนำความรู้ไปใช้ประโยชน์ในการปฏิบัติงานได้จริง | F29: การจัดกิจกรรมต่างๆ ในหลักสูตรมีความเหมาะสมอย่างมาก | G29: มีการเตรียมความพร้อมในการใช้งานระบบสารสนเทศให้แก่ผู้เรียนอย่างเหมาะสมและเพียงพอ | H29: ระบบสารสนเทศที่ใช้ในการเรียนการสอนมีความเสถียรมาก ไม่มีปัญหาในการเรียนการสอน
A30: 46212.633 | B30: bnco0977@signalschool.ac.th | C30: มีความเข้าใจวัตถุประสงค์และเนื้อหาวิชาต่างๆที่บรรจุอยู่ในหลักสูตร | D30: เนื้อหาของวิชาในหลักสูตรมีความสอดคล้องกันและมีความทันสมัย | E30: ระยะเวลาในการฝึกปฏิบัติเพียงพอและสามารถนำความรู้ไปใช้ประโยชน์ในการปฏิบัติงานได้จริง | F30: การจัดกิจกรรมต่างๆ ในหลักสูตรมีความเหมาะสมอย่างมาก | G30: มีการเตรียมความพร้อมในการใช้งานระบบสารสนเทศให้แก่ผู้เรียนอย่างเหมาะสมและเพียงพอ | H30: ระบบสารสนเทศที่ใช้ในการเรียนการสอนมีความเสถียร "แต่ยังมีปัญหา" ในการเรียนการสอนอยู่บ้าง
A31: 46212.633 | B31: bnco0919@signalschool.ac.th | C31: "ไม่มีความเข้าใจ" วัตถุประสงค์แต่เข้าใจเนื้อหาวิชาต่างๆที่บรรจุอยู่ในหลักสูตร | D31: เนื้อหาของวิชาในหลักสูตรมีความสอดคล้องกัน "แต่ไม่มีความทันสมัย" | E31: ระยะเวลาในการฝึกปฏิบัติ "ไม่เพียงพอ" แต่สามารถนำความรู้ไปใช้ประโยชน์ในการปฏิบัติงานได้บางส่วน | F31: การจัดกิจกรรมต่างๆ ในหลักสูตรมีความเหมาะสม | G31: มีการเตรียมความพร้อมในการใช้งานระบบสารสนเทศให้แก่ผู้เรียนอย่างเหมาะสม "แต่ไม่เพียงพอ" | H31: ระบบสารสนเทศที่ใช้ในการเรียนการสอนมีความเสถียร "แต่ยังมีปัญหา" ในการเรียนการสอนอยู่บ้าง
A32: 46212.633 | B32: bnco0933@signalschool.ac.th | C32: มีความเข้าใจวัตถุประสงค์และเนื้อหาวิชาต่างๆที่บรรจุอยู่ในหลักสูตร | D32: เนื้อหาของวิชาในหลักสูตรมีความสอดคล้องกันและมีความทันสมัย | E32: ระยะเวลาในการฝึกปฏิบัติเพียงพอและสามารถนำความรู้ไปใช้ประโยชน์ในการปฏิบัติงานได้จริง | F32: การจัดกิจกรรมต่างๆ ในหลักสูตรมีความเหมาะสมอย่างมาก | G32: มีการเตรียมความพร้อมในการใช้งานระบบสารสนเทศให้แก่ผู้เรียนอย่างเหมาะสมและเพียงพอ | H32: ระบบสารสนเทศที่ใช้ในการเรียนการสอนมีความเสถียรมาก ไม่มีปัญหาในการเรียนการสอน
A33: 46212.633 | B33: bnco0937@signalschool.ac.th | C33: มีความเข้าใจวัตถุประสงค์และเนื้อหาวิชาต่างๆที่บรรจุอยู่ในหลักสูตร | D33: เนื้อหาของวิชาในหลักสูตรมีความสอดคล้องกันและมีความทันสมัย | E33: ระยะเวลาในการฝึกปฏิบัติเพียงพอและสามารถนำความรู้ไปใช้ประโยชน์ในการปฏิบัติงานได้จริง | F33: การจัดกิจกรรมต่างๆ ในหลักสูตรมีความเหมาะสมอย่างมาก | G33: มีการเตรียมความพร้อมในการใช้งานระบบสารสนเทศให้แก่ผู้เรียนอย่างเหมาะสมและเพียงพอ | H33: ระบบสารสนเทศที่ใช้ในการเรียนการสอนมีความเสถียรมาก ไม่มีปัญหาในการเรียนการสอน
A34: 46212.633 | B34: bnco0964@signalschool.ac.th | C34: มีความเข้าใจวัตถุประสงค์และเนื้อหาวิชาต่างๆที่บรรจุอยู่ในหลักสูตร | D34: เนื้อหาของวิชาในหลักสูตรมีความสอดคล้องกันและมีความทันสมัย | E34: ระยะเวลาในการฝึกปฏิบัติเพียงพอและสามารถนำความรู้ไปใช้ประโยชน์ในการปฏิบัติงานได้จริง | F34: การจัดกิจกรรมต่างๆ ในหลักสูตรมีความเหมาะสมอย่างมาก | G34: มีการเตรียมความพร้อมในการใช้งานระบบสารสนเทศให้แก่ผู้เรียนอย่างเหมาะสมและเพียงพอ | H34: ระบบสารสนเทศที่ใช้ในการเรียนการสอนมีความเสถียรมาก ไม่มีปัญหาในการเรียนการสอน
A35: 46212.633 | B35: bnco0950@signalschool.ac.th | C35: มีความเข้าใจวัตถุประสงค์และเนื้อหาวิชาต่างๆที่บรรจุอยู่ในหลักสูตร | D35: เนื้อหาของวิชาในหลักสูตรมีความสอดคล้องกันและมีความทันสมัย | E35: ระยะเวลาในการฝึกปฏิบัติเพียงพอและสามารถนำความรู้ไปใช้ประโยชน์ในการปฏิบัติงานได้จริง | F35: การจัดกิจกรรมต่างๆ ในหลักสูตรมีความเหมาะสมอย่างมาก | G35: มีการเตรียมความพร้อมในการใช้งานระบบสารสนเทศให้แก่ผู้เรียนอย่างเหมาะสมและเพียงพอ | H35: ระบบสารสนเทศที่ใช้ในการเรียนการสอนมีความเสถียรมาก ไม่มีปัญหาในการเรียนการสอน | I35: ไม่มีครับ
A36: 46212.633 | B36: bnco0963@signalschool.ac.th | C36: มีความเข้าใจวัตถุประสงค์และเนื้อหาวิชาต่างๆที่บรรจุอยู่ในหลักสูตร | D36: เนื้อหาของวิชาในหลักสูตรมีความสอดคล้องกันและมีความทันสมัย | E36: ระยะเวลาในการฝึกปฏิบัติ "ไม่เพียงพอ" แต่สามารถนำความรู้ไปใช้ประโยชน์ในการปฏิบัติงานได้บางส่วน | F36: การจัดกิจกรรมต่างๆ ในหลักสูตรมีความเหมาะสม | G36: มีการเตรียมความพร้อมในการใช้งานระบบสารสนเทศให้แก่ผู้เรียนอย่างเหมาะสมและเพียงพอ | H36: ระบบสารสนเทศที่ใช้ในการเรียนการสอนมีความเสถียร "แต่ยังมีปัญหา" ในการเรียนการสอนอยู่บ้าง
A37: 46212.633 | B37: bnco0934@signalschool.ac.th | C37: มีความเข้าใจวัตถุประสงค์และเนื้อหาวิชาต่างๆที่บรรจุอยู่ในหลักสูตร | D37: เนื้อหาของวิชาในหลักสูตรมีความสอดคล้องกันและมีความทันสมัย | E37: ระยะเวลาในการฝึกปฏิบัติเพียงพอและสามารถนำความรู้ไปใช้ประโยชน์ในการปฏิบัติงานได้จริง | F37: การจัดกิจกรรมต่างๆ ในหลักสูตรมีความเหมาะสมอย่างมาก | G37: มีการเตรียมความพร้อมในการใช้งานระบบสารสนเทศให้แก่ผู้เรียนอย่างเหมาะสมและเพียงพอ | H37: ระบบสารสนเทศที่ใช้ในการเรียนการสอนมีความเสถียรมาก ไม่มีปัญหาในการเรียนการสอน
A38: 46212.633 | B38: bnco0912@signalschool.ac.th | C38: มีความเข้าใจวัตถุประสงค์และเนื้อหาวิชาต่างๆที่บรรจุอยู่ในหลักสูตร | D38: เนื้อหาของวิชาในหลักสูตรมีความสอดคล้องกันและมีความทันสมัย | E38: ระยะเวลาในการฝึกปฏิบัติเพียงพอและสามารถนำความรู้ไปใช้ประโยชน์ในการปฏิบัติงานได้จริง | F38: การจัดกิจกรรมต่างๆ ในหลักสูตรมีความเหมาะสมอย่างมาก | G38: มีการเตรียมความพร้อมในการใช้งานระบบสารสนเทศให้แก่ผู้เรียนอย่างเหมาะสมและเพียงพอ | H38: ระบบสารสนเทศที่ใช้ในการเรียนการสอนมีความเสถียรมาก ไม่มีปัญหาในการเรียนการสอน
A39: 46212.633 | B39: bnco0941@signalschool.ac.th | C39: มีความเข้าใจวัตถุประสงค์และเนื้อหาวิชาต่างๆที่บรรจุอยู่ในหลักสูตร | D39: เนื้อหาของวิชาในหลักสูตรมีความสอดคล้องกันและมีความทันสมัย | E39: ระยะเวลาในการฝึกปฏิบัติเพียงพอและสามารถนำความรู้ไปใช้ประโยชน์ในการปฏิบัติงานได้จริง | F39: การจัดกิจกรรมต่างๆ ในหลักสูตรมีความเหมาะสมอย่างมาก | G39: มีการเตรียมความพร้อมในการใช้งานระบบสารสนเทศให้แก่ผู้เรียนอย่างเหมาะสมและเพียงพอ | H39: ระบบสารสนเทศที่ใช้ในการเรียนการสอนมีความเสถียรมาก ไม่มีปัญหาในการเรียนการสอน
A40: 46212.633 | B40: bnco0949@signalschool.ac.th | C40: มีความเข้าใจวัตถุประสงค์และเนื้อหาวิชาต่างๆที่บรรจุอยู่ในหลักสูตร | D40: เนื้อหาของวิชาในหลักสูตรมีความสอดคล้องกันและมีความทันสมัย | E40: ระยะเวลาในการฝึกปฏิบัติเพียงพอและสามารถนำความรู้ไปใช้ประโยชน์ในการปฏิบัติงานได้จริง | F40: การจัดกิจกรรมต่างๆ ในหลักสูตรมีความเหมาะสมอย่างมาก | G40: มีการเตรียมความพร้อมในการใช้งานระบบสารสนเทศให้แก่ผู้เรียนอย่างเหมาะสมและเพียงพอ | H40: ระบบสารสนเทศที่ใช้ในการเรียนการสอนมีความเสถียรมาก ไม่มีปัญหาในการเรียนการสอน
A41: 46212.633 | B41: bnco0942@signalschool.ac.th | C41: มีความเข้าใจวัตถุประสงค์และเนื้อหาวิชาต่างๆที่บรรจุอยู่ในหลักสูตร | D41: เนื้อหาของวิชาในหลักสูตรมีความสอดคล้องกันและมีความทันสมัย | E41: ระยะเวลาในการฝึกปฏิบัติเพียงพอและสามารถนำความรู้ไปใช้ประโยชน์ในการปฏิบัติงานได้จริง | F41: การจัดกิจกรรมต่างๆ ในหลักสูตรมีความเหมาะสมอย่างมาก | G41: มีการเตรียมความพร้อมในการใช้งานระบบสารสนเทศให้แก่ผู้เรียนอย่างเหมาะสมและเพียงพอ | H41: ระบบสารสนเทศที่ใช้ในการเรียนการสอนมีความเสถียรมาก ไม่มีปัญหาในการเรียนการสอน
A42: 46212.633 | B42: bnco0945@signalschool.ac.th | C42: มีความเข้าใจวัตถุประสงค์และเนื้อหาวิชาต่างๆที่บรรจุอยู่ในหลักสูตร | D42: เนื้อหาของวิชาในหลักสูตรมีความสอดคล้องกันและมีความทันสมัย | E42: ระยะเวลาในการฝึกปฏิบัติเพียงพอและสามารถนำความรู้ไปใช้ประโยชน์ในการปฏิบัติงานได้จริง | F42: การจัดกิจกรรมต่างๆ ในหลักสูตรมีความเหมาะสมอย่างมาก | G42: มีการเตรียมความพร้อมในการใช้งานระบบสารสนเทศให้แก่ผู้เรียนอย่างเหมาะสมและเพียงพอ | H42: ระบบสารสนเทศที่ใช้ในการเรียนการสอนมีความเสถียรมาก ไม่มีปัญหาในการเรียนการสอน
A43: 46212.633 | B43: bnco0918@signalschool.ac.th | C43: มีความเข้าใจวัตถุประสงค์และเนื้อหาวิชาต่างๆที่บรรจุอยู่ในหลักสูตร | D43: เนื้อหาของวิชาในหลักสูตรมีความสอดคล้องกันและมีความทันสมัย | E43: ระยะเวลาในการฝึกปฏิบัติเพียงพอและสามารถนำความรู้ไปใช้ประโยชน์ในการปฏิบัติงานได้จริง | F43: การจัดกิจกรรมต่างๆ ในหลักสูตรมีความเหมาะสมอย่างมาก | G43: มีการเตรียมความพร้อมในการใช้งานระบบสารสนเทศให้แก่ผู้เรียนอย่างเหมาะสมและเพียงพอ | H43: ระบบสารสนเทศที่ใช้ในการเรียนการสอนมีความเสถียรมาก ไม่มีปัญหาในการเรียนการสอน
A44: 46212.633 | B44: bnco0901@signalschool.ac.th | C44: มีความเข้าใจวัตถุประสงค์และเนื้อหาวิชาต่างๆที่บรรจุอยู่ในหลักสูตร | D44: เนื้อหาของวิชาในหลักสูตรมีความสอดคล้องกันและมีความทันสมัย | E44: ระยะเวลาในการฝึกปฏิบัติเพียงพอและสามารถนำความรู้ไปใช้ประโยชน์ในการปฏิบัติงานได้จริง | F44: การจัดกิจกรรมต่างๆ ในหลักสูตรมีความเหมาะสมอย่างมาก | G44: มีการเตรียมความพร้อมในการใช้งานระบบสารสนเทศให้แก่ผู้เรียนอย่างเหมาะสมและเพียงพอ | H44: ระบบสารสนเทศที่ใช้ในการเรียนการสอนมีความเสถียรมาก ไม่มีปัญหาในการเรียนการสอน
A45: 46212.633 | B45: bnco0913@signalschool.ac.th | C45: มีความเข้าใจวัตถุประสงค์และเนื้อหาวิชาต่างๆที่บรรจุอยู่ในหลักสูตร | D45: เนื้อหาของวิชาในหลักสูตรมีความสอดคล้องกัน "แต่ไม่มีความทันสมัย" | E45: ระยะเวลาในการฝึกปฏิบัติเพียงพอและสามารถนำความรู้ไปใช้ประโยชน์ในการปฏิบัติงานได้จริง | F45: การจัดกิจกรรมต่างๆ ในหลักสูตรมีความเหมาะสมอย่างมาก | G45: มีการเตรียมความพร้อมในการใช้งานระบบสารสนเทศให้แก่ผู้เรียนอย่างเหมาะสมและเพียงพอ | H45: ระบบสารสนเทศที่ใช้ในการเรียนการสอนมีความเสถียรมาก ไม่มีปัญหาในการเรียนการสอน
A46: 46212.633 | B46: bnco0966@signalschool.ac.th | C46: มีความเข้าใจวัตถุประสงค์และเนื้อหาวิชาต่างๆที่บรรจุอยู่ในหลักสูตร | D46: เนื้อหาของวิชาในหลักสูตรมีความสอดคล้องกันและมีความทันสมัย | E46: ระยะเวลาในการฝึกปฏิบัติเพียงพอและสามารถนำความรู้ไปใช้ประโยชน์ในการปฏิบัติงานได้จริง | F46: การจัดกิจกรรมต่างๆ ในหลักสูตรมีความเหมาะสมอย่างมาก | G46: มีการเตรียมความพร้อมในการใช้งานระบบสารสนเทศให้แก่ผู้เรียนอย่างเหมาะสมและเพียงพอ | H46: ระบบสารสนเทศที่ใช้ในการเรียนการสอนมีความเสถียรมาก ไม่มีปัญหาในการเรียนการสอน
...

Sheet toNum
A1: ประทับเวลา | B1: ที่อยู่อีเมล | D1: 1. ด้านวัตถุประสงค์และเนื้อหาวิชาต่างๆ | E1: 2. ด้านความสอดคล้องของเนื้อหาวิชาในหลักสูตร | F1: 3. ด้านนำความรู้ไปใช้ประโยชน์ | G1: 4. ด้านการจัดกิจกรรมต่างๆ ในหลักสูตร | H1: 5. ด้านความพร้อมในการจัดหลักสูตรผ่านสื่อ (รูปแบบ E- Learning) | I1: 6. ด้านระบบสารสนเทศ (เช่น โปรแกรม ZOOM, Google Meet, Google classroom) | K1: ตรวจสอบผู้เข้าประเมิน
A2: ='หลักสูตร'!A:A -> 46181.409 | B2: ='หลักสูตร'!B:B -> bnco0979@signalschool.ac.th | C2: 1 | D2: =IFERROR(vlookup('หลักสูตร'!C:C,lookup!$A$2:$B$4,2,false),) -> 5 | E2: =IFERROR(vlookup('หลักสูตร'!D:D,lookup!$A$6:$B$8,2,false),) -> 5 | F2: =IFERROR(vlookup('หลักสูตร'!E:E,lookup!$A$10:$B$12,2,false),) -> 5 | G2: =IFERROR(vlookup('หลักสูตร'!F:F,lookup!$A$14:$B$16,2,false),) -> 5 | H2: =IFERROR(vlookup('หลักสูตร'!G:G,lookup!$A$18:$B$20,2,false),) -> 5 | I2: =IFERROR(vlookup('หลักสูตร'!H:H,lookup!$A$22:$B$24,2,false),) -> 5 | K2: 1 | L2: =CONCAT(P2,"@signalschool.ac.th") -> bnco0901@signalschool.ac.th | M2: =IFERROR(VLOOKUP(L2,B$2:C$81,2,FALSE),0) -> 1 | P2: bnco0901
A3: ='หลักสูตร'!A:A -> 46181.417 | B3: ='หลักสูตร'!B:B -> bnco0909@signalschool.ac.th | C3: 1 | D3: =IFERROR(vlookup('หลักสูตร'!C:C,lookup!$A$2:$B$4,2,false),) -> 5 | E3: =IFERROR(vlookup('หลักสูตร'!D:D,lookup!$A$6:$B$8,2,false),) -> 5 | F3: =IFERROR(vlookup('หลักสูตร'!E:E,lookup!$A$10:$B$12,2,false),) -> 5 | G3: =IFERROR(vlookup('หลักสูตร'!F:F,lookup!$A$14:$B$16,2,false),) -> 5 | H3: =IFERROR(vlookup('หลักสูตร'!G:G,lookup!$A$18:$B$20,2,false),) -> 5 | I3: =IFERROR(vlookup('หลักสูตร'!H:H,lookup!$A$22:$B$24,2,false),) -> 5 | K3: 2 | L3: =CONCAT(P3,"@signalschool.ac.th") -> bnco0902@signalschool.ac.th | M3: =IFERROR(VLOOKUP(L3,B$2:C$81,2,FALSE),0) -> 1 | P3: bnco0902
A4: ='หลักสูตร'!A:A -> 46182.36 | B4: ='หลักสูตร'!B:B -> bnco0904@signalschool.ac.th | C4: 1 | D4: =IFERROR(vlookup('หลักสูตร'!C:C,lookup!$A$2:$B$4,2,false),) -> 5 | E4: =IFERROR(vlookup('หลักสูตร'!D:D,lookup!$A$6:$B$8,2,false),) -> 5 | F4: =IFERROR(vlookup('หลักสูตร'!E:E,lookup!$A$10:$B$12,2,false),) -> 5 | G4: =IFERROR(vlookup('หลักสูตร'!F:F,lookup!$A$14:$B$16,2,false),) -> 5 | H4: =IFERROR(vlookup('หลักสูตร'!G:G,lookup!$A$18:$B$20,2,false),) -> 5 | I4: =IFERROR(vlookup('หลักสูตร'!H:H,lookup!$A$22:$B$24,2,false),) -> 5 | K4: 3 | L4: =CONCAT(P4,"@signalschool.ac.th") -> bnco0903@signalschool.ac.th | M4: =IFERROR(VLOOKUP(L4,B$2:C$81,2,FALSE),0) -> 1 | P4: bnco0903
A5: ='หลักสูตร'!A:A -> 46189.427 | B5: ='หลักสูตร'!B:B -> bnco0936@signalschool.ac.th | C5: 1 | D5: =IFERROR(vlookup('หลักสูตร'!C:C,lookup!$A$2:$B$4,2,false),) -> 5 | E5: =IFERROR(vlookup('หลักสูตร'!D:D,lookup!$A$6:$B$8,2,false),) -> 5 | F5: =IFERROR(vlookup('หลักสูตร'!E:E,lookup!$A$10:$B$12,2,false),) -> 5 | G5: =IFERROR(vlookup('หลักสูตร'!F:F,lookup!$A$14:$B$16,2,false),) -> 5 | H5: =IFERROR(vlookup('หลักสูตร'!G:G,lookup!$A$18:$B$20,2,false),) -> 5 | I5: =IFERROR(vlookup('หลักสูตร'!H:H,lookup!$A$22:$B$24,2,false),) -> 3 | K5: 4 | L5: =CONCAT(P5,"@signalschool.ac.th") -> bnco0904@signalschool.ac.th | M5: =IFERROR(VLOOKUP(L5,B$2:C$81,2,FALSE),0) -> 1 | P5: bnco0904
A6: ='หลักสูตร'!A:A -> 46198.058 | B6: ='หลักสูตร'!B:B -> bnco0944@signalschool.ac.th | C6: 1 | D6: =IFERROR(vlookup('หลักสูตร'!C:C,lookup!$A$2:$B$4,2,false),) -> 5 | E6: =IFERROR(vlookup('หลักสูตร'!D:D,lookup!$A$6:$B$8,2,false),) -> 5 | F6: =IFERROR(vlookup('หลักสูตร'!E:E,lookup!$A$10:$B$12,2,false),) -> 5 | G6: =IFERROR(vlookup('หลักสูตร'!F:F,lookup!$A$14:$B$16,2,false),) -> 5 | H6: =IFERROR(vlookup('หลักสูตร'!G:G,lookup!$A$18:$B$20,2,false),) -> 5 | I6: =IFERROR(vlookup('หลักสูตร'!H:H,lookup!$A$22:$B$24,2,false),) -> 5 | K6: 5 | L6: =CONCAT(P6,"@signalschool.ac.th") -> bnco0905@signalschool.ac.th | M6: =IFERROR(VLOOKUP(L6,B$2:C$81,2,FALSE),0) -> 1 | P6: bnco0905
A7: ='หลักสูตร'!A:A -> 46203.706 | B7: ='หลักสูตร'!B:B -> bnco0910@signalschool.ac.th | C7: 1 | D7: =IFERROR(vlookup('หลักสูตร'!C:C,lookup!$A$2:$B$4,2,false),) -> 5 | E7: =IFERROR(vlookup('หลักสูตร'!D:D,lookup!$A$6:$B$8,2,false),) -> 5 | F7: =IFERROR(vlookup('หลักสูตร'!E:E,lookup!$A$10:$B$12,2,false),) -> 5 | G7: =IFERROR(vlookup('หลักสูตร'!F:F,lookup!$A$14:$B$16,2,false),) -> 5 | H7: =IFERROR(vlookup('หลักสูตร'!G:G,lookup!$A$18:$B$20,2,false),) -> 5 | I7: =IFERROR(vlookup('หลักสูตร'!H:H,lookup!$A$22:$B$24,2,false),) -> 5 | K7: 6 | L7: =CONCAT(P7,"@signalschool.ac.th") -> bnco0906@signalschool.ac.th | M7: =IFERROR(VLOOKUP(L7,B$2:C$81,2,FALSE),0) -> 1 | P7: bnco0906
A8: ='หลักสูตร'!A:A -> 46206.604 | B8: ='หลักสูตร'!B:B -> bnco0920@signalschool.ac.th | C8: 1 | D8: =IFERROR(vlookup('หลักสูตร'!C:C,lookup!$A$2:$B$4,2,false),) -> 5 | E8: =IFERROR(vlookup('หลักสูตร'!D:D,lookup!$A$6:$B$8,2,false),) -> 5 | F8: =IFERROR(vlookup('หลักสูตร'!E:E,lookup!$A$10:$B$12,2,false),) -> 5 | G8: =IFERROR(vlookup('หลักสูตร'!F:F,lookup!$A$14:$B$16,2,false),) -> 5 | H8: =IFERROR(vlookup('หลักสูตร'!G:G,lookup!$A$18:$B$20,2,false),) -> 5 | I8: =IFERROR(vlookup('หลักสูตร'!H:H,lookup!$A$22:$B$24,2,false),) -> 5 | K8: 7 | L8: =CONCAT(P8,"@signalschool.ac.th") -> bnco0907@signalschool.ac.th | M8: =IFERROR(VLOOKUP(L8,B$2:C$81,2,FALSE),0) -> 1 | P8: bnco0907
A9: ='หลักสูตร'!A:A -> 46212.595 | B9: ='หลักสูตร'!B:B -> bnco0906@signalschool.ac.th | C9: 1 | D9: =IFERROR(vlookup('หลักสูตร'!C:C,lookup!$A$2:$B$4,2,false),) -> 3 | E9: =IFERROR(vlookup('หลักสูตร'!D:D,lookup!$A$6:$B$8,2,false),) -> 3 | F9: =IFERROR(vlookup('หลักสูตร'!E:E,lookup!$A$10:$B$12,2,false),) -> 3 | G9: =IFERROR(vlookup('หลักสูตร'!F:F,lookup!$A$14:$B$16,2,false),) -> 3 | H9: =IFERROR(vlookup('หลักสูตร'!G:G,lookup!$A$18:$B$20,2,false),) -> 3 | I9: =IFERROR(vlookup('หลักสูตร'!H:H,lookup!$A$22:$B$24,2,false),) -> 3 | K9: 8 | L9: =CONCAT(P9,"@signalschool.ac.th") -> bnco0908@signalschool.ac.th | M9: =IFERROR(VLOOKUP(L9,B$2:C$81,2,FALSE),0) -> 1 | P9: bnco0908
A10: ='หลักสูตร'!A:A -> 46212.623 | B10: ='หลักสูตร'!B:B -> bnco0955@signalschool.ac.th | C10: 1 | D10: =IFERROR(vlookup('หลักสูตร'!C:C,lookup!$A$2:$B$4,2,false),) -> 5 | E10: =IFERROR(vlookup('หลักสูตร'!D:D,lookup!$A$6:$B$8,2,false),) -> 5 | F10: =IFERROR(vlookup('หลักสูตร'!E:E,lookup!$A$10:$B$12,2,false),) -> 5 | G10: =IFERROR(vlookup('หลักสูตร'!F:F,lookup!$A$14:$B$16,2,false),) -> 5 | H10: =IFERROR(vlookup('หลักสูตร'!G:G,lookup!$A$18:$B$20,2,false),) -> 5 | I10: =IFERROR(vlookup('หลักสูตร'!H:H,lookup!$A$22:$B$24,2,false),) -> 5 | K10: 9 | L10: =CONCAT(P10,"@signalschool.ac.th") -> bnco0909@signalschool.ac.th | M10: =IFERROR(VLOOKUP(L10,B$2:C$81,2,FALSE),0) -> 1 | P10: bnco0909
A11: ='หลักสูตร'!A:A -> 46212.624 | B11: ='หลักสูตร'!B:B -> bnco0958@signalschool.ac.th | C11: 1 | D11: =IFERROR(vlookup('หลักสูตร'!C:C,lookup!$A$2:$B$4,2,false),) -> 5 | E11: =IFERROR(vlookup('หลักสูตร'!D:D,lookup!$A$6:$B$8,2,false),) -> 5 | F11: =IFERROR(vlookup('หลักสูตร'!E:E,lookup!$A$10:$B$12,2,false),) -> 3 | G11: =IFERROR(vlookup('หลักสูตร'!F:F,lookup!$A$14:$B$16,2,false),) -> 3 | H11: =IFERROR(vlookup('หลักสูตร'!G:G,lookup!$A$18:$B$20,2,false),) -> 5 | I11: =IFERROR(vlookup('หลักสูตร'!H:H,lookup!$A$22:$B$24,2,false),) -> 3 | K11: 10 | L11: =CONCAT(P11,"@signalschool.ac.th") -> bnco0910@signalschool.ac.th | M11: =IFERROR(VLOOKUP(L11,B$2:C$81,2,FALSE),0) -> 1 | P11: bnco0910
A12: ='หลักสูตร'!A:A -> 46212.627 | B12: ='หลักสูตร'!B:B -> bnco0924@signalschool.ac.th | C12: 1 | D12: =IFERROR(vlookup('หลักสูตร'!C:C,lookup!$A$2:$B$4,2,false),) -> 5 | E12: =IFERROR(vlookup('หลักสูตร'!D:D,lookup!$A$6:$B$8,2,false),) -> 5 | F12: =IFERROR(vlookup('หลักสูตร'!E:E,lookup!$A$10:$B$12,2,false),) -> 5 | G12: =IFERROR(vlookup('หลักสูตร'!F:F,lookup!$A$14:$B$16,2,false),) -> 5 | H12: =IFERROR(vlookup('หลักสูตร'!G:G,lookup!$A$18:$B$20,2,false),) -> 5 | I12: =IFERROR(vlookup('หลักสูตร'!H:H,lookup!$A$22:$B$24,2,false),) -> 5 | K12: 11 | L12: =CONCAT(P12,"@signalschool.ac.th") -> bnco0911@signalschool.ac.th | M12: =IFERROR(VLOOKUP(L12,B$2:C$81,2,FALSE),0) -> 1 | P12: bnco0911
A13: ='หลักสูตร'!A:A -> 46212.631 | B13: ='หลักสูตร'!B:B -> bnco0926@signalschool.ac.th | C13: 1 | D13: =IFERROR(vlookup('หลักสูตร'!C:C,lookup!$A$2:$B$4,2,false),) -> 5 | E13: =IFERROR(vlookup('หลักสูตร'!D:D,lookup!$A$6:$B$8,2,false),) -> 5 | F13: =IFERROR(vlookup('หลักสูตร'!E:E,lookup!$A$10:$B$12,2,false),) -> 5 | G13: =IFERROR(vlookup('หลักสูตร'!F:F,lookup!$A$14:$B$16,2,false),) -> 5 | H13: =IFERROR(vlookup('หลักสูตร'!G:G,lookup!$A$18:$B$20,2,false),) -> 5 | I13: =IFERROR(vlookup('หลักสูตร'!H:H,lookup!$A$22:$B$24,2,false),) -> 5 | K13: 12 | L13: =CONCAT(P13,"@signalschool.ac.th") -> bnco0912@signalschool.ac.th | M13: =IFERROR(VLOOKUP(L13,B$2:C$81,2,FALSE),0) -> 1 | P13: bnco0912
... A80: ='หลักสูตร'!A:A | B80: ='หลักสูตร'!B:B | C80: 1 | D80: =IFERROR(vlookup('หลักสูตร'!C:C,lookup!$A$2:$B$4,2,false),) | E80: =IFERROR(vlookup('หลักสูตร'!D:D,lookup!$A$6:$B$8,2,false),) | F80: =IFERROR(vlookup('หลักสูตร'!E:E,lookup!$A$10:$B$12,2,false),) | G80: =IFERROR(vlookup('หลักสูตร'!F:F,lookup!$A$14:$B$16,2,false),) | H80: =IFERROR(vlookup('หลักสูตร'!G:G,lookup!$A$18:$B$20,2,false),) | I80: =IFERROR(vlookup('หลักสูตร'!H:H,lookup!$A$22:$B$24,2,false),) | K80: 79 | L80: =CONCAT(P80,"@signalschool.ac.th") -> bnco0979@signalschool.ac.th | M80: =IFERROR(VLOOKUP(L80,B$2:C$81,2,FALSE),0) -> 1 | P80: bnco0979
A81: ='หลักสูตร'!A:A | B81: ='หลักสูตร'!B:B | C81: 1 | D81: =IFERROR(vlookup('หลักสูตร'!C:C,lookup!$A$2:$B$4,2,false),) | E81: =IFERROR(vlookup('หลักสูตร'!D:D,lookup!$A$6:$B$8,2,false),) | F81: =IFERROR(vlookup('หลักสูตร'!E:E,lookup!$A$10:$B$12,2,false),) | G81: =IFERROR(vlookup('หลักสูตร'!F:F,lookup!$A$14:$B$16,2,false),) | H81: =IFERROR(vlookup('หลักสูตร'!G:G,lookup!$A$18:$B$20,2,false),) | I81: =IFERROR(vlookup('หลักสูตร'!H:H,lookup!$A$22:$B$24,2,false),) | J81: เฉลี่ยรวม | K81: 80 | L81: =CONCAT(P81,"@signalschool.ac.th") -> bnco0980@signalschool.ac.th | M81: =IFERROR(VLOOKUP(L81,B$2:C$81,2,FALSE),0) -> 1 | P81: bnco0980
A82: ค่าเฉลี่ย | D82: =iferror(AVERAGE(D2:D81),"") -> 4.9142857 | E82: =iferror(AVERAGE(E2:E81),"") -> 4.8571429 | F82: =iferror(AVERAGE(F2:F81),"") -> 4.7714286 | G82: =iferror(AVERAGE(G2:G81),"") -> 4.8 | H82: =iferror(AVERAGE(H2:H81),"") -> 4.9142857 | I82: =iferror(AVERAGE(I2:I81),"") -> 4.6857143 | J82: =iferror(AVERAGE(D82:I82),"") -> 4.8238095 | L82: ยอดผู้เข้าประเมิน | M82: =SUM(M2:M81) -> 70
L83: ภาพรวมร้อยละ | M83: =(M82*100)/80 -> 87.5

Sheet lookup
A2: มีความเข้าใจวัตถุประสงค์และเนื้อหาวิชาต่างๆที่บรรจุอยู่ในหลักสูตร | B2: 5
A3: "ไม่มีความเข้าใจ" วัตถุประสงค์แต่เข้าใจเนื้อหาวิชาต่างๆที่บรรจุอยู่ในหลักสูตร | B3: 3
A4: "ไม่มีความเข้าใจ" วัตถุประสงค์และ "ไม่เข้าใจ" เนื้อหาวิชาต่างๆที่บรรจุอยู่ในหลักสูตร | B4: 1
A6: เนื้อหาของวิชาในหลักสูตรมีความสอดคล้องกันและมีความทันสมัย | B6: 5
A7: เนื้อหาของวิชาในหลักสูตรมีความสอดคล้องกัน "แต่ไม่มีความทันสมัย" | B7: 3
A8: เนื้อหาของวิชาในหลักสูตร "ไม่มีความสอดคล้องกัน" และ "ไม่มีความทันสมัย" | B8: 1
A10: ระยะเวลาในการฝึกปฏิบัติเพียงพอและสามารถนำความรู้ไปใช้ประโยชน์ในการปฏิบัติงานได้จริง | B10: 5
A11: ระยะเวลาในการฝึกปฏิบัติ "ไม่เพียงพอ" แต่สามารถนำความรู้ไปใช้ประโยชน์ในการปฏิบัติงานได้บางส่วน | B11: 3
A12: ระยะเวลาในการฝึกปฏิบัติ "ไม่เพียงพอ" และ "ไม่สามารถนำความรู้ไปใช้ประโยชน์" ในการปฏิบัติงานได้จริง | B12: 1
A14: การจัดกิจกรรมต่างๆ ในหลักสูตรมีความเหมาะสมอย่างมาก | B14: 5
A15: การจัดกิจกรรมต่างๆ ในหลักสูตรมีความเหมาะสม | B15: 3
A16: การจัดกิจกรรมต่างๆ ในหลักสูตรไม่มีความเหมาะสม | B16: 1
... A24: ระบบสารสนเทศที่ใช้ในการเรียนการสอนไม่มีความเสถียร ควรได้รับการปรับปรุง | B24: 1
