Workbook

Sheet 1.1
A1: ประทับเวลา | B1: ที่อยู่อีเมล | C1: ยศ ชื่อ-สกุล ครู-อาจารย์ผู้สอน | D1: 1. บุคลิกภาพและลักษณะท่าทางของอาจารย์ผู้สอน | E1: 2. การพูดและการใช้นํ้าเสียง | F1: 3. การเตรียมการสอน | G1: 4. การจัดเตรียมสื่อการสอน | H1: 5. การถ่ายทอดความรู้และการนำเข้าสู่บทเรียน | I1: 6. ผู้เรียนได้ฝึกทักษะการคิดวิเคราะห์ หรือการพัฒนาความคิดสร้างสรรค์จากการเรียนรายวิชานี้มากน้อยเพียงใด | J1: 7. ผู้เรียนได้ฝึกทักษะการสื่อสาร การนำเสนอ และการใช้งานเทคโนโลยีสารสนเทศจากการเรียนรายวิชานี้มากน้อยเพียงใด | K1: ข้อเสนอแนะอื่นๆ
A2: 46262.41 | B2: bnco1013@signalschool.ac.th | C2: ส.อ.ไชยพร รักษากุล | D2: ลักษณะทางทหาร "ดีมาก" มีความเชื่อมั่นในตนเองเป็นแบบอย่างที่ดีแก่ผู้เรียนได้ | E2: เสียงดังฟังชัดและจังหวะการพูดไม่ช้า/เร็วเกินไป | F2: มีประมวลรายวิชาและแนะนำเนื้อหาวิชา | G2: มีการจัดเตรียมสื่อการเรียนการสอนและรวบรวมแหล่งอ้างอิงไว้อย่างเหมาะสม | H2: มีการจัดการเรียนการสอนเป็นไปตามประมวลรายวิชาครบถ้วนและการนำเข้าสู่บทเรียนให้ข้อมูลที่เป็นประโยชน์แก่ผู้เรียนครบถ้วน | I2: มีการส่งเสริมให้ผู้เรียนได้ฝึกทักษะการคิดได้อย่างเหมาะสมดีมาก | J2: มีการส่งเสริมให้ผู้เรียนได้ฝึกทักษะการสื่อสารได้อย่างเหมาะสมดีมาก
A3: 46262.412 | B3: bnco1058@signalschool.ac.th | C3: ส.อ.ไชยพร รักษากุล | D3: ลักษณะทางทหาร "ดีมาก" มีความเชื่อมั่นในตนเองเป็นแบบอย่างที่ดีแก่ผู้เรียนได้ | E3: เสียงดังฟังชัดและจังหวะการพูดไม่ช้า/เร็วเกินไป | F3: มีประมวลรายวิชาและแนะนำเนื้อหาวิชา | G3: มีการจัดเตรียมสื่อการเรียนการสอนและรวบรวมแหล่งอ้างอิงไว้อย่างเหมาะสม | H3: มีการจัดการเรียนการสอนเป็นไปตามประมวลรายวิชาครบถ้วนและการนำเข้าสู่บทเรียนให้ข้อมูลที่เป็นประโยชน์แก่ผู้เรียนครบถ้วน | I3: มีการส่งเสริมให้ผู้เรียนได้ฝึกทักษะการคิดได้อย่างเหมาะสมดีมาก | J3: มีการส่งเสริมให้ผู้เรียนได้ฝึกทักษะการสื่อสารได้อย่างเหมาะสมดีมาก
A4: 46262.415 | B4: bnco1009@signalschool.ac.th | C4: ส.อ.ไชยพร รักษากุล | D4: ลักษณะทางทหาร "ดีมาก" มีความเชื่อมั่นในตนเองเป็นแบบอย่างที่ดีแก่ผู้เรียนได้ | E4: เสียงดังฟังชัดและจังหวะการพูดไม่ช้า/เร็วเกินไป | F4: มีประมวลรายวิชาและแนะนำเนื้อหาวิชา | G4: มีการจัดเตรียมสื่อการเรียนการสอนและรวบรวมแหล่งอ้างอิงไว้อย่างเหมาะสม | H4: มีการจัดการเรียนการสอนเป็นไปตามประมวลรายวิชาครบถ้วนและการนำเข้าสู่บทเรียนให้ข้อมูลที่เป็นประโยชน์แก่ผู้เรียนครบถ้วน | I4: มีการส่งเสริมให้ผู้เรียนได้ฝึกทักษะการคิดได้อย่างเหมาะสมดีมาก | J4: มีการส่งเสริมให้ผู้เรียนได้ฝึกทักษะการสื่อสารได้อย่างเหมาะสมดีมาก
A5: 46262.416 | B5: bnco1056@signalschool.ac.th | C5: ร.ท.ศุภรัชฏ หมอกสุข | D5: ลักษณะทางทหาร "ดีมาก" มีความเชื่อมั่นในตนเองเป็นแบบอย่างที่ดีแก่ผู้เรียนได้ | E5: เสียงดังฟังชัดและจังหวะการพูดไม่ช้า/เร็วเกินไป | F5: มีประมวลรายวิชาและแนะนำเนื้อหาวิชา | G5: มีการจัดเตรียมสื่อการเรียนการสอนและรวบรวมแหล่งอ้างอิงไว้อย่างเหมาะสม | H5: มีการจัดการเรียนการสอนเป็นไปตามประมวลรายวิชาครบถ้วนและการนำเข้าสู่บทเรียนให้ข้อมูลที่เป็นประโยชน์แก่ผู้เรียนครบถ้วน | I5: มีการส่งเสริมให้ผู้เรียนได้ฝึกทักษะการคิดได้อย่างเหมาะสมดีมาก | J5: มีการส่งเสริมให้ผู้เรียนได้ฝึกทักษะการสื่อสารได้อย่างเหมาะสมดีมาก
A6: 46262.422 | B6: bnco1062@signalschool.ac.th | C6: ส.อ.ไชยพร รักษากุล | D6: ลักษณะทางทหาร "ดีมาก" มีความเชื่อมั่นในตนเองเป็นแบบอย่างที่ดีแก่ผู้เรียนได้ | E6: เสียงดังฟังชัดและจังหวะการพูดไม่ช้า/เร็วเกินไป | F6: มีประมวลรายวิชาและแนะนำเนื้อหาวิชา | G6: มีการจัดเตรียมสื่อการเรียนการสอนและรวบรวมแหล่งอ้างอิงไว้อย่างเหมาะสม | H6: มีการจัดการเรียนการสอนเป็นไปตามประมวลรายวิชาครบถ้วนและการนำเข้าสู่บทเรียนให้ข้อมูลที่เป็นประโยชน์แก่ผู้เรียนครบถ้วน | I6: มีการส่งเสริมให้ผู้เรียนได้ฝึกทักษะการคิดได้อย่างเหมาะสมดีมาก | J6: มีการส่งเสริมให้ผู้เรียนได้ฝึกทักษะการสื่อสารได้อย่างเหมาะสมดีมาก
A7: 46262.425 | B7: bnco1041@signalschool.ac.th | C7: พ.ต.ไมตรี บุญเหลื่อม | D7: ลักษณะทางทหาร "ดีมาก" มีความเชื่อมั่นในตนเองเป็นแบบอย่างที่ดีแก่ผู้เรียนได้ | E7: เสียงดังฟังชัดและจังหวะการพูดไม่ช้า/เร็วเกินไป | F7: มีประมวลรายวิชาและแนะนำเนื้อหาวิชา | G7: มีการจัดเตรียมสื่อการเรียนการสอนและรวบรวมแหล่งอ้างอิงไว้อย่างเหมาะสม | H7: มีการจัดการเรียนการสอนเป็นไปตามประมวลรายวิชาครบถ้วนและการนำเข้าสู่บทเรียนให้ข้อมูลที่เป็นประโยชน์แก่ผู้เรียนครบถ้วน | I7: มีการส่งเสริมให้ผู้เรียนได้ฝึกทักษะการคิดได้อย่างเหมาะสมดีมาก | J7: มีการส่งเสริมให้ผู้เรียนได้ฝึกทักษะการสื่อสารได้อย่างเหมาะสมดีมาก | K7: ขอบคุณมากครับ สำหรับความรู้ที่อาจารย์มอบให้ครับ ^_^
A8: 46262.434 | B8: bnco1012@signalschool.ac.th | C8: ร.ท.ศุภรัชฏ หมอกสุข | D8: ลักษณะทางทหาร "ดีมาก" มีความเชื่อมั่นในตนเองเป็นแบบอย่างที่ดีแก่ผู้เรียนได้ | E8: เสียงดังฟังชัดและจังหวะการพูดไม่ช้า/เร็วเกินไป | F8: มีประมวลรายวิชาและแนะนำเนื้อหาวิชา | G8: มีการจัดเตรียมสื่อการเรียนการสอนและรวบรวมแหล่งอ้างอิงไว้อย่างเหมาะสม | H8: มีการจัดการเรียนการสอนเป็นไปตามประมวลรายวิชาครบถ้วนและการนำเข้าสู่บทเรียนให้ข้อมูลที่เป็นประโยชน์แก่ผู้เรียนครบถ้วน | I8: มีการส่งเสริมให้ผู้เรียนได้ฝึกทักษะการคิดได้อย่างเหมาะสมดีมาก | J8: มีการส่งเสริมให้ผู้เรียนได้ฝึกทักษะการสื่อสารได้อย่างเหมาะสมดีมาก | K8: ไม่มี
A9: 46262.436 | B9: bnco1006@signalschool.ac.th | C9: ร.ท.ศุภรัชฎ หมอกสุข | D9: ลักษณะทางทหาร "ดีมาก" มีความเชื่อมั่นในตนเองเป็นแบบอย่างที่ดีแก่ผู้เรียนได้ | E9: เสียงดังฟังชัดและจังหวะการพูดไม่ช้า/เร็วเกินไป | F9: มีประมวลรายวิชาและแนะนำเนื้อหาวิชา | G9: มีการจัดเตรียมสื่อการเรียนการสอนและรวบรวมแหล่งอ้างอิงไว้อย่างเหมาะสม | H9: มีการจัดการเรียนการสอนเป็นไปตามประมวลรายวิชาครบถ้วนและการนำเข้าสู่บทเรียนให้ข้อมูลที่เป็นประโยชน์แก่ผู้เรียนครบถ้วน | I9: มีการส่งเสริมให้ผู้เรียนได้ฝึกทักษะการคิดได้อย่างเหมาะสมดีมาก | J9: มีการส่งเสริมให้ผู้เรียนได้ฝึกทักษะการสื่อสารได้อย่างเหมาะสมดีมาก
A10: 46262.441 | B10: bnco1051@signalschool.ac.th | C10: ร.อ.สุพจน์ มงคล | D10: ลักษณะทางทหาร "ดีมาก" มีความเชื่อมั่นในตนเองเป็นแบบอย่างที่ดีแก่ผู้เรียนได้ | E10: เสียงดังฟังชัดและจังหวะการพูดไม่ช้า/เร็วเกินไป | F10: มีประมวลรายวิชาและแนะนำเนื้อหาวิชา | G10: มีการจัดเตรียมสื่อการเรียนการสอนและรวบรวมแหล่งอ้างอิงไว้อย่างเหมาะสม | H10: มีการจัดการเรียนการสอนเป็นไปตามประมวลรายวิชาครบถ้วนและการนำเข้าสู่บทเรียนให้ข้อมูลที่เป็นประโยชน์แก่ผู้เรียนครบถ้วน | I10: มีการส่งเสริมให้ผู้เรียนได้ฝึกทักษะการคิดได้อย่างเหมาะสมดีมาก | J10: มีการส่งเสริมให้ผู้เรียนได้ฝึกทักษะการสื่อสารได้อย่างเหมาะสมดีมาก
A11: 46262.441 | B11: bnco1050@signalschool.ac.th | C11: ร.อ.สุพจน์ มงคล | D11: ลักษณะทางทหาร "ดีมาก" มีความเชื่อมั่นในตนเองเป็นแบบอย่างที่ดีแก่ผู้เรียนได้ | E11: เสียงดังฟังชัดและจังหวะการพูดไม่ช้า/เร็วเกินไป | F11: มีประมวลรายวิชาและแนะนำเนื้อหาวิชา | G11: มีการจัดเตรียมสื่อการเรียนการสอนและรวบรวมแหล่งอ้างอิงไว้อย่างเหมาะสม | H11: มีการจัดการเรียนการสอนเป็นไปตามประมวลรายวิชาครบถ้วนและการนำเข้าสู่บทเรียนให้ข้อมูลที่เป็นประโยชน์แก่ผู้เรียนครบถ้วน | I11: มีการส่งเสริมให้ผู้เรียนได้ฝึกทักษะการคิดได้อย่างเหมาะสมดีมาก | J11: มีการส่งเสริมให้ผู้เรียนได้ฝึกทักษะการสื่อสารได้อย่างเหมาะสมดีมาก
A12: 46262.442 | B12: bnco1052@signalschool.ac.th | C12: ร.ท.ศุภรัชฎ หมอกสุข | D12: ลักษณะทางทหาร "ดีมาก" มีความเชื่อมั่นในตนเองเป็นแบบอย่างที่ดีแก่ผู้เรียนได้ | E12: เสียงดังฟังชัดและจังหวะการพูดไม่ช้า/เร็วเกินไป | F12: มีประมวลรายวิชาและแนะนำเนื้อหาวิชา | G12: มีการจัดเตรียมสื่อการเรียนการสอนและรวบรวมแหล่งอ้างอิงไว้อย่างเหมาะสม | H12: มีการจัดการเรียนการสอนเป็นไปตามประมวลรายวิชาครบถ้วนและการนำเข้าสู่บทเรียนให้ข้อมูลที่เป็นประโยชน์แก่ผู้เรียนครบถ้วน | I12: มีการส่งเสริมให้ผู้เรียนได้ฝึกทักษะการคิดได้อย่างเหมาะสมดีมาก | J12: มีการส่งเสริมให้ผู้เรียนได้ฝึกทักษะการสื่อสารได้อย่างเหมาะสมดีมาก
A13: 46262.444 | B13: bnco1018@signalschool.ac.th | C13: ร.ท.ศุภรัชฎ หมอกสุข | D13: ลักษณะทางทหาร "ดีมาก" มีความเชื่อมั่นในตนเองเป็นแบบอย่างที่ดีแก่ผู้เรียนได้ | E13: เสียงดังฟังชัดและจังหวะการพูดไม่ช้า/เร็วเกินไป | F13: มีประมวลรายวิชาและแนะนำเนื้อหาวิชา | G13: มีการจัดเตรียมสื่อการเรียนการสอนและรวบรวมแหล่งอ้างอิงไว้อย่างเหมาะสม | H13: มีการจัดการเรียนการสอนเป็นไปตามประมวลรายวิชาครบถ้วนและการนำเข้าสู่บทเรียนให้ข้อมูลที่เป็นประโยชน์แก่ผู้เรียนครบถ้วน | I13: มีการส่งเสริมให้ผู้เรียนได้ฝึกทักษะการคิดได้อย่างเหมาะสมดีมาก | J13: มีการส่งเสริมให้ผู้เรียนได้ฝึกทักษะการสื่อสารได้อย่างเหมาะสมดีมาก | K13: ไม่มีครับ
A14: 46262.449 | B14: bnco1038@signalschool.ac.th | C14: ร.ท.ศุภรัชฎ หมอกสุข | D14: ลักษณะทางทหาร "ดีมาก" มีความเชื่อมั่นในตนเองเป็นแบบอย่างที่ดีแก่ผู้เรียนได้ | E14: เสียงดังฟังชัดและจังหวะการพูดไม่ช้า/เร็วเกินไป | F14: มีประมวลรายวิชาและแนะนำเนื้อหาวิชา | G14: มีการจัดเตรียมสื่อการเรียนการสอนและรวบรวมแหล่งอ้างอิงไว้อย่างเหมาะสม | H14: มีการจัดการเรียนการสอนเป็นไปตามประมวลรายวิชาครบถ้วนและการนำเข้าสู่บทเรียนให้ข้อมูลที่เป็นประโยชน์แก่ผู้เรียนครบถ้วน | I14: มีการส่งเสริมให้ผู้เรียนได้ฝึกทักษะการคิดได้อย่างเหมาะสมดีมาก | J14: มีการส่งเสริมให้ผู้เรียนได้ฝึกทักษะการสื่อสารได้อย่างเหมาะสมดีมาก | K14: อาจารย์สอนดี เน้นย้ำในส่วนสำคัญให้เข้าใจมากขึ้น
A15: 46262.45 | B15: bnco1035@signalschool.ac.th | C15: ร.ท.ศุภรัชฎ หมอกสุข | D15: ลักษณะทางทหาร "ดีมาก" มีความเชื่อมั่นในตนเองเป็นแบบอย่างที่ดีแก่ผู้เรียนได้ | E15: เสียงดังฟังชัดและจังหวะการพูดไม่ช้า/เร็วเกินไป | F15: มีประมวลรายวิชาและแนะนำเนื้อหาวิชา | G15: มีการจัดเตรียมสื่อการเรียนการสอนและรวบรวมแหล่งอ้างอิงไว้อย่างเหมาะสม | H15: มีการจัดการเรียนการสอนเป็นไปตามประมวลรายวิชาครบถ้วนและการนำเข้าสู่บทเรียนให้ข้อมูลที่เป็นประโยชน์แก่ผู้เรียนครบถ้วน | I15: มีการส่งเสริมให้ผู้เรียนได้ฝึกทักษะการคิดได้อย่างเหมาะสมดีมาก | J15: มีการส่งเสริมให้ผู้เรียนได้ฝึกทักษะการสื่อสารได้อย่างเหมาะสมดีมาก
A16: 46262.452 | B16: bnco1070@signalschool.ac.th | C16: พ.ต.ไมตรี บุญเหลี่ยม | D16: ลักษณะทางทหาร "ดีมาก" มีความเชื่อมั่นในตนเองเป็นแบบอย่างที่ดีแก่ผู้เรียนได้ | E16: เสียงดังฟังชัดและจังหวะการพูดไม่ช้า/เร็วเกินไป | F16: มีประมวลรายวิชา "แต่ไม่มีการ" แนะนำเนื้อหาวิชา | G16: มีการจัดเตรียมสื่อการเรียนการสอน "แต่ไม่ปรากฏ" แหล่งอ้างอิง | H16: มีการจัดการเรียนการสอนเป็นไปตามประมวลรายวิชาครบถ้วนและการนำเข้าสู่บทเรียนให้ข้อมูลที่เป็นประโยชน์แก่ผู้เรียนครบถ้วน | I16: มีการส่งเสริมให้ผู้เรียนได้ฝึกทักษะการคิดได้อย่างเหมาะสม | J16: มีการส่งเสริมให้ผู้เรียนได้ฝึกทักษะการสื่อสารได้อย่างเหมาะสม
A17: 46262.457 | B17: bnco1036@signalschool.ac.th | C17: ร.ท.ศุภรัชฎ หมอกสุข | D17: ลักษณะทางทหาร "ดีมาก" มีความเชื่อมั่นในตนเองเป็นแบบอย่างที่ดีแก่ผู้เรียนได้ | E17: เสียงดังฟังชัดและจังหวะการพูดไม่ช้า/เร็วเกินไป | F17: มีประมวลรายวิชาและแนะนำเนื้อหาวิชา | G17: มีการจัดเตรียมสื่อการเรียนการสอนและรวบรวมแหล่งอ้างอิงไว้อย่างเหมาะสม | H17: มีการจัดการเรียนการสอนเป็นไปตามประมวลรายวิชาครบถ้วนและการนำเข้าสู่บทเรียนให้ข้อมูลที่เป็นประโยชน์แก่ผู้เรียนครบถ้วน | I17: มีการส่งเสริมให้ผู้เรียนได้ฝึกทักษะการคิดได้อย่างเหมาะสมดีมาก | J17: มีการส่งเสริมให้ผู้เรียนได้ฝึกทักษะการสื่อสารได้อย่างเหมาะสมดีมาก
A18: 46262.459 | B18: bnco1042@signalschool.ac.th | C18: ร.ท.ศุภรัชฎ หมอกสุข | D18: ลักษณะทางทหาร "ดีมาก" มีความเชื่อมั่นในตนเองเป็นแบบอย่างที่ดีแก่ผู้เรียนได้ | E18: เสียงดังฟังชัดและจังหวะการพูดไม่ช้า/เร็วเกินไป | F18: มีประมวลรายวิชาและแนะนำเนื้อหาวิชา | G18: มีการจัดเตรียมสื่อการเรียนการสอนและรวบรวมแหล่งอ้างอิงไว้อย่างเหมาะสม | H18: มีการจัดการเรียนการสอนเป็นไปตามประมวลรายวิชาครบถ้วนและการนำเข้าสู่บทเรียนให้ข้อมูลที่เป็นประโยชน์แก่ผู้เรียนครบถ้วน | I18: มีการส่งเสริมให้ผู้เรียนได้ฝึกทักษะการคิดได้อย่างเหมาะสมดีมาก | J18: มีการส่งเสริมให้ผู้เรียนได้ฝึกทักษะการสื่อสารได้อย่างเหมาะสมดีมาก
A19: 46262.463 | B19: bnco1003@signalschool.ac.th | C19: ร.ท.ศุภรัชฎ หมอกสุข | D19: ลักษณะทางทหาร "ดีมาก" มีความเชื่อมั่นในตนเองเป็นแบบอย่างที่ดีแก่ผู้เรียนได้ | E19: เสียงดังฟังชัดและจังหวะการพูดไม่ช้า/เร็วเกินไป | F19: มีประมวลรายวิชาและแนะนำเนื้อหาวิชา | G19: มีการจัดเตรียมสื่อการเรียนการสอนและรวบรวมแหล่งอ้างอิงไว้อย่างเหมาะสม | H19: มีการจัดการเรียนการสอนเป็นไปตามประมวลรายวิชาครบถ้วนและการนำเข้าสู่บทเรียนให้ข้อมูลที่เป็นประโยชน์แก่ผู้เรียนครบถ้วน | I19: มีการส่งเสริมให้ผู้เรียนได้ฝึกทักษะการคิดได้อย่างเหมาะสมดีมาก | J19: มีการส่งเสริมให้ผู้เรียนได้ฝึกทักษะการสื่อสารได้อย่างเหมาะสมดีมาก
A20: 46262.466 | B20: bnco1079@signalschool.ac.th | C20: ร.ท.ศุภรัชฎ หมอกสุข | D20: ลักษณะทางทหาร "ดีมาก" มีความเชื่อมั่นในตนเองเป็นแบบอย่างที่ดีแก่ผู้เรียนได้ | E20: เสียงดังฟังชัดและจังหวะการพูดไม่ช้า/เร็วเกินไป | F20: มีประมวลรายวิชาและแนะนำเนื้อหาวิชา | G20: มีการจัดเตรียมสื่อการเรียนการสอนและรวบรวมแหล่งอ้างอิงไว้อย่างเหมาะสม | H20: มีการจัดการเรียนการสอนเป็นไปตามประมวลรายวิชาครบถ้วนและการนำเข้าสู่บทเรียนให้ข้อมูลที่เป็นประโยชน์แก่ผู้เรียนครบถ้วน | I20: มีการส่งเสริมให้ผู้เรียนได้ฝึกทักษะการคิดได้อย่างเหมาะสมดีมาก | J20: มีการส่งเสริมให้ผู้เรียนได้ฝึกทักษะการสื่อสารได้อย่างเหมาะสมดีมาก
A21: 46262.481 | B21: bnco1032@signalschool.ac.th | C21: ร.ท.ศุภรัชฏ หมอกสุข | D21: ลักษณะทางทหาร "ดีมาก" มีความเชื่อมั่นในตนเองเป็นแบบอย่างที่ดีแก่ผู้เรียนได้ | E21: เสียงดังฟังชัดและจังหวะการพูดไม่ช้า/เร็วเกินไป | F21: มีประมวลรายวิชาและแนะนำเนื้อหาวิชา | G21: มีการจัดเตรียมสื่อการเรียนการสอนและรวบรวมแหล่งอ้างอิงไว้อย่างเหมาะสม | H21: มีการจัดการเรียนการสอนเป็นไปตามประมวลรายวิชาครบถ้วนและการนำเข้าสู่บทเรียนให้ข้อมูลที่เป็นประโยชน์แก่ผู้เรียนครบถ้วน | I21: มีการส่งเสริมให้ผู้เรียนได้ฝึกทักษะการคิดได้อย่างเหมาะสมดีมาก | J21: มีการส่งเสริมให้ผู้เรียนได้ฝึกทักษะการสื่อสารได้อย่างเหมาะสมดีมาก | K21: อาจาร์ยสอนเข้าใจง่ายดีครับ
A22: 46262.486 | B22: bnco1060@signalschool.ac.th | C22: ร.ท.ศุภรัฎ หมอกสุข | D22: ลักษณะทางทหาร "ดีมาก" มีความเชื่อมั่นในตนเองเป็นแบบอย่างที่ดีแก่ผู้เรียนได้ | E22: เสียงดังฟังชัดและจังหวะการพูดไม่ช้า/เร็วเกินไป | F22: มีประมวลรายวิชาและแนะนำเนื้อหาวิชา | G22: มีการจัดเตรียมสื่อการเรียนการสอนและรวบรวมแหล่งอ้างอิงไว้อย่างเหมาะสม | H22: มีการจัดการเรียนการสอนเป็นไปตามประมวลรายวิชาครบถ้วนและการนำเข้าสู่บทเรียนให้ข้อมูลที่เป็นประโยชน์แก่ผู้เรียนครบถ้วน | I22: มีการส่งเสริมให้ผู้เรียนได้ฝึกทักษะการคิดได้อย่างเหมาะสมดีมาก | J22: มีการส่งเสริมให้ผู้เรียนได้ฝึกทักษะการสื่อสารได้อย่างเหมาะสมดีมาก | K22: สอนเข้าใจมากครับ
A23: 46262.494 | B23: bnco1031@signalschool.ac.th | C23: ร.ท. ศุภรัชฎ หมอกสุข | D23: ลักษณะทางทหาร "ดีมาก" มีความเชื่อมั่นในตนเองเป็นแบบอย่างที่ดีแก่ผู้เรียนได้ | E23: เสียงดังฟังชัดและจังหวะการพูดไม่ช้า/เร็วเกินไป | F23: มีประมวลรายวิชาและแนะนำเนื้อหาวิชา | G23: มีการจัดเตรียมสื่อการเรียนการสอนและรวบรวมแหล่งอ้างอิงไว้อย่างเหมาะสม | H23: มีการจัดการเรียนการสอนเป็นไปตามประมวลรายวิชาครบถ้วนและการนำเข้าสู่บทเรียนให้ข้อมูลที่เป็นประโยชน์แก่ผู้เรียนครบถ้วน | I23: มีการส่งเสริมให้ผู้เรียนได้ฝึกทักษะการคิดได้อย่างเหมาะสมดีมาก | J23: มีการส่งเสริมให้ผู้เรียนได้ฝึกทักษะการสื่อสารได้อย่างเหมาะสมดีมาก
A24: 46262.499 | B24: bnco1063@signalschool.ac.th | C24: ร.ท.ศุภรัชฎ หมอกสุข | D24: ลักษณะทางทหาร "ดีมาก" มีความเชื่อมั่นในตนเองเป็นแบบอย่างที่ดีแก่ผู้เรียนได้ | E24: เสียงดังฟังชัดและจังหวะการพูดไม่ช้า/เร็วเกินไป | F24: มีประมวลรายวิชาและแนะนำเนื้อหาวิชา | G24: มีการจัดเตรียมสื่อการเรียนการสอนและรวบรวมแหล่งอ้างอิงไว้อย่างเหมาะสม | H24: มีการจัดการเรียนการสอนเป็นไปตามประมวลรายวิชาครบถ้วนและการนำเข้าสู่บทเรียนให้ข้อมูลที่เป็นประโยชน์แก่ผู้เรียนครบถ้วน | I24: มีการส่งเสริมให้ผู้เรียนได้ฝึกทักษะการคิดได้อย่างเหมาะสมดีมาก | J24: มีการส่งเสริมให้ผู้เรียนได้ฝึกทักษะการสื่อสารได้อย่างเหมาะสมดีมาก
A25: 46262.521 | B25: bnco1066@signalschool.ac.th | C25: ร.ท.ศุภรัชฎ หมอกสุข | D25: ลักษณะทางทหาร "ดีมาก" มีความเชื่อมั่นในตนเองเป็นแบบอย่างที่ดีแก่ผู้เรียนได้ | E25: เสียงดังฟังชัดและจังหวะการพูดไม่ช้า/เร็วเกินไป | F25: มีประมวลรายวิชาและแนะนำเนื้อหาวิชา | G25: มีการจัดเตรียมสื่อการเรียนการสอนและรวบรวมแหล่งอ้างอิงไว้อย่างเหมาะสม | H25: มีการจัดการเรียนการสอนเป็นไปตามประมวลรายวิชาครบถ้วนและการนำเข้าสู่บทเรียนให้ข้อมูลที่เป็นประโยชน์แก่ผู้เรียนครบถ้วน | I25: มีการส่งเสริมให้ผู้เรียนได้ฝึกทักษะการคิดได้อย่างเหมาะสมดีมาก | J25: มีการส่งเสริมให้ผู้เรียนได้ฝึกทักษะการสื่อสารได้อย่างเหมาะสมดีมาก
A26: 46262.528 | B26: bnco1069@signalschool.ac.th | C26: ร.ท.ศุภรัชฎ หมอกสุข | D26: ลักษณะทางทหาร "ดีมาก" มีความเชื่อมั่นในตนเองเป็นแบบอย่างที่ดีแก่ผู้เรียนได้ | E26: เสียงดังฟังชัดและจังหวะการพูดไม่ช้า/เร็วเกินไป | F26: มีประมวลรายวิชาและแนะนำเนื้อหาวิชา | G26: มีการจัดเตรียมสื่อการเรียนการสอนและรวบรวมแหล่งอ้างอิงไว้อย่างเหมาะสม | H26: มีการจัดการเรียนการสอนเป็นไปตามประมวลรายวิชาครบถ้วนและการนำเข้าสู่บทเรียนให้ข้อมูลที่เป็นประโยชน์แก่ผู้เรียนครบถ้วน | I26: มีการส่งเสริมให้ผู้เรียนได้ฝึกทักษะการคิดได้อย่างเหมาะสมดีมาก | J26: มีการส่งเสริมให้ผู้เรียนได้ฝึกทักษะการสื่อสารได้อย่างเหมาะสมดีมาก
A27: 46262.552 | B27: bnco1044@signalschool.ac.th | C27: ร.ท. ศุภรัชฏ หมอกสุข | D27: ลักษณะทางทหาร "ดีมาก" มีความเชื่อมั่นในตนเองเป็นแบบอย่างที่ดีแก่ผู้เรียนได้ | E27: เสียงดังฟังชัดและจังหวะการพูดไม่ช้า/เร็วเกินไป | F27: มีประมวลรายวิชาและแนะนำเนื้อหาวิชา | G27: มีการจัดเตรียมสื่อการเรียนการสอนและรวบรวมแหล่งอ้างอิงไว้อย่างเหมาะสม | H27: มีการจัดการเรียนการสอนเป็นไปตามประมวลรายวิชาครบถ้วนและการนำเข้าสู่บทเรียนให้ข้อมูลที่เป็นประโยชน์แก่ผู้เรียนครบถ้วน | I27: มีการส่งเสริมให้ผู้เรียนได้ฝึกทักษะการคิดได้อย่างเหมาะสมดีมาก | J27: มีการส่งเสริมให้ผู้เรียนได้ฝึกทักษะการสื่อสารได้อย่างเหมาะสมดีมาก
A28: 46262.553 | B28: bnco1068@signalschool.ac.th | C28: ร.ท.ศุภรัชฎ หมอกสุข | D28: ลักษณะทางทหาร "ดีมาก" มีความเชื่อมั่นในตนเองเป็นแบบอย่างที่ดีแก่ผู้เรียนได้ | E28: เสียงดังฟังชัดและจังหวะการพูดไม่ช้า/เร็วเกินไป | F28: มีประมวลรายวิชาและแนะนำเนื้อหาวิชา | G28: มีการจัดเตรียมสื่อการเรียนการสอนและรวบรวมแหล่งอ้างอิงไว้อย่างเหมาะสม | H28: มีการจัดการเรียนการสอนเป็นไปตามประมวลรายวิชาครบถ้วนและการนำเข้าสู่บทเรียนให้ข้อมูลที่เป็นประโยชน์แก่ผู้เรียนครบถ้วน | I28: มีการส่งเสริมให้ผู้เรียนได้ฝึกทักษะการคิดได้อย่างเหมาะสมดีมาก | J28: มีการส่งเสริมให้ผู้เรียนได้ฝึกทักษะการสื่อสารได้อย่างเหมาะสมดีมาก
A29: 46262.558 | B29: bnco1049@signalschool.ac.th | C29: ร.ท.ศุภรัชฎ หมอกสุข | D29: ลักษณะทางทหาร "ดีมาก" มีความเชื่อมั่นในตนเองเป็นแบบอย่างที่ดีแก่ผู้เรียนได้ | E29: เสียงดังฟังชัดและจังหวะการพูดไม่ช้า/เร็วเกินไป | F29: มีประมวลรายวิชาและแนะนำเนื้อหาวิชา | G29: มีการจัดเตรียมสื่อการเรียนการสอนและรวบรวมแหล่งอ้างอิงไว้อย่างเหมาะสม | H29: มีการจัดการเรียนการสอนเป็นไปตามประมวลรายวิชาครบถ้วนและการนำเข้าสู่บทเรียนให้ข้อมูลที่เป็นประโยชน์แก่ผู้เรียนครบถ้วน | I29: มีการส่งเสริมให้ผู้เรียนได้ฝึกทักษะการคิดได้อย่างเหมาะสมดีมาก | J29: มีการส่งเสริมให้ผู้เรียนได้ฝึกทักษะการสื่อสารได้อย่างเหมาะสมดีมาก
A30: 46262.559 | B30: bnco1008@signalschool.ac.th | C30: ร.ท.ศุภรัชฎ หมอกสุข | D30: ลักษณะทางทหาร "ดีมาก" มีความเชื่อมั่นในตนเองเป็นแบบอย่างที่ดีแก่ผู้เรียนได้ | E30: เสียงดังฟังชัดและจังหวะการพูดไม่ช้า/เร็วเกินไป | F30: มีประมวลรายวิชาและแนะนำเนื้อหาวิชา | G30: มีการจัดเตรียมสื่อการเรียนการสอนและรวบรวมแหล่งอ้างอิงไว้อย่างเหมาะสม | H30: มีการจัดการเรียนการสอนเป็นไปตามประมวลรายวิชาครบถ้วนและการนำเข้าสู่บทเรียนให้ข้อมูลที่เป็นประโยชน์แก่ผู้เรียนครบถ้วน | I30: มีการส่งเสริมให้ผู้เรียนได้ฝึกทักษะการคิดได้อย่างเหมาะสมดีมาก | J30: มีการส่งเสริมให้ผู้เรียนได้ฝึกทักษะการสื่อสารได้อย่างเหมาะสมดีมาก
A31: 46262.569 | B31: bnco1022@signalschool.ac.th | C31: ร.ท.ศุภรัชฏ หมอกสุข | D31: ลักษณะทางทหาร "ดีมาก" มีความเชื่อมั่นในตนเองเป็นแบบอย่างที่ดีแก่ผู้เรียนได้ | E31: เสียงดังฟังชัดและจังหวะการพูดไม่ช้า/เร็วเกินไป | F31: มีประมวลรายวิชาและแนะนำเนื้อหาวิชา | G31: มีการจัดเตรียมสื่อการเรียนการสอนและรวบรวมแหล่งอ้างอิงไว้อย่างเหมาะสม | H31: มีการจัดการเรียนการสอนเป็นไปตามประมวลรายวิชาครบถ้วนและการนำเข้าสู่บทเรียนให้ข้อมูลที่เป็นประโยชน์แก่ผู้เรียนครบถ้วน | I31: มีการส่งเสริมให้ผู้เรียนได้ฝึกทักษะการคิดได้อย่างเหมาะสมดีมาก | J31: มีการส่งเสริมให้ผู้เรียนได้ฝึกทักษะการสื่อสารได้อย่างเหมาะสมดีมาก | K31: อาจาร์สอนเข้าใจง่ายครับ
A32: 46262.577 | B32: bnco1005@signalschool.ac.th | C32: ร.ท.ศุภรัชฏ หมอกสุข | D32: ลักษณะทางทหาร "ดีมาก" มีความเชื่อมั่นในตนเองเป็นแบบอย่างที่ดีแก่ผู้เรียนได้ | E32: เสียงดังฟังชัดและจังหวะการพูดไม่ช้า/เร็วเกินไป | F32: มีประมวลรายวิชาและแนะนำเนื้อหาวิชา | G32: มีการจัดเตรียมสื่อการเรียนการสอนและรวบรวมแหล่งอ้างอิงไว้อย่างเหมาะสม | H32: มีการจัดการเรียนการสอนเป็นไปตามประมวลรายวิชาครบถ้วนและการนำเข้าสู่บทเรียนให้ข้อมูลที่เป็นประโยชน์แก่ผู้เรียนครบถ้วน | I32: มีการส่งเสริมให้ผู้เรียนได้ฝึกทักษะการคิดได้อย่างเหมาะสมดีมาก | J32: มีการส่งเสริมให้ผู้เรียนได้ฝึกทักษะการสื่อสารได้อย่างเหมาะสมดีมาก
A33: 46262.577 | B33: bnco1067@signalschool.ac.th | C33: ร.ท.ศุภรัชฏ หมอกสุข | D33: ลักษณะทางทหาร "ดีมาก" มีความเชื่อมั่นในตนเองเป็นแบบอย่างที่ดีแก่ผู้เรียนได้ | E33: เสียงดังฟังชัดและจังหวะการพูดไม่ช้า/เร็วเกินไป | F33: มีประมวลรายวิชาและแนะนำเนื้อหาวิชา | G33: มีการจัดเตรียมสื่อการเรียนการสอนและรวบรวมแหล่งอ้างอิงไว้อย่างเหมาะสม | H33: มีการจัดการเรียนการสอนเป็นไปตามประมวลรายวิชาครบถ้วนและการนำเข้าสู่บทเรียนให้ข้อมูลที่เป็นประโยชน์แก่ผู้เรียนครบถ้วน | I33: มีการส่งเสริมให้ผู้เรียนได้ฝึกทักษะการคิดได้อย่างเหมาะสมดีมาก | J33: มีการส่งเสริมให้ผู้เรียนได้ฝึกทักษะการสื่อสารได้อย่างเหมาะสมดีมาก
A34: 46262.586 | B34: bnco1039@signalschool.ac.th | C34: ร.ท.ศุภรัชฎ หมอกสุข | D34: ลักษณะทางทหาร "ดีมาก" มีความเชื่อมั่นในตนเองเป็นแบบอย่างที่ดีแก่ผู้เรียนได้ | E34: เสียงดังฟังชัดและจังหวะการพูดไม่ช้า/เร็วเกินไป | F34: มีประมวลรายวิชา "แต่ไม่มีการ" แนะนำเนื้อหาวิชา | G34: มีการจัดเตรียมสื่อการเรียนการสอนและรวบรวมแหล่งอ้างอิงไว้อย่างเหมาะสม | H34: มีการจัดการเรียนการสอนเป็นไปตามประมวลรายวิชาครบถ้วนและการนำเข้าสู่บทเรียนให้ข้อมูลที่เป็นประโยชน์แก่ผู้เรียนครบถ้วน | I34: มีการส่งเสริมให้ผู้เรียนได้ฝึกทักษะการคิดได้อย่างเหมาะสมดีมาก | J34: มีการส่งเสริมให้ผู้เรียนได้ฝึกทักษะการสื่อสารได้อย่างเหมาะสมดีมาก
A35: 46262.591 | B35: bnco1045@signalschool.ac.th | C35: ร.ท.ศุภรัชฎ หมอกสุข | D35: ลักษณะทางทหาร "มีความเหมาะสม" มีความเชื่อมั่นในตนเองปานกลาง | E35: เสียงดังฟังชัดและจังหวะการพูดไม่ช้า/เร็วเกินไป | F35: มีประมวลรายวิชาและแนะนำเนื้อหาวิชา | G35: มีการจัดเตรียมสื่อการเรียนการสอนและรวบรวมแหล่งอ้างอิงไว้อย่างเหมาะสม | H35: มีการจัดการเรียนการสอนเป็นไปตามประมวลรายวิชาบางส่วน "หรือ" การนำเข้าสู่บทเรียนให้ข้อมูลที่เป็นประโยชน์แก่ผู้เรียน (อย่างใดอย่างหนึ่ง) | I35: มีการส่งเสริมให้ผู้เรียนได้ฝึกทักษะการคิดได้อย่างเหมาะสมดีมาก | J35: มีการส่งเสริมให้ผู้เรียนได้ฝึกทักษะการสื่อสารได้อย่างเหมาะสมดีมาก
A36: 46262.61 | B36: bnco1080@signalschool.ac.th | C36: ร.ท.ศุภรัฐ หมอกสุข | D36: ลักษณะทางทหาร "ดีมาก" มีความเชื่อมั่นในตนเองเป็นแบบอย่างที่ดีแก่ผู้เรียนได้ | E36: เสียงดังฟังชัดและจังหวะการพูดไม่ช้า/เร็วเกินไป | F36: มีประมวลรายวิชาและแนะนำเนื้อหาวิชา | G36: มีการจัดเตรียมสื่อการเรียนการสอนและรวบรวมแหล่งอ้างอิงไว้อย่างเหมาะสม | H36: มีการจัดการเรียนการสอนเป็นไปตามประมวลรายวิชาครบถ้วนและการนำเข้าสู่บทเรียนให้ข้อมูลที่เป็นประโยชน์แก่ผู้เรียนครบถ้วน | I36: มีการส่งเสริมให้ผู้เรียนได้ฝึกทักษะการคิดได้อย่างเหมาะสมดีมาก | J36: มีการส่งเสริมให้ผู้เรียนได้ฝึกทักษะการสื่อสารได้อย่างเหมาะสมดีมาก
A37: 46262.625 | B37: bnco1064@signalschool.ac.th | C37: ร.ท.ศุภรัชฏ หมอกสุข | D37: ลักษณะทางทหาร "ดีมาก" มีความเชื่อมั่นในตนเองเป็นแบบอย่างที่ดีแก่ผู้เรียนได้ | E37: เสียงดังฟังชัดและจังหวะการพูดไม่ช้า/เร็วเกินไป | F37: มีประมวลรายวิชาและแนะนำเนื้อหาวิชา | G37: มีการจัดเตรียมสื่อการเรียนการสอนและรวบรวมแหล่งอ้างอิงไว้อย่างเหมาะสม | H37: มีการจัดการเรียนการสอนเป็นไปตามประมวลรายวิชาครบถ้วนและการนำเข้าสู่บทเรียนให้ข้อมูลที่เป็นประโยชน์แก่ผู้เรียนครบถ้วน | I37: มีการส่งเสริมให้ผู้เรียนได้ฝึกทักษะการคิดได้อย่างเหมาะสมดีมาก | J37: มีการส่งเสริมให้ผู้เรียนได้ฝึกทักษะการสื่อสารได้อย่างเหมาะสมดีมาก | K37: -
A38: 46262.642 | B38: bnco1021@signalschool.ac.th | C38: ร.ท.ศุภรัชฎ หมอกสุข | D38: ลักษณะทางทหาร "ดีมาก" มีความเชื่อมั่นในตนเองเป็นแบบอย่างที่ดีแก่ผู้เรียนได้ | E38: เสียงดังฟังชัดและจังหวะการพูดไม่ช้า/เร็วเกินไป | F38: มีประมวลรายวิชาและแนะนำเนื้อหาวิชา | G38: มีการจัดเตรียมสื่อการเรียนการสอนและรวบรวมแหล่งอ้างอิงไว้อย่างเหมาะสม | H38: มีการจัดการเรียนการสอนเป็นไปตามประมวลรายวิชาครบถ้วนและการนำเข้าสู่บทเรียนให้ข้อมูลที่เป็นประโยชน์แก่ผู้เรียนครบถ้วน | I38: มีการส่งเสริมให้ผู้เรียนได้ฝึกทักษะการคิดได้อย่างเหมาะสมดีมาก | J38: มีการส่งเสริมให้ผู้เรียนได้ฝึกทักษะการสื่อสารได้อย่างเหมาะสมดีมาก
A39: 46262.643 | B39: bnco1027@signalschool.ac.th | C39: ร.ท.ศุภรัชฏ หมอกสุข | D39: ลักษณะทางทหาร "ดีมาก" มีความเชื่อมั่นในตนเองเป็นแบบอย่างที่ดีแก่ผู้เรียนได้ | E39: เสียงดังฟังชัดและจังหวะการพูดไม่ช้า/เร็วเกินไป | F39: มีประมวลรายวิชาและแนะนำเนื้อหาวิชา | G39: มีการจัดเตรียมสื่อการเรียนการสอนและรวบรวมแหล่งอ้างอิงไว้อย่างเหมาะสม | H39: มีการจัดการเรียนการสอนเป็นไปตามประมวลรายวิชาครบถ้วนและการนำเข้าสู่บทเรียนให้ข้อมูลที่เป็นประโยชน์แก่ผู้เรียนครบถ้วน | I39: มีการส่งเสริมให้ผู้เรียนได้ฝึกทักษะการคิดได้อย่างเหมาะสมดีมาก | J39: มีการส่งเสริมให้ผู้เรียนได้ฝึกทักษะการสื่อสารได้อย่างเหมาะสมดีมาก | K39: -
A40: 46262.737 | B40: bnco1072@signalschool.ac.th | C40: ร.ท.ศุภรัชฎ หมอกสุข | D40: ลักษณะทางทหาร "ดีมาก" มีความเชื่อมั่นในตนเองเป็นแบบอย่างที่ดีแก่ผู้เรียนได้ | E40: เสียงดังฟังชัดและจังหวะการพูดไม่ช้า/เร็วเกินไป | F40: มีประมวลรายวิชาและแนะนำเนื้อหาวิชา | G40: มีการจัดเตรียมสื่อการเรียนการสอนและรวบรวมแหล่งอ้างอิงไว้อย่างเหมาะสม | H40: มีการจัดการเรียนการสอนเป็นไปตามประมวลรายวิชาครบถ้วนและการนำเข้าสู่บทเรียนให้ข้อมูลที่เป็นประโยชน์แก่ผู้เรียนครบถ้วน | I40: มีการส่งเสริมให้ผู้เรียนได้ฝึกทักษะการคิดได้อย่างเหมาะสมดีมาก | J40: มีการส่งเสริมให้ผู้เรียนได้ฝึกทักษะการสื่อสารได้อย่างเหมาะสมดีมาก
...

Sheet ค่า 1.1
A1: ประทับเวลา | B1: ที่อยู่อีเมล | C1: ยศ ชื่อ-สกุล ครู-อาจารย์ผู้สอน | E1: 1. บุคลิกภาพและลักษณะท่าทางของอาจารย์ผู้สอน | F1: 2. การพูดและการใช้นํ้าเสียง | G1: 3. การเตรียมการสอน | H1: 4. การจัดเตรียมสื่อการสอน | I1: 5. การถ่ายทอดความรู้และการนำเข้าสู่บทเรียน | J1: 6. ผู้เรียนได้ฝึกทักษะการคิดวิเคราะห์ หรือการพัฒนาความคิดสร้างสรรค์จากการเรียนรายวิชานี้มากน้อยเพียงใด | K1: 7. ผู้เรียนได้ฝึกทักษะการสื่อสาร การนำเสนอ และการใช้งานเทคโนโลยีสารสนเทศจากการเรียนรายวิชานี้มากน้อยเพียงใด | M1: ตรวจสอบผู้เข้าประเมิน
A2: ='1.1'!A:A -> 46262.41 | B2: ='1.1'!B:B -> bnco1013@signalschool.ac.th | C2: ='1.1'!C:C -> ส.อ.ไชยพร รักษากุล | D2: 1 | E2: =IFERROR(vlookup('1.1'!D:D,lookup!$A$2:$B$4,2,false),0) -> 5 | F2: =IFERROR(vlookup('1.1'!E:E,lookup!$A$6:$B$8,2,false),0) -> 5 | G2: =IFERROR(vlookup('1.1'!F:F,lookup!$A$10:$B$12,2,false),0) -> 5 | H2: =IFERROR(vlookup('1.1'!G:G,lookup!$A$14:$B$16,2,false),0) -> 5 | I2: =IFERROR(vlookup('1.1'!H:H,lookup!$A$18:$B$20,2,false),0) -> 5 | J2: =IFERROR(vlookup('1.1'!I:I,lookup!$A$22:$B$24,2,false),0) -> 5 | K2: =IFERROR(vlookup('1.1'!J:J,lookup!$A$26:$B$28,2,false),0) -> 5 | M2: 1 | N2: =CONCAT(R2,"@signalschool.ac.th") -> bnco1001@signalschool.ac.th | O2: =IFERROR(VLOOKUP(N2,B$2:D$81,3,FALSE),0) -> 1 | R2: bnco1001
A3: ='1.1'!A:A -> 46262.412 | B3: ='1.1'!B:B -> bnco1058@signalschool.ac.th | C3: ='1.1'!C:C -> ส.อ.ไชยพร รักษากุล | D3: 1 | E3: =IFERROR(vlookup('1.1'!D:D,lookup!$A$2:$B$4,2,false),0) -> 5 | F3: =IFERROR(vlookup('1.1'!E:E,lookup!$A$6:$B$8,2,false),0) -> 5 | G3: =IFERROR(vlookup('1.1'!F:F,lookup!$A$10:$B$12,2,false),0) -> 5 | H3: =IFERROR(vlookup('1.1'!G:G,lookup!$A$14:$B$16,2,false),0) -> 5 | I3: =IFERROR(vlookup('1.1'!H:H,lookup!$A$18:$B$20,2,false),0) -> 5 | J3: =IFERROR(vlookup('1.1'!I:I,lookup!$A$22:$B$24,2,false),0) -> 5 | K3: =IFERROR(vlookup('1.1'!J:J,lookup!$A$26:$B$28,2,false),0) -> 5 | M3: 2 | N3: =CONCAT(R3,"@signalschool.ac.th") -> bnco1002@signalschool.ac.th | O3: =IFERROR(VLOOKUP(N3,B$2:D$81,3,FALSE),0) -> 1 | R3: bnco1002
A4: ='1.1'!A:A -> 46262.415 | B4: ='1.1'!B:B -> bnco1009@signalschool.ac.th | C4: ='1.1'!C:C -> ส.อ.ไชยพร รักษากุล | D4: 1 | E4: =IFERROR(vlookup('1.1'!D:D,lookup!$A$2:$B$4,2,false),0) -> 5 | F4: =IFERROR(vlookup('1.1'!E:E,lookup!$A$6:$B$8,2,false),0) -> 5 | G4: =IFERROR(vlookup('1.1'!F:F,lookup!$A$10:$B$12,2,false),0) -> 5 | H4: =IFERROR(vlookup('1.1'!G:G,lookup!$A$14:$B$16,2,false),0) -> 5 | I4: =IFERROR(vlookup('1.1'!H:H,lookup!$A$18:$B$20,2,false),0) -> 5 | J4: =IFERROR(vlookup('1.1'!I:I,lookup!$A$22:$B$24,2,false),0) -> 5 | K4: =IFERROR(vlookup('1.1'!J:J,lookup!$A$26:$B$28,2,false),0) -> 5 | M4: 3 | N4: =CONCAT(R4,"@signalschool.ac.th") -> bnco1003@signalschool.ac.th | O4: =IFERROR(VLOOKUP(N4,B$2:D$81,3,FALSE),0) -> 1 | R4: bnco1003
A5: ='1.1'!A:A -> 46262.416 | B5: ='1.1'!B:B -> bnco1056@signalschool.ac.th | C5: ='1.1'!C:C -> ร.ท.ศุภรัชฏ หมอกสุข | D5: 1 | E5: =IFERROR(vlookup('1.1'!D:D,lookup!$A$2:$B$4,2,false),0) -> 5 | F5: =IFERROR(vlookup('1.1'!E:E,lookup!$A$6:$B$8,2,false),0) -> 5 | G5: =IFERROR(vlookup('1.1'!F:F,lookup!$A$10:$B$12,2,false),0) -> 5 | H5: =IFERROR(vlookup('1.1'!G:G,lookup!$A$14:$B$16,2,false),0) -> 5 | I5: =IFERROR(vlookup('1.1'!H:H,lookup!$A$18:$B$20,2,false),0) -> 5 | J5: =IFERROR(vlookup('1.1'!I:I,lookup!$A$22:$B$24,2,false),0) -> 5 | K5: =IFERROR(vlookup('1.1'!J:J,lookup!$A$26:$B$28,2,false),0) -> 5 | M5: 4 | N5: =CONCAT(R5,"@signalschool.ac.th") -> bnco1004@signalschool.ac.th | O5: =IFERROR(VLOOKUP(N5,B$2:D$81,3,FALSE),0) -> 1 | R5: bnco1004
A6: ='1.1'!A:A -> 46262.422 | B6: ='1.1'!B:B -> bnco1062@signalschool.ac.th | C6: ='1.1'!C:C -> ส.อ.ไชยพร รักษากุล | D6: 1 | E6: =IFERROR(vlookup('1.1'!D:D,lookup!$A$2:$B$4,2,false),0) -> 5 | F6: =IFERROR(vlookup('1.1'!E:E,lookup!$A$6:$B$8,2,false),0) -> 5 | G6: =IFERROR(vlookup('1.1'!F:F,lookup!$A$10:$B$12,2,false),0) -> 5 | H6: =IFERROR(vlookup('1.1'!G:G,lookup!$A$14:$B$16,2,false),0) -> 5 | I6: =IFERROR(vlookup('1.1'!H:H,lookup!$A$18:$B$20,2,false),0) -> 5 | J6: =IFERROR(vlookup('1.1'!I:I,lookup!$A$22:$B$24,2,false),0) -> 5 | K6: =IFERROR(vlookup('1.1'!J:J,lookup!$A$26:$B$28,2,false),0) -> 5 | M6: 5 | N6: =CONCAT(R6,"@signalschool.ac.th") -> bnco1005@signalschool.ac.th | O6: =IFERROR(VLOOKUP(N6,B$2:D$81,3,FALSE),0) -> 1 | R6: bnco1005
A7: ='1.1'!A:A -> 46262.425 | B7: ='1.1'!B:B -> bnco1041@signalschool.ac.th | C7: ='1.1'!C:C -> พ.ต.ไมตรี บุญเหลื่อม | D7: 1 | E7: =IFERROR(vlookup('1.1'!D:D,lookup!$A$2:$B$4,2,false),0) -> 5 | F7: =IFERROR(vlookup('1.1'!E:E,lookup!$A$6:$B$8,2,false),0) -> 5 | G7: =IFERROR(vlookup('1.1'!F:F,lookup!$A$10:$B$12,2,false),0) -> 5 | H7: =IFERROR(vlookup('1.1'!G:G,lookup!$A$14:$B$16,2,false),0) -> 5 | I7: =IFERROR(vlookup('1.1'!H:H,lookup!$A$18:$B$20,2,false),0) -> 5 | J7: =IFERROR(vlookup('1.1'!I:I,lookup!$A$22:$B$24,2,false),0) -> 5 | K7: =IFERROR(vlookup('1.1'!J:J,lookup!$A$26:$B$28,2,false),0) -> 5 | M7: 6 | N7: =CONCAT(R7,"@signalschool.ac.th") -> bnco1006@signalschool.ac.th | O7: =IFERROR(VLOOKUP(N7,B$2:D$81,3,FALSE),0) -> 1 | R7: bnco1006
A8: ='1.1'!A:A -> 46262.434 | B8: ='1.1'!B:B -> bnco1012@signalschool.ac.th | C8: ='1.1'!C:C -> ร.ท.ศุภรัชฏ หมอกสุข | D8: 1 | E8: =IFERROR(vlookup('1.1'!D:D,lookup!$A$2:$B$4,2,false),0) -> 5 | F8: =IFERROR(vlookup('1.1'!E:E,lookup!$A$6:$B$8,2,false),0) -> 5 | G8: =IFERROR(vlookup('1.1'!F:F,lookup!$A$10:$B$12,2,false),0) -> 5 | H8: =IFERROR(vlookup('1.1'!G:G,lookup!$A$14:$B$16,2,false),0) -> 5 | I8: =IFERROR(vlookup('1.1'!H:H,lookup!$A$18:$B$20,2,false),0) -> 5 | J8: =IFERROR(vlookup('1.1'!I:I,lookup!$A$22:$B$24,2,false),0) -> 5 | K8: =IFERROR(vlookup('1.1'!J:J,lookup!$A$26:$B$28,2,false),0) -> 5 | M8: 7 | N8: =CONCAT(R8,"@signalschool.ac.th") -> bnco1007@signalschool.ac.th | O8: =IFERROR(VLOOKUP(N8,B$2:D$81,3,FALSE),0) -> 0 | R8: bnco1007
A9: ='1.1'!A:A -> 46262.436 | B9: ='1.1'!B:B -> bnco1006@signalschool.ac.th | C9: ='1.1'!C:C -> ร.ท.ศุภรัชฎ หมอกสุข | D9: 1 | E9: =IFERROR(vlookup('1.1'!D:D,lookup!$A$2:$B$4,2,false),0) -> 5 | F9: =IFERROR(vlookup('1.1'!E:E,lookup!$A$6:$B$8,2,false),0) -> 5 | G9: =IFERROR(vlookup('1.1'!F:F,lookup!$A$10:$B$12,2,false),0) -> 5 | H9: =IFERROR(vlookup('1.1'!G:G,lookup!$A$14:$B$16,2,false),0) -> 5 | I9: =IFERROR(vlookup('1.1'!H:H,lookup!$A$18:$B$20,2,false),0) -> 5 | J9: =IFERROR(vlookup('1.1'!I:I,lookup!$A$22:$B$24,2,false),0) -> 5 | K9: =IFERROR(vlookup('1.1'!J:J,lookup!$A$26:$B$28,2,false),0) -> 5 | M9: 8 | N9: =CONCAT(R9,"@signalschool.ac.th") -> bnco1008@signalschool.ac.th | O9: =IFERROR(VLOOKUP(N9,B$2:D$81,3,FALSE),0) -> 1 | R9: bnco1008
A10: ='1.1'!A:A -> 46262.441 | B10: ='1.1'!B:B -> bnco1051@signalschool.ac.th | C10: ='1.1'!C:C -> ร.อ.สุพจน์ มงคล | D10: 1 | E10: =IFERROR(vlookup('1.1'!D:D,lookup!$A$2:$B$4,2,false),0) -> 5 | F10: =IFERROR(vlookup('1.1'!E:E,lookup!$A$6:$B$8,2,false),0) -> 5 | G10: =IFERROR(vlookup('1.1'!F:F,lookup!$A$10:$B$12,2,false),0) -> 5 | H10: =IFERROR(vlookup('1.1'!G:G,lookup!$A$14:$B$16,2,false),0) -> 5 | I10: =IFERROR(vlookup('1.1'!H:H,lookup!$A$18:$B$20,2,false),0) -> 5 | J10: =IFERROR(vlookup('1.1'!I:I,lookup!$A$22:$B$24,2,false),0) -> 5 | K10: =IFERROR(vlookup('1.1'!J:J,lookup!$A$26:$B$28,2,false),0) -> 5 | M10: 9 | N10: =CONCAT(R10,"@signalschool.ac.th") -> bnco1009@signalschool.ac.th | O10: =IFERROR(VLOOKUP(N10,B$2:D$81,3,FALSE),0) -> 1 | R10: bnco1009
A11: ='1.1'!A:A -> 46262.441 | B11: ='1.1'!B:B -> bnco1050@signalschool.ac.th | C11: ='1.1'!C:C -> ร.อ.สุพจน์ มงคล | D11: 1 | E11: =IFERROR(vlookup('1.1'!D:D,lookup!$A$2:$B$4,2,false),0) -> 5 | F11: =IFERROR(vlookup('1.1'!E:E,lookup!$A$6:$B$8,2,false),0) -> 5 | G11: =IFERROR(vlookup('1.1'!F:F,lookup!$A$10:$B$12,2,false),0) -> 5 | H11: =IFERROR(vlookup('1.1'!G:G,lookup!$A$14:$B$16,2,false),0) -> 5 | I11: =IFERROR(vlookup('1.1'!H:H,lookup!$A$18:$B$20,2,false),0) -> 5 | J11: =IFERROR(vlookup('1.1'!I:I,lookup!$A$22:$B$24,2,false),0) -> 5 | K11: =IFERROR(vlookup('1.1'!J:J,lookup!$A$26:$B$28,2,false),0) -> 5 | M11: 10 | N11: =CONCAT(R11,"@signalschool.ac.th") -> bnco1010@signalschool.ac.th | O11: =IFERROR(VLOOKUP(N11,B$2:D$81,3,FALSE),0) -> 0 | R11: bnco1010
A12: ='1.1'!A:A -> 46262.442 | B12: ='1.1'!B:B -> bnco1052@signalschool.ac.th | C12: ='1.1'!C:C -> ร.ท.ศุภรัชฎ หมอกสุข | D12: 1 | E12: =IFERROR(vlookup('1.1'!D:D,lookup!$A$2:$B$4,2,false),0) -> 5 | F12: =IFERROR(vlookup('1.1'!E:E,lookup!$A$6:$B$8,2,false),0) -> 5 | G12: =IFERROR(vlookup('1.1'!F:F,lookup!$A$10:$B$12,2,false),0) -> 5 | H12: =IFERROR(vlookup('1.1'!G:G,lookup!$A$14:$B$16,2,false),0) -> 5 | I12: =IFERROR(vlookup('1.1'!H:H,lookup!$A$18:$B$20,2,false),0) -> 5 | J12: =IFERROR(vlookup('1.1'!I:I,lookup!$A$22:$B$24,2,false),0) -> 5 | K12: =IFERROR(vlookup('1.1'!J:J,lookup!$A$26:$B$28,2,false),0) -> 5 | M12: 11 | N12: =CONCAT(R12,"@signalschool.ac.th") -> bnco1011@signalschool.ac.th | O12: =IFERROR(VLOOKUP(N12,B$2:D$81,3,FALSE),0) -> 1 | R12: bnco1011
A13: ='1.1'!A:A -> 46262.444 | B13: ='1.1'!B:B -> bnco1018@signalschool.ac.th | C13: ='1.1'!C:C -> ร.ท.ศุภรัชฎ หมอกสุข | D13: 1 | E13: =IFERROR(vlookup('1.1'!D:D,lookup!$A$2:$B$4,2,false),0) -> 5 | F13: =IFERROR(vlookup('1.1'!E:E,lookup!$A$6:$B$8,2,false),0) -> 5 | G13: =IFERROR(vlookup('1.1'!F:F,lookup!$A$10:$B$12,2,false),0) -> 5 | H13: =IFERROR(vlookup('1.1'!G:G,lookup!$A$14:$B$16,2,false),0) -> 5 | I13: =IFERROR(vlookup('1.1'!H:H,lookup!$A$18:$B$20,2,false),0) -> 5 | J13: =IFERROR(vlookup('1.1'!I:I,lookup!$A$22:$B$24,2,false),0) -> 5 | K13: =IFERROR(vlookup('1.1'!J:J,lookup!$A$26:$B$28,2,false),0) -> 5 | M13: 12 | N13: =CONCAT(R13,"@signalschool.ac.th") -> bnco1012@signalschool.ac.th | O13: =IFERROR(VLOOKUP(N13,B$2:D$81,3,FALSE),0) -> 1 | R13: bnco1012
... A81: ='1.1'!A:A | B81: ='1.1'!B:B | C81: ='1.1'!C:C | D81: 1 | E81: =IFERROR(vlookup('1.1'!D:D,lookup!$A$2:$B$4,2,false),0) -> 0 | F81: =IFERROR(vlookup('1.1'!E:E,lookup!$A$6:$B$8,2,false),0) -> 0 | G81: =IFERROR(vlookup('1.1'!F:F,lookup!$A$10:$B$12,2,false),0) -> 0 | H81: =IFERROR(vlookup('1.1'!G:G,lookup!$A$14:$B$16,2,false),0) -> 0 | I81: =IFERROR(vlookup('1.1'!H:H,lookup!$A$18:$B$20,2,false),0) -> 0 | J81: =IFERROR(vlookup('1.1'!I:I,lookup!$A$22:$B$24,2,false),0) -> 0 | K81: =IFERROR(vlookup('1.1'!J:J,lookup!$A$26:$B$28,2,false),0) -> 0 | M81: 80 | N81: =CONCAT(R81,"@signalschool.ac.th") -> bnco1080@signalschool.ac.th | O81: =IFERROR(VLOOKUP(N81,B$2:D$81,3,FALSE),0) -> 1 | R81: bnco1080
A82: ='1.1'!A:A | B82: ='1.1'!B:B | C82: ='1.1'!C:C
A83: ='1.1'!A:A | B83: ='1.1'!B:B | C83: ='1.1'!C:C
A84: ='1.1'!A:A | B84: ='1.1'!B:B | C84: ='1.1'!C:C
A85: ='1.1'!A:A | B85: ='1.1'!B:B | C85: ='1.1'!C:C
A86: ='1.1'!A:A | B86: ='1.1'!B:B | C86: ='1.1'!C:C
A87: ='1.1'!A:A | B87: ='1.1'!B:B | C87: ='1.1'!C:C
A88: ='1.1'!A:A | B88: ='1.1'!B:B | C88: ='1.1'!C:C
A89: ='1.1'!A:A | B89: ='1.1'!B:B | C89: ='1.1'!C:C
A90: ='1.1'!A:A | B90: ='1.1'!B:B | C90: ='1.1'!C:C
A91: ='1.1'!A:A | B91: ='1.1'!B:B | C91: ='1.1'!C:C
A92: ='1.1'!A:A | B92: ='1.1'!B:B | C92: ='1.1'!C:C
A93: ='1.1'!A:A | B93: ='1.1'!B:B | C93: ='1.1'!C:C
... A100: ='1.1'!A:A | B100: ='1.1'!B:B | C100: ='1.1'!C:C
A101: ='1.1'!A:A | B101: ='1.1'!B:B | C101: ='1.1'!C:C | N101: ยอดผู้เข้าประเมิน | O101: =SUM(O2:O81) -> 67
E102: =AVERAGE(E2:E81) -> 4.2 | F102: =AVERAGE(F2:F81) -> 4.225 | G102: =AVERAGE(G2:G81) -> 4.175 | H102: =AVERAGE(H2:H81) -> 4.2 | I102: =AVERAGE(I2:I81) -> 4.2 | J102: =AVERAGE(J2:J81) -> 4.175 | K102: =AVERAGE(K2:K81) -> 4.175 | L102: =AVERAGE(E102:K102) -> 4.1928571 | N102: ภาพรวมร้อยละ | O102: =(O101*100)/80 -> 83.75

Sheet 1.2
A1: ประทับเวลา | B1: ที่อยู่อีเมล | C1: ยศ ชื่อ-สกุล ครู-อาจารย์ผู้สอน | D1: 1. บุคลิกภาพและลักษณะท่าทางของอาจารย์ผู้สอน | E1: 2. การพูดและการใช้นํ้าเสียง | F1: 3. การเตรียมการสอน | G1: 4. การจัดเตรียมสื่อการสอน | H1: 5. การถ่ายทอดความรู้และการนำเข้าสู่บทเรียน | I1: 6. ผู้เรียนได้ฝึกทักษะการคิดวิเคราะห์ หรือการพัฒนาความคิดสร้างสรรค์จากการเรียนรายวิชานี้มากน้อยเพียงใด | J1: 7. ผู้เรียนได้ฝึกทักษะการสื่อสาร การนำเสนอ และการใช้งานเทคโนโลยีสารสนเทศจากการเรียนรายวิชานี้มากน้อยเพียงใด | K1: ข้อเสนอแนะอื่นๆ
A2: 46262.412 | B2: bnco1013@signalschool.ac.th | C2: ร.อ.สุพจน์ มงคล | D2: ลักษณะทางทหาร "ดีมาก" มีความเชื่อมั่นในตนเองเป็นแบบอย่างที่ดีแก่ผู้เรียนได้ | E2: เสียงดังฟังชัดและจังหวะการพูดไม่ช้า/เร็วเกินไป | F2: มีประมวลรายวิชาและแนะนำเนื้อหาวิชา | G2: มีการจัดเตรียมสื่อการเรียนการสอนและรวบรวมแหล่งอ้างอิงไว้อย่างเหมาะสม | H2: มีการจัดการเรียนการสอนเป็นไปตามประมวลรายวิชาครบถ้วนและการนำเข้าสู่บทเรียนให้ข้อมูลที่เป็นประโยชน์แก่ผู้เรียนครบถ้วน | I2: มีการส่งเสริมให้ผู้เรียนได้ฝึกทักษะการคิดได้อย่างเหมาะสมดีมาก | J2: มีการส่งเสริมให้ผู้เรียนได้ฝึกทักษะการสื่อสารได้อย่างเหมาะสมดีมาก
A3: 46262.414 | B3: bnco1058@signalschool.ac.th | C3: ร.อ.สุพจน์ มงคล | D3: ลักษณะทางทหาร "ดีมาก" มีความเชื่อมั่นในตนเองเป็นแบบอย่างที่ดีแก่ผู้เรียนได้ | E3: เสียงดังฟังชัดและจังหวะการพูดไม่ช้า/เร็วเกินไป | F3: มีประมวลรายวิชาและแนะนำเนื้อหาวิชา | G3: มีการจัดเตรียมสื่อการเรียนการสอนและรวบรวมแหล่งอ้างอิงไว้อย่างเหมาะสม | H3: มีการจัดการเรียนการสอนเป็นไปตามประมวลรายวิชาครบถ้วนและการนำเข้าสู่บทเรียนให้ข้อมูลที่เป็นประโยชน์แก่ผู้เรียนครบถ้วน | I3: มีการส่งเสริมให้ผู้เรียนได้ฝึกทักษะการคิดได้อย่างเหมาะสมดีมาก | J3: มีการส่งเสริมให้ผู้เรียนได้ฝึกทักษะการสื่อสารได้อย่างเหมาะสมดีมาก
A4: 46262.415 | B4: bnco1009@signalschool.ac.th | C4: ร.อ.สพจน์ มงคล | D4: ลักษณะทางทหาร "ดีมาก" มีความเชื่อมั่นในตนเองเป็นแบบอย่างที่ดีแก่ผู้เรียนได้ | E4: เสียงดังฟังชัดและจังหวะการพูดไม่ช้า/เร็วเกินไป | F4: มีประมวลรายวิชาและแนะนำเนื้อหาวิชา | G4: มีการจัดเตรียมสื่อการเรียนการสอนและรวบรวมแหล่งอ้างอิงไว้อย่างเหมาะสม | H4: มีการจัดการเรียนการสอนเป็นไปตามประมวลรายวิชาครบถ้วนและการนำเข้าสู่บทเรียนให้ข้อมูลที่เป็นประโยชน์แก่ผู้เรียนครบถ้วน | I4: มีการส่งเสริมให้ผู้เรียนได้ฝึกทักษะการคิดได้อย่างเหมาะสมดีมาก | J4: มีการส่งเสริมให้ผู้เรียนได้ฝึกทักษะการสื่อสารได้อย่างเหมาะสมดีมาก
A5: 46262.417 | B5: bnco1056@signalschool.ac.th | C5: ร.ท. สุพจน์ มงคล | D5: ลักษณะทางทหาร "ดีมาก" มีความเชื่อมั่นในตนเองเป็นแบบอย่างที่ดีแก่ผู้เรียนได้ | E5: เสียงดังฟังชัดและจังหวะการพูดไม่ช้า/เร็วเกินไป | F5: มีประมวลรายวิชาและแนะนำเนื้อหาวิชา | G5: มีการจัดเตรียมสื่อการเรียนการสอนและรวบรวมแหล่งอ้างอิงไว้อย่างเหมาะสม | H5: มีการจัดการเรียนการสอนเป็นไปตามประมวลรายวิชาครบถ้วนและการนำเข้าสู่บทเรียนให้ข้อมูลที่เป็นประโยชน์แก่ผู้เรียนครบถ้วน | I5: มีการส่งเสริมให้ผู้เรียนได้ฝึกทักษะการคิดได้อย่างเหมาะสมดีมาก | J5: มีการส่งเสริมให้ผู้เรียนได้ฝึกทักษะการสื่อสารได้อย่างเหมาะสมดีมาก
A6: 46262.424 | B6: bnco1062@signalschool.ac.th | C6: ร.อ.สุพจน์ มงคล | D6: ลักษณะทางทหาร "ดีมาก" มีความเชื่อมั่นในตนเองเป็นแบบอย่างที่ดีแก่ผู้เรียนได้ | E6: เสียงดังฟังชัดและจังหวะการพูดไม่ช้า/เร็วเกินไป | F6: มีประมวลรายวิชาและแนะนำเนื้อหาวิชา | G6: มีการจัดเตรียมสื่อการเรียนการสอน "แต่ไม่ปรากฏ" แหล่งอ้างอิง | H6: มีการจัดการเรียนการสอนเป็นไปตามประมวลรายวิชาครบถ้วนและการนำเข้าสู่บทเรียนให้ข้อมูลที่เป็นประโยชน์แก่ผู้เรียนครบถ้วน | I6: มีการส่งเสริมให้ผู้เรียนได้ฝึกทักษะการคิดได้อย่างเหมาะสมดีมาก | J6: มีการส่งเสริมให้ผู้เรียนได้ฝึกทักษะการสื่อสารได้อย่างเหมาะสมดีมาก
A7: 46262.426 | B7: bnco1041@signalschool.ac.th | C7: ร.ท.สุพจน์ มงคล | D7: ลักษณะทางทหาร "ดีมาก" มีความเชื่อมั่นในตนเองเป็นแบบอย่างที่ดีแก่ผู้เรียนได้ | E7: เสียงดังฟังชัดและจังหวะการพูดไม่ช้า/เร็วเกินไป | F7: มีประมวลรายวิชาและแนะนำเนื้อหาวิชา | G7: มีการจัดเตรียมสื่อการเรียนการสอนและรวบรวมแหล่งอ้างอิงไว้อย่างเหมาะสม | H7: มีการจัดการเรียนการสอนเป็นไปตามประมวลรายวิชาครบถ้วนและการนำเข้าสู่บทเรียนให้ข้อมูลที่เป็นประโยชน์แก่ผู้เรียนครบถ้วน | I7: มีการส่งเสริมให้ผู้เรียนได้ฝึกทักษะการคิดได้อย่างเหมาะสมดีมาก | J7: มีการส่งเสริมให้ผู้เรียนได้ฝึกทักษะการสื่อสารได้อย่างเหมาะสมดีมาก | K7: อาจารย์สอนดีมากครับ
A8: 46262.428 | B8: bnco1012@signalschool.ac.th | C8: ร.ท.ศุภรัชฏ หมอกสุข | D8: ลักษณะทางทหาร "ดีมาก" มีความเชื่อมั่นในตนเองเป็นแบบอย่างที่ดีแก่ผู้เรียนได้ | E8: เสียงดังฟังชัดและจังหวะการพูดไม่ช้า/เร็วเกินไป | F8: มีประมวลรายวิชาและแนะนำเนื้อหาวิชา | G8: มีการจัดเตรียมสื่อการเรียนการสอนและรวบรวมแหล่งอ้างอิงไว้อย่างเหมาะสม | H8: มีการจัดการเรียนการสอนเป็นไปตามประมวลรายวิชาครบถ้วนและการนำเข้าสู่บทเรียนให้ข้อมูลที่เป็นประโยชน์แก่ผู้เรียนครบถ้วน | I8: มีการส่งเสริมให้ผู้เรียนได้ฝึกทักษะการคิดได้อย่างเหมาะสมดีมาก | J8: มีการส่งเสริมให้ผู้เรียนได้ฝึกทักษะการสื่อสารได้อย่างเหมาะสมดีมาก | K8: ไม่มี
A9: 46262.436 | B9: bnco1006@signalschool.ac.th | C9: ร.ท.สุพจน์ มงคล | D9: ลักษณะทางทหาร "ดีมาก" มีความเชื่อมั่นในตนเองเป็นแบบอย่างที่ดีแก่ผู้เรียนได้ | E9: เสียงดังฟังชัดและจังหวะการพูดไม่ช้า/เร็วเกินไป | F9: มีประมวลรายวิชาและแนะนำเนื้อหาวิชา | G9: มีการจัดเตรียมสื่อการเรียนการสอนและรวบรวมแหล่งอ้างอิงไว้อย่างเหมาะสม | H9: มีการจัดการเรียนการสอนเป็นไปตามประมวลรายวิชาครบถ้วนและการนำเข้าสู่บทเรียนให้ข้อมูลที่เป็นประโยชน์แก่ผู้เรียนครบถ้วน | I9: มีการส่งเสริมให้ผู้เรียนได้ฝึกทักษะการคิดได้อย่างเหมาะสมดีมาก | J9: มีการส่งเสริมให้ผู้เรียนได้ฝึกทักษะการสื่อสารได้อย่างเหมาะสมดีมาก
A10: 46262.442 | B10: bnco1051@signalschool.ac.th | C10: ร.อ.สุพจน์ มงคล | D10: ลักษณะทางทหาร "ดีมาก" มีความเชื่อมั่นในตนเองเป็นแบบอย่างที่ดีแก่ผู้เรียนได้ | E10: เสียงดังฟังชัดและจังหวะการพูดไม่ช้า/เร็วเกินไป | F10: มีประมวลรายวิชาและแนะนำเนื้อหาวิชา | G10: มีการจัดเตรียมสื่อการเรียนการสอนและรวบรวมแหล่งอ้างอิงไว้อย่างเหมาะสม | H10: มีการจัดการเรียนการสอนเป็นไปตามประมวลรายวิชาครบถ้วนและการนำเข้าสู่บทเรียนให้ข้อมูลที่เป็นประโยชน์แก่ผู้เรียนครบถ้วน | I10: มีการส่งเสริมให้ผู้เรียนได้ฝึกทักษะการคิดได้อย่างเหมาะสมดีมาก | J10: มีการส่งเสริมให้ผู้เรียนได้ฝึกทักษะการสื่อสารได้อย่างเหมาะสมดีมาก
A11: 46262.442 | B11: bnco1050@signalschool.ac.th | C11: ร.อ.สุพจน์ มงคล | D11: ลักษณะทางทหาร "ดีมาก" มีความเชื่อมั่นในตนเองเป็นแบบอย่างที่ดีแก่ผู้เรียนได้ | E11: เสียงดังฟังชัดและจังหวะการพูดไม่ช้า/เร็วเกินไป | F11: มีประมวลรายวิชาและแนะนำเนื้อหาวิชา | G11: มีการจัดเตรียมสื่อการเรียนการสอนและรวบรวมแหล่งอ้างอิงไว้อย่างเหมาะสม | H11: มีการจัดการเรียนการสอนเป็นไปตามประมวลรายวิชาครบถ้วนและการนำเข้าสู่บทเรียนให้ข้อมูลที่เป็นประโยชน์แก่ผู้เรียนครบถ้วน | I11: มีการส่งเสริมให้ผู้เรียนได้ฝึกทักษะการคิดได้อย่างเหมาะสมดีมาก | J11: มีการส่งเสริมให้ผู้เรียนได้ฝึกทักษะการสื่อสารได้อย่างเหมาะสมดีมาก
A12: 46262.444 | B12: bnco1052@signalschool.ac.th | C12: ร.ท.สุพจน์ มงคล | D12: ลักษณะทางทหาร "ดีมาก" มีความเชื่อมั่นในตนเองเป็นแบบอย่างที่ดีแก่ผู้เรียนได้ | E12: เสียงดังฟังชัดและจังหวะการพูดไม่ช้า/เร็วเกินไป | F12: มีประมวลรายวิชาและแนะนำเนื้อหาวิชา | G12: มีการจัดเตรียมสื่อการเรียนการสอนและรวบรวมแหล่งอ้างอิงไว้อย่างเหมาะสม | H12: มีการจัดการเรียนการสอนเป็นไปตามประมวลรายวิชาครบถ้วนและการนำเข้าสู่บทเรียนให้ข้อมูลที่เป็นประโยชน์แก่ผู้เรียนครบถ้วน | I12: มีการส่งเสริมให้ผู้เรียนได้ฝึกทักษะการคิดได้อย่างเหมาะสมดีมาก | J12: มีการส่งเสริมให้ผู้เรียนได้ฝึกทักษะการสื่อสารได้อย่างเหมาะสมดีมาก
A13: 46262.445 | B13: bnco1018@signalschool.ac.th | C13: ร.อ.สุพจน์ มงคล | D13: ลักษณะทางทหาร "ดีมาก" มีความเชื่อมั่นในตนเองเป็นแบบอย่างที่ดีแก่ผู้เรียนได้ | E13: เสียงดังฟังชัดและจังหวะการพูดไม่ช้า/เร็วเกินไป | F13: มีประมวลรายวิชาและแนะนำเนื้อหาวิชา | G13: มีการจัดเตรียมสื่อการเรียนการสอนและรวบรวมแหล่งอ้างอิงไว้อย่างเหมาะสม | H13: มีการจัดการเรียนการสอนเป็นไปตามประมวลรายวิชาครบถ้วนและการนำเข้าสู่บทเรียนให้ข้อมูลที่เป็นประโยชน์แก่ผู้เรียนครบถ้วน | I13: มีการส่งเสริมให้ผู้เรียนได้ฝึกทักษะการคิดได้อย่างเหมาะสมดีมาก | J13: มีการส่งเสริมให้ผู้เรียนได้ฝึกทักษะการสื่อสารได้อย่างเหมาะสมดีมาก | K13: ไม่มีครับ
A14: 46262.45 | B14: bnco1038@signalschool.ac.th | C14: ร.อ.สุพจน์ มงคล | D14: ลักษณะทางทหาร "ดีมาก" มีความเชื่อมั่นในตนเองเป็นแบบอย่างที่ดีแก่ผู้เรียนได้ | E14: เสียงดังฟังชัดและจังหวะการพูดไม่ช้า/เร็วเกินไป | F14: มีประมวลรายวิชาและแนะนำเนื้อหาวิชา | G14: มีการจัดเตรียมสื่อการเรียนการสอนและรวบรวมแหล่งอ้างอิงไว้อย่างเหมาะสม | H14: มีการจัดการเรียนการสอนเป็นไปตามประมวลรายวิชาครบถ้วนและการนำเข้าสู่บทเรียนให้ข้อมูลที่เป็นประโยชน์แก่ผู้เรียนครบถ้วน | I14: มีการส่งเสริมให้ผู้เรียนได้ฝึกทักษะการคิดได้อย่างเหมาะสมดีมาก | J14: มีการส่งเสริมให้ผู้เรียนได้ฝึกทักษะการสื่อสารได้อย่างเหมาะสมดีมาก | K14: อาจารย์สอนเข้าใจง่ายและยกตัวอย่างได้ชัดเจน
A15: 46262.451 | B15: bnco1035@signalschool.ac.th | C15: ร.ท.ศุภรัชฎ หมอกสุข | D15: ลักษณะทางทหาร "ดีมาก" มีความเชื่อมั่นในตนเองเป็นแบบอย่างที่ดีแก่ผู้เรียนได้ | E15: เสียงดังฟังชัดและจังหวะการพูดไม่ช้า/เร็วเกินไป | F15: มีประมวลรายวิชาและแนะนำเนื้อหาวิชา | G15: มีการจัดเตรียมสื่อการเรียนการสอนและรวบรวมแหล่งอ้างอิงไว้อย่างเหมาะสม | H15: มีการจัดการเรียนการสอนเป็นไปตามประมวลรายวิชาครบถ้วนและการนำเข้าสู่บทเรียนให้ข้อมูลที่เป็นประโยชน์แก่ผู้เรียนครบถ้วน | I15: มีการส่งเสริมให้ผู้เรียนได้ฝึกทักษะการคิดได้อย่างเหมาะสมดีมาก | J15: มีการส่งเสริมให้ผู้เรียนได้ฝึกทักษะการสื่อสารได้อย่างเหมาะสมดีมาก
A16: 46262.458 | B16: bnco1036@signalschool.ac.th | C16: ร.อ.สุพจน์ มงคล | D16: ลักษณะทางทหาร "ดีมาก" มีความเชื่อมั่นในตนเองเป็นแบบอย่างที่ดีแก่ผู้เรียนได้ | E16: เสียงดังฟังชัดและจังหวะการพูดไม่ช้า/เร็วเกินไป | F16: มีประมวลรายวิชาและแนะนำเนื้อหาวิชา | G16: มีการจัดเตรียมสื่อการเรียนการสอนและรวบรวมแหล่งอ้างอิงไว้อย่างเหมาะสม | H16: มีการจัดการเรียนการสอนเป็นไปตามประมวลรายวิชาครบถ้วนและการนำเข้าสู่บทเรียนให้ข้อมูลที่เป็นประโยชน์แก่ผู้เรียนครบถ้วน | I16: มีการส่งเสริมให้ผู้เรียนได้ฝึกทักษะการคิดได้อย่างเหมาะสมดีมาก | J16: มีการส่งเสริมให้ผู้เรียนได้ฝึกทักษะการสื่อสารได้อย่างเหมาะสมดีมาก
A17: 46262.46 | B17: bnco1070@signalschool.ac.th | C17: ร.อ.สุพจน์ มงคล | D17: ลักษณะทางทหาร "มีความเหมาะสม" มีความเชื่อมั่นในตนเองปานกลาง | E17: เสียงดังฟังชัดและจังหวะการพูดไม่ช้า/เร็วเกินไป | F17: มีประมวลรายวิชา "แต่ไม่มีการ" แนะนำเนื้อหาวิชา | G17: มีการจัดเตรียมสื่อการเรียนการสอน "แต่ไม่ปรากฏ" แหล่งอ้างอิง | H17: มีการจัดการเรียนการสอนเป็นไปตามประมวลรายวิชาครบถ้วนและการนำเข้าสู่บทเรียนให้ข้อมูลที่เป็นประโยชน์แก่ผู้เรียนครบถ้วน | I17: มีการส่งเสริมให้ผู้เรียนได้ฝึกทักษะการคิดได้อย่างเหมาะสมดีมาก | J17: มีการส่งเสริมให้ผู้เรียนได้ฝึกทักษะการสื่อสารได้อย่างเหมาะสมดีมาก
A18: 46262.461 | B18: bnco1042@signalschool.ac.th | C18: ร.อ.สุพจน์ มงคล | D18: ลักษณะทางทหาร "ดีมาก" มีความเชื่อมั่นในตนเองเป็นแบบอย่างที่ดีแก่ผู้เรียนได้ | E18: เสียงดังฟังชัดและจังหวะการพูดไม่ช้า/เร็วเกินไป | F18: มีประมวลรายวิชาและแนะนำเนื้อหาวิชา | G18: มีการจัดเตรียมสื่อการเรียนการสอนและรวบรวมแหล่งอ้างอิงไว้อย่างเหมาะสม | H18: มีการจัดการเรียนการสอนเป็นไปตามประมวลรายวิชาครบถ้วนและการนำเข้าสู่บทเรียนให้ข้อมูลที่เป็นประโยชน์แก่ผู้เรียนครบถ้วน | I18: มีการส่งเสริมให้ผู้เรียนได้ฝึกทักษะการคิดได้อย่างเหมาะสมดีมาก | J18: มีการส่งเสริมให้ผู้เรียนได้ฝึกทักษะการสื่อสารได้อย่างเหมาะสมดีมาก
A19: 46262.464 | B19: bnco1003@signalschool.ac.th | C19: ร.อ.สุพจน์ มงคล | D19: ลักษณะทางทหาร "ดีมาก" มีความเชื่อมั่นในตนเองเป็นแบบอย่างที่ดีแก่ผู้เรียนได้ | E19: เสียงดังฟังชัดและจังหวะการพูดไม่ช้า/เร็วเกินไป | F19: มีประมวลรายวิชาและแนะนำเนื้อหาวิชา | G19: มีการจัดเตรียมสื่อการเรียนการสอนและรวบรวมแหล่งอ้างอิงไว้อย่างเหมาะสม | H19: มีการจัดการเรียนการสอนเป็นไปตามประมวลรายวิชาครบถ้วนและการนำเข้าสู่บทเรียนให้ข้อมูลที่เป็นประโยชน์แก่ผู้เรียนครบถ้วน | I19: มีการส่งเสริมให้ผู้เรียนได้ฝึกทักษะการคิดได้อย่างเหมาะสมดีมาก | J19: มีการส่งเสริมให้ผู้เรียนได้ฝึกทักษะการสื่อสารได้อย่างเหมาะสมดีมาก
A20: 46262.468 | B20: bnco1079@signalschool.ac.th | C20: ร.อ.สุพจน์ มงคล | D20: ลักษณะทางทหาร "ดีมาก" มีความเชื่อมั่นในตนเองเป็นแบบอย่างที่ดีแก่ผู้เรียนได้ | E20: เสียงดังฟังชัดและจังหวะการพูดไม่ช้า/เร็วเกินไป | F20: มีประมวลรายวิชาและแนะนำเนื้อหาวิชา | G20: มีการจัดเตรียมสื่อการเรียนการสอนและรวบรวมแหล่งอ้างอิงไว้อย่างเหมาะสม | H20: มีการจัดการเรียนการสอนเป็นไปตามประมวลรายวิชาครบถ้วนและการนำเข้าสู่บทเรียนให้ข้อมูลที่เป็นประโยชน์แก่ผู้เรียนครบถ้วน | I20: มีการส่งเสริมให้ผู้เรียนได้ฝึกทักษะการคิดได้อย่างเหมาะสมดีมาก | J20: มีการส่งเสริมให้ผู้เรียนได้ฝึกทักษะการสื่อสารได้อย่างเหมาะสมดีมาก
A21: 46262.482 | B21: bnco1032@signalschool.ac.th | C21: ร.อ.สุพจน์ มงคล | D21: ลักษณะทางทหาร "ดีมาก" มีความเชื่อมั่นในตนเองเป็นแบบอย่างที่ดีแก่ผู้เรียนได้ | E21: เสียงดังฟังชัดและจังหวะการพูดไม่ช้า/เร็วเกินไป | F21: มีประมวลรายวิชาและแนะนำเนื้อหาวิชา | G21: มีการจัดเตรียมสื่อการเรียนการสอนและรวบรวมแหล่งอ้างอิงไว้อย่างเหมาะสม | H21: มีการจัดการเรียนการสอนเป็นไปตามประมวลรายวิชาครบถ้วนและการนำเข้าสู่บทเรียนให้ข้อมูลที่เป็นประโยชน์แก่ผู้เรียนครบถ้วน | I21: มีการส่งเสริมให้ผู้เรียนได้ฝึกทักษะการคิดได้อย่างเหมาะสมดีมาก | J21: มีการส่งเสริมให้ผู้เรียนได้ฝึกทักษะการสื่อสารได้อย่างเหมาะสมดีมาก | K21: อาจาร์ยสอนเข้าใจง่ายดีครับ
A22: 46262.487 | B22: bnco1060@signalschool.ac.th | C22: ร.อ.สุพจน์ มงคล | D22: ลักษณะทางทหาร "ดีมาก" มีความเชื่อมั่นในตนเองเป็นแบบอย่างที่ดีแก่ผู้เรียนได้ | E22: เสียงดังฟังชัดและจังหวะการพูดไม่ช้า/เร็วเกินไป | F22: มีประมวลรายวิชาและแนะนำเนื้อหาวิชา | G22: มีการจัดเตรียมสื่อการเรียนการสอนและรวบรวมแหล่งอ้างอิงไว้อย่างเหมาะสม | H22: มีการจัดการเรียนการสอนเป็นไปตามประมวลรายวิชาครบถ้วนและการนำเข้าสู่บทเรียนให้ข้อมูลที่เป็นประโยชน์แก่ผู้เรียนครบถ้วน | I22: มีการส่งเสริมให้ผู้เรียนได้ฝึกทักษะการคิดได้อย่างเหมาะสมดีมาก | J22: มีการส่งเสริมให้ผู้เรียนได้ฝึกทักษะการสื่อสารได้อย่างเหมาะสมดีมาก | K22: สอนเข้าใจมากครับ
A23: 46262.497 | B23: bnco1031@signalschool.ac.th | C23: ร.ท. สุพจน์ มงคล | D23: ลักษณะทางทหาร "ดีมาก" มีความเชื่อมั่นในตนเองเป็นแบบอย่างที่ดีแก่ผู้เรียนได้ | E23: เสียงดังฟังชัดและจังหวะการพูดไม่ช้า/เร็วเกินไป | F23: มีประมวลรายวิชาและแนะนำเนื้อหาวิชา | G23: มีการจัดเตรียมสื่อการเรียนการสอนและรวบรวมแหล่งอ้างอิงไว้อย่างเหมาะสม | H23: มีการจัดการเรียนการสอนเป็นไปตามประมวลรายวิชาครบถ้วนและการนำเข้าสู่บทเรียนให้ข้อมูลที่เป็นประโยชน์แก่ผู้เรียนครบถ้วน | I23: มีการส่งเสริมให้ผู้เรียนได้ฝึกทักษะการคิดได้อย่างเหมาะสมดีมาก | J23: มีการส่งเสริมให้ผู้เรียนได้ฝึกทักษะการสื่อสารได้อย่างเหมาะสมดีมาก
A24: 46262.5 | B24: bnco1063@signalschool.ac.th | C24: ร.อ.สุพจน์ มงคล | D24: ลักษณะทางทหาร "ดีมาก" มีความเชื่อมั่นในตนเองเป็นแบบอย่างที่ดีแก่ผู้เรียนได้ | E24: เสียงดังฟังชัดและจังหวะการพูดไม่ช้า/เร็วเกินไป | F24: มีประมวลรายวิชาและแนะนำเนื้อหาวิชา | G24: มีการจัดเตรียมสื่อการเรียนการสอนและรวบรวมแหล่งอ้างอิงไว้อย่างเหมาะสม | H24: มีการจัดการเรียนการสอนเป็นไปตามประมวลรายวิชาครบถ้วนและการนำเข้าสู่บทเรียนให้ข้อมูลที่เป็นประโยชน์แก่ผู้เรียนครบถ้วน | I24: มีการส่งเสริมให้ผู้เรียนได้ฝึกทักษะการคิดได้อย่างเหมาะสมดีมาก | J24: มีการส่งเสริมให้ผู้เรียนได้ฝึกทักษะการสื่อสารได้อย่างเหมาะสมดีมาก
A25: 46262.523 | B25: bnco1066@signalschool.ac.th | C25: ร.อ.สุพจน์ มงคล | D25: ลักษณะทางทหาร "ดีมาก" มีความเชื่อมั่นในตนเองเป็นแบบอย่างที่ดีแก่ผู้เรียนได้ | E25: เสียงดังฟังชัดและจังหวะการพูดไม่ช้า/เร็วเกินไป | F25: มีประมวลรายวิชาและแนะนำเนื้อหาวิชา | G25: มีการจัดเตรียมสื่อการเรียนการสอนและรวบรวมแหล่งอ้างอิงไว้อย่างเหมาะสม | H25: มีการจัดการเรียนการสอนเป็นไปตามประมวลรายวิชาครบถ้วนและการนำเข้าสู่บทเรียนให้ข้อมูลที่เป็นประโยชน์แก่ผู้เรียนครบถ้วน | I25: มีการส่งเสริมให้ผู้เรียนได้ฝึกทักษะการคิดได้อย่างเหมาะสมดีมาก | J25: มีการส่งเสริมให้ผู้เรียนได้ฝึกทักษะการสื่อสารได้อย่างเหมาะสมดีมาก
A26: 46262.529 | B26: bnco1069@signalschool.ac.th | C26: ร.อ.สุพจน์ มงคล | D26: ลักษณะทางทหาร "ดีมาก" มีความเชื่อมั่นในตนเองเป็นแบบอย่างที่ดีแก่ผู้เรียนได้ | E26: เสียงดังฟังชัดและจังหวะการพูดไม่ช้า/เร็วเกินไป | F26: มีประมวลรายวิชาและแนะนำเนื้อหาวิชา | G26: มีการจัดเตรียมสื่อการเรียนการสอนและรวบรวมแหล่งอ้างอิงไว้อย่างเหมาะสม | H26: มีการจัดการเรียนการสอนเป็นไปตามประมวลรายวิชาครบถ้วนและการนำเข้าสู่บทเรียนให้ข้อมูลที่เป็นประโยชน์แก่ผู้เรียนครบถ้วน | I26: มีการส่งเสริมให้ผู้เรียนได้ฝึกทักษะการคิดได้อย่างเหมาะสมดีมาก | J26: มีการส่งเสริมให้ผู้เรียนได้ฝึกทักษะการสื่อสารได้อย่างเหมาะสมดีมาก
A27: 46262.554 | B27: bnco1068@signalschool.ac.th | C27: ร.อ. สุพจน์ มงคล | D27: ลักษณะทางทหาร "ดีมาก" มีความเชื่อมั่นในตนเองเป็นแบบอย่างที่ดีแก่ผู้เรียนได้ | E27: เสียงดังฟังชัดและจังหวะการพูดไม่ช้า/เร็วเกินไป | F27: มีประมวลรายวิชาและแนะนำเนื้อหาวิชา | G27: มีการจัดเตรียมสื่อการเรียนการสอนและรวบรวมแหล่งอ้างอิงไว้อย่างเหมาะสม | H27: มีการจัดการเรียนการสอนเป็นไปตามประมวลรายวิชาครบถ้วนและการนำเข้าสู่บทเรียนให้ข้อมูลที่เป็นประโยชน์แก่ผู้เรียนครบถ้วน | I27: มีการส่งเสริมให้ผู้เรียนได้ฝึกทักษะการคิดได้อย่างเหมาะสมดีมาก | J27: มีการส่งเสริมให้ผู้เรียนได้ฝึกทักษะการสื่อสารได้อย่างเหมาะสมดีมาก
A28: 46262.554 | B28: bnco1044@signalschool.ac.th | C28: ร.อ. สุพจน์ มงคล | D28: ลักษณะทางทหาร "ดีมาก" มีความเชื่อมั่นในตนเองเป็นแบบอย่างที่ดีแก่ผู้เรียนได้ | E28: เสียงดังฟังชัดและจังหวะการพูดไม่ช้า/เร็วเกินไป | F28: มีประมวลรายวิชาและแนะนำเนื้อหาวิชา | G28: มีการจัดเตรียมสื่อการเรียนการสอนและรวบรวมแหล่งอ้างอิงไว้อย่างเหมาะสม | H28: มีการจัดการเรียนการสอนเป็นไปตามประมวลรายวิชาครบถ้วนและการนำเข้าสู่บทเรียนให้ข้อมูลที่เป็นประโยชน์แก่ผู้เรียนครบถ้วน | I28: มีการส่งเสริมให้ผู้เรียนได้ฝึกทักษะการคิดได้อย่างเหมาะสมดีมาก | J28: มีการส่งเสริมให้ผู้เรียนได้ฝึกทักษะการสื่อสารได้อย่างเหมาะสมดีมาก
A29: 46262.56 | B29: bnco1008@signalschool.ac.th | C29: ร.อ.สุพจน์ มงคล | D29: ลักษณะทางทหาร "ดีมาก" มีความเชื่อมั่นในตนเองเป็นแบบอย่างที่ดีแก่ผู้เรียนได้ | E29: เสียงดังฟังชัดและจังหวะการพูดไม่ช้า/เร็วเกินไป | F29: มีประมวลรายวิชาและแนะนำเนื้อหาวิชา | G29: มีการจัดเตรียมสื่อการเรียนการสอนและรวบรวมแหล่งอ้างอิงไว้อย่างเหมาะสม | H29: มีการจัดการเรียนการสอนเป็นไปตามประมวลรายวิชาครบถ้วนและการนำเข้าสู่บทเรียนให้ข้อมูลที่เป็นประโยชน์แก่ผู้เรียนครบถ้วน | I29: มีการส่งเสริมให้ผู้เรียนได้ฝึกทักษะการคิดได้อย่างเหมาะสมดีมาก | J29: มีการส่งเสริมให้ผู้เรียนได้ฝึกทักษะการสื่อสารได้อย่างเหมาะสมดีมาก
A30: 46262.56 | B30: bnco1049@signalschool.ac.th | C30: ร.อ.สุพจน์ มงคล | D30: ลักษณะทางทหาร "ดีมาก" มีความเชื่อมั่นในตนเองเป็นแบบอย่างที่ดีแก่ผู้เรียนได้ | E30: เสียงดังฟังชัดและจังหวะการพูดไม่ช้า/เร็วเกินไป | F30: มีประมวลรายวิชาและแนะนำเนื้อหาวิชา | G30: มีการจัดเตรียมสื่อการเรียนการสอนและรวบรวมแหล่งอ้างอิงไว้อย่างเหมาะสม | H30: มีการจัดการเรียนการสอนเป็นไปตามประมวลรายวิชาครบถ้วนและการนำเข้าสู่บทเรียนให้ข้อมูลที่เป็นประโยชน์แก่ผู้เรียนครบถ้วน | I30: มีการส่งเสริมให้ผู้เรียนได้ฝึกทักษะการคิดได้อย่างเหมาะสมดีมาก | J30: มีการส่งเสริมให้ผู้เรียนได้ฝึกทักษะการสื่อสารได้อย่างเหมาะสมดีมาก
A31: 46262.57 | B31: bnco1022@signalschool.ac.th | C31: ร.อ.สุพจน์ มงคล | D31: ลักษณะทางทหาร "ดีมาก" มีความเชื่อมั่นในตนเองเป็นแบบอย่างที่ดีแก่ผู้เรียนได้ | E31: เสียงดังฟังชัดและจังหวะการพูดไม่ช้า/เร็วเกินไป | F31: มีประมวลรายวิชาและแนะนำเนื้อหาวิชา | G31: มีการจัดเตรียมสื่อการเรียนการสอนและรวบรวมแหล่งอ้างอิงไว้อย่างเหมาะสม | H31: มีการจัดการเรียนการสอนเป็นไปตามประมวลรายวิชาครบถ้วนและการนำเข้าสู่บทเรียนให้ข้อมูลที่เป็นประโยชน์แก่ผู้เรียนครบถ้วน | I31: มีการส่งเสริมให้ผู้เรียนได้ฝึกทักษะการคิดได้อย่างเหมาะสมดีมาก | J31: มีการส่งเสริมให้ผู้เรียนได้ฝึกทักษะการสื่อสารได้อย่างเหมาะสมดีมาก | K31: อาจาร์สอนเข้าใจง่ายครับ
A32: 46262.579 | B32: bnco1005@signalschool.ac.th | C32: ร.อ.สุพจน์ มงคล | D32: ลักษณะทางทหาร "ดีมาก" มีความเชื่อมั่นในตนเองเป็นแบบอย่างที่ดีแก่ผู้เรียนได้ | E32: เสียงดังฟังชัดและจังหวะการพูดไม่ช้า/เร็วเกินไป | F32: มีประมวลรายวิชาและแนะนำเนื้อหาวิชา | G32: มีการจัดเตรียมสื่อการเรียนการสอนและรวบรวมแหล่งอ้างอิงไว้อย่างเหมาะสม | H32: มีการจัดการเรียนการสอนเป็นไปตามประมวลรายวิชาครบถ้วนและการนำเข้าสู่บทเรียนให้ข้อมูลที่เป็นประโยชน์แก่ผู้เรียนครบถ้วน | I32: มีการส่งเสริมให้ผู้เรียนได้ฝึกทักษะการคิดได้อย่างเหมาะสมดีมาก | J32: มีการส่งเสริมให้ผู้เรียนได้ฝึกทักษะการสื่อสารได้อย่างเหมาะสมดีมาก
A33: 46262.579 | B33: bnco1067@signalschool.ac.th | C33: ร.อ.สุพจน์ มงคล | D33: ลักษณะทางทหาร "ดีมาก" มีความเชื่อมั่นในตนเองเป็นแบบอย่างที่ดีแก่ผู้เรียนได้ | E33: เสียงดังฟังชัดและจังหวะการพูดไม่ช้า/เร็วเกินไป | F33: มีประมวลรายวิชาและแนะนำเนื้อหาวิชา | G33: มีการจัดเตรียมสื่อการเรียนการสอนและรวบรวมแหล่งอ้างอิงไว้อย่างเหมาะสม | H33: มีการจัดการเรียนการสอนเป็นไปตามประมวลรายวิชาครบถ้วนและการนำเข้าสู่บทเรียนให้ข้อมูลที่เป็นประโยชน์แก่ผู้เรียนครบถ้วน | I33: มีการส่งเสริมให้ผู้เรียนได้ฝึกทักษะการคิดได้อย่างเหมาะสมดีมาก | J33: มีการส่งเสริมให้ผู้เรียนได้ฝึกทักษะการสื่อสารได้อย่างเหมาะสมดีมาก
A34: 46262.586 | B34: bnco1039@signalschool.ac.th | C34: ร.อ.สุพจน์ มงคล | D34: ลักษณะทางทหาร "ดีมาก" มีความเชื่อมั่นในตนเองเป็นแบบอย่างที่ดีแก่ผู้เรียนได้ | E34: เสียงดังฟังชัดและจังหวะการพูดไม่ช้า/เร็วเกินไป | F34: มีประมวลรายวิชาและแนะนำเนื้อหาวิชา | G34: มีการจัดเตรียมสื่อการเรียนการสอน "แต่ไม่ปรากฏ" แหล่งอ้างอิง | H34: มีการจัดการเรียนการสอนเป็นไปตามประมวลรายวิชาครบถ้วนและการนำเข้าสู่บทเรียนให้ข้อมูลที่เป็นประโยชน์แก่ผู้เรียนครบถ้วน | I34: มีการส่งเสริมให้ผู้เรียนได้ฝึกทักษะการคิดได้อย่างเหมาะสมดีมาก | J34: มีการส่งเสริมให้ผู้เรียนได้ฝึกทักษะการสื่อสารได้อย่างเหมาะสมดีมาก
A35: 46262.592 | B35: bnco1045@signalschool.ac.th | C35: ร.อ.สุพจน์ มงคล | D35: ลักษณะทางทหาร "มีความเหมาะสม" มีความเชื่อมั่นในตนเองปานกลาง | E35: เสียงดังฟังชัดและจังหวะการพูดไม่ช้า/เร็วเกินไป | F35: มีประมวลรายวิชาและแนะนำเนื้อหาวิชา | G35: มีการจัดเตรียมสื่อการเรียนการสอนและรวบรวมแหล่งอ้างอิงไว้อย่างเหมาะสม | H35: มีการจัดการเรียนการสอนเป็นไปตามประมวลรายวิชาครบถ้วนและการนำเข้าสู่บทเรียนให้ข้อมูลที่เป็นประโยชน์แก่ผู้เรียนครบถ้วน | I35: มีการส่งเสริมให้ผู้เรียนได้ฝึกทักษะการคิดได้อย่างเหมาะสมดีมาก | J35: มีการส่งเสริมให้ผู้เรียนได้ฝึกทักษะการสื่อสารได้อย่างเหมาะสมดีมาก
A36: 46262.611 | B36: bnco1080@signalschool.ac.th | C36: ร.อ.สุพจน์ มงคล | D36: ลักษณะทางทหาร "ดีมาก" มีความเชื่อมั่นในตนเองเป็นแบบอย่างที่ดีแก่ผู้เรียนได้ | E36: เสียงดังฟังชัดและจังหวะการพูดไม่ช้า/เร็วเกินไป | F36: มีประมวลรายวิชาและแนะนำเนื้อหาวิชา | G36: มีการจัดเตรียมสื่อการเรียนการสอนและรวบรวมแหล่งอ้างอิงไว้อย่างเหมาะสม | H36: มีการจัดการเรียนการสอนเป็นไปตามประมวลรายวิชาครบถ้วนและการนำเข้าสู่บทเรียนให้ข้อมูลที่เป็นประโยชน์แก่ผู้เรียนครบถ้วน | I36: มีการส่งเสริมให้ผู้เรียนได้ฝึกทักษะการคิดได้อย่างเหมาะสมดีมาก | J36: มีการส่งเสริมให้ผู้เรียนได้ฝึกทักษะการสื่อสารได้อย่างเหมาะสมดีมาก
A37: 46262.627 | B37: bnco1064@signalschool.ac.th | C37: ร.อ.สุพจน์ มลคค | D37: ลักษณะทางทหาร "ดีมาก" มีความเชื่อมั่นในตนเองเป็นแบบอย่างที่ดีแก่ผู้เรียนได้ | E37: เสียงดังฟังชัดและจังหวะการพูดไม่ช้า/เร็วเกินไป | F37: มีประมวลรายวิชาและแนะนำเนื้อหาวิชา | G37: มีการจัดเตรียมสื่อการเรียนการสอนและรวบรวมแหล่งอ้างอิงไว้อย่างเหมาะสม | H37: มีการจัดการเรียนการสอนเป็นไปตามประมวลรายวิชาครบถ้วนและการนำเข้าสู่บทเรียนให้ข้อมูลที่เป็นประโยชน์แก่ผู้เรียนครบถ้วน | I37: มีการส่งเสริมให้ผู้เรียนได้ฝึกทักษะการคิดได้อย่างเหมาะสมดีมาก | J37: มีการส่งเสริมให้ผู้เรียนได้ฝึกทักษะการสื่อสารได้อย่างเหมาะสมดีมาก | K37: -
A38: 46262.643 | B38: bnco1021@signalschool.ac.th | C38: ร.อ.สุพจน์ มงคล | D38: ลักษณะทางทหาร "ดีมาก" มีความเชื่อมั่นในตนเองเป็นแบบอย่างที่ดีแก่ผู้เรียนได้ | E38: เสียงดังฟังชัดและจังหวะการพูดไม่ช้า/เร็วเกินไป | F38: มีประมวลรายวิชาและแนะนำเนื้อหาวิชา | G38: มีการจัดเตรียมสื่อการเรียนการสอนและรวบรวมแหล่งอ้างอิงไว้อย่างเหมาะสม | H38: มีการจัดการเรียนการสอนเป็นไปตามประมวลรายวิชาครบถ้วนและการนำเข้าสู่บทเรียนให้ข้อมูลที่เป็นประโยชน์แก่ผู้เรียนครบถ้วน | I38: มีการส่งเสริมให้ผู้เรียนได้ฝึกทักษะการคิดได้อย่างเหมาะสมดีมาก | J38: มีการส่งเสริมให้ผู้เรียนได้ฝึกทักษะการสื่อสารได้อย่างเหมาะสมดีมาก
A39: 46262.644 | B39: bnco1027@signalschool.ac.th | C39: ร.อ.สุพจน์ มงคล | D39: ลักษณะทางทหาร "ดีมาก" มีความเชื่อมั่นในตนเองเป็นแบบอย่างที่ดีแก่ผู้เรียนได้ | E39: เสียงดังฟังชัดและจังหวะการพูดไม่ช้า/เร็วเกินไป | F39: มีประมวลรายวิชาและแนะนำเนื้อหาวิชา | G39: มีการจัดเตรียมสื่อการเรียนการสอนและรวบรวมแหล่งอ้างอิงไว้อย่างเหมาะสม | H39: มีการจัดการเรียนการสอนเป็นไปตามประมวลรายวิชาครบถ้วนและการนำเข้าสู่บทเรียนให้ข้อมูลที่เป็นประโยชน์แก่ผู้เรียนครบถ้วน | I39: มีการส่งเสริมให้ผู้เรียนได้ฝึกทักษะการคิดได้อย่างเหมาะสมดีมาก | J39: มีการส่งเสริมให้ผู้เรียนได้ฝึกทักษะการสื่อสารได้อย่างเหมาะสมดีมาก | K39: -
A40: 46262.74 | B40: bnco1072@signalschool.ac.th | C40: ร.อ.สุพจน์ มงคล | D40: ลักษณะทางทหาร "ดีมาก" มีความเชื่อมั่นในตนเองเป็นแบบอย่างที่ดีแก่ผู้เรียนได้ | E40: เสียงดังฟังชัดและจังหวะการพูดไม่ช้า/เร็วเกินไป | F40: มีประมวลรายวิชาและแนะนำเนื้อหาวิชา | G40: มีการจัดเตรียมสื่อการเรียนการสอนและรวบรวมแหล่งอ้างอิงไว้อย่างเหมาะสม | H40: มีการจัดการเรียนการสอนเป็นไปตามประมวลรายวิชาครบถ้วนและการนำเข้าสู่บทเรียนให้ข้อมูลที่เป็นประโยชน์แก่ผู้เรียนครบถ้วน | I40: มีการส่งเสริมให้ผู้เรียนได้ฝึกทักษะการคิดได้อย่างเหมาะสมดีมาก | J40: มีการส่งเสริมให้ผู้เรียนได้ฝึกทักษะการสื่อสารได้อย่างเหมาะสมดีมาก
...

Sheet ค่า 1.2
A1: ประทับเวลา | B1: ที่อยู่อีเมล | C1: ยศ ชื่อ-สกุล ครู-อาจารย์ผู้สอน | E1: 1. บุคลิกภาพและลักษณะท่าทางของอาจารย์ผู้สอน | F1: 2. การพูดและการใช้นํ้าเสียง | G1: 3. การเตรียมการสอน | H1: 4. การจัดเตรียมสื่อการสอน | I1: 5. การถ่ายทอดความรู้และการนำเข้าสู่บทเรียน | J1: 6. ผู้เรียนได้ฝึกทักษะการคิดวิเคราะห์ หรือการพัฒนาความคิดสร้างสรรค์จากการเรียนรายวิชานี้มากน้อยเพียงใด | K1: 7. ผู้เรียนได้ฝึกทักษะการสื่อสาร การนำเสนอ และการใช้งานเทคโนโลยีสารสนเทศจากการเรียนรายวิชานี้มากน้อยเพียงใด | M1: ตรวจสอบผู้เข้าประเมิน
