Workbook

Sheet 1.1
A1: ประทับเวลา | B1: ที่อยู่อีเมล | C1: ยศ ชื่อ-สกุล ครู-อาจารย์ผู้สอน | D1: 1. บุคลิกภาพและลักษณะท่าทางของอาจารย์ผู้สอน | E1: 2. การพูดและการใช้นํ้าเสียง | F1: 3. การเตรียมการสอน | G1: 4. การจัดเตรียมสื่อการสอน | H1: 5. การถ่ายทอดความรู้และการนำเข้าสู่บทเรียน | I1: 6. ผู้เรียนได้ฝึกทักษะการคิดวิเคราะห์ หรือการพัฒนาความคิดสร้างสรรค์จากการเรียนรายวิชานี้มากน้อยเพียงใด | J1: 7. ผู้เรียนได้ฝึกทักษะการสื่อสาร การนำเสนอ และการใช้งานเทคโนโลยีสารสนเทศจากการเรียนรายวิชานี้มากน้อยเพียงใด | K1: ข้อเสนอแนะอื่นๆ
A2: 46181.522 | B2: bnco0910@signalschool.ac.th | C2: ส.อ.ไชยพร รัก รักษากุล | D2: ลักษณะทางทหาร "ดีมาก" มีความเชื่อมั่นในตนเองเป็นแบบอย่างที่ดีแก่ผู้เรียนได้ | E2: เสียงดังฟังชัดและจังหวะการพูดไม่ช้า/เร็วเกินไป | F2: มีประมวลรายวิชาและแนะนำเนื้อหาวิชา | G2: มีการจัดเตรียมสื่อการเรียนการสอนและรวบรวมแหล่งอ้างอิงไว้อย่างเหมาะสม | H2: มีการจัดการเรียนการสอนเป็นไปตามประมวลรายวิชาครบถ้วนและการนำเข้าสู่บทเรียนให้ข้อมูลที่เป็นประโยชน์แก่ผู้เรียนครบถ้วน | I2: มีการส่งเสริมให้ผู้เรียนได้ฝึกทักษะการคิดได้อย่างเหมาะสมดีมาก | J2: มีการส่งเสริมให้ผู้เรียนได้ฝึกทักษะการสื่อสารได้อย่างเหมาะสมดีมาก
A3: 46189.429 | B3: bnco0936@signalschool.ac.th | C3: จ.ส.ต.ภานุพงษ์ ใจเฉื่อย | D3: ลักษณะทางทหาร "ดีมาก" มีความเชื่อมั่นในตนเองเป็นแบบอย่างที่ดีแก่ผู้เรียนได้ | E3: เสียงดังฟังชัดและจังหวะการพูดไม่ช้า/เร็วเกินไป | F3: มีประมวลรายวิชาและแนะนำเนื้อหาวิชา | G3: มีการจัดเตรียมสื่อการเรียนการสอนและรวบรวมแหล่งอ้างอิงไว้อย่างเหมาะสม | H3: มีการจัดการเรียนการสอนเป็นไปตามประมวลรายวิชาครบถ้วนและการนำเข้าสู่บทเรียนให้ข้อมูลที่เป็นประโยชน์แก่ผู้เรียนครบถ้วน | I3: มีการส่งเสริมให้ผู้เรียนได้ฝึกทักษะการคิดได้อย่างเหมาะสมดีมาก | J3: มีการส่งเสริมให้ผู้เรียนได้ฝึกทักษะการสื่อสารได้อย่างเหมาะสมดีมาก
A4: 46189.435 | B4: bnco0940@signalschool.ac.th | C4: ส.อ.ไชยพร รักษากุล | D4: ลักษณะทางทหาร "ดีมาก" มีความเชื่อมั่นในตนเองเป็นแบบอย่างที่ดีแก่ผู้เรียนได้ | E4: เสียงดังฟังชัดและจังหวะการพูดไม่ช้า/เร็วเกินไป | F4: มีประมวลรายวิชาและแนะนำเนื้อหาวิชา | G4: มีการจัดเตรียมสื่อการเรียนการสอนและรวบรวมแหล่งอ้างอิงไว้อย่างเหมาะสม | H4: มีการจัดการเรียนการสอนเป็นไปตามประมวลรายวิชาครบถ้วนและการนำเข้าสู่บทเรียนให้ข้อมูลที่เป็นประโยชน์แก่ผู้เรียนครบถ้วน | I4: มีการส่งเสริมให้ผู้เรียนได้ฝึกทักษะการคิดได้อย่างเหมาะสมดีมาก | J4: มีการส่งเสริมให้ผู้เรียนได้ฝึกทักษะการสื่อสารได้อย่างเหมาะสมดีมาก | K4: -
A5: 46204.346 | B5: bnco0950@signalschool.ac.th | C5: ส.อ.ไชยพร รักษากุล | D5: ลักษณะทางทหาร "ดีมาก" มีความเชื่อมั่นในตนเองเป็นแบบอย่างที่ดีแก่ผู้เรียนได้ | E5: เสียงดังฟังชัดและจังหวะการพูดไม่ช้า/เร็วเกินไป | F5: มีประมวลรายวิชาและแนะนำเนื้อหาวิชา | G5: มีการจัดเตรียมสื่อการเรียนการสอนและรวบรวมแหล่งอ้างอิงไว้อย่างเหมาะสม | H5: มีการจัดการเรียนการสอนเป็นไปตามประมวลรายวิชาครบถ้วนและการนำเข้าสู่บทเรียนให้ข้อมูลที่เป็นประโยชน์แก่ผู้เรียนครบถ้วน | I5: มีการส่งเสริมให้ผู้เรียนได้ฝึกทักษะการคิดได้อย่างเหมาะสมดีมาก | J5: มีการส่งเสริมให้ผู้เรียนได้ฝึกทักษะการสื่อสารได้อย่างเหมาะสมดีมาก | K5: ไม่มีครับ
A6: 46204.467 | B6: bnco0951@signalschool.ac.th | C6: ส.อ.ไชยพร รักษากุล | D6: ลักษณะทางทหาร "ดีมาก" มีความเชื่อมั่นในตนเองเป็นแบบอย่างที่ดีแก่ผู้เรียนได้ | E6: เสียงดังฟังชัดและจังหวะการพูดไม่ช้า/เร็วเกินไป | F6: มีประมวลรายวิชาและแนะนำเนื้อหาวิชา | G6: มีการจัดเตรียมสื่อการเรียนการสอนและรวบรวมแหล่งอ้างอิงไว้อย่างเหมาะสม | H6: มีการจัดการเรียนการสอนเป็นไปตามประมวลรายวิชาครบถ้วนและการนำเข้าสู่บทเรียนให้ข้อมูลที่เป็นประโยชน์แก่ผู้เรียนครบถ้วน | I6: มีการส่งเสริมให้ผู้เรียนได้ฝึกทักษะการคิดได้อย่างเหมาะสมดีมาก | J6: มีการส่งเสริมให้ผู้เรียนได้ฝึกทักษะการสื่อสารได้อย่างเหมาะสมดีมาก
A7: 46206.594 | B7: bnco0920@signalschool.ac.th | C7: จ.ส.ท.ณัฐพงษ์ / จ.ส.ต.ภาณุพงษ์ | D7: ลักษณะทางทหาร "ดีมาก" มีความเชื่อมั่นในตนเองเป็นแบบอย่างที่ดีแก่ผู้เรียนได้ | E7: เสียงดังฟังชัดและจังหวะการพูดไม่ช้า/เร็วเกินไป | F7: มีประมวลรายวิชาและแนะนำเนื้อหาวิชา | G7: มีการจัดเตรียมสื่อการเรียนการสอนและรวบรวมแหล่งอ้างอิงไว้อย่างเหมาะสม | H7: มีการจัดการเรียนการสอนเป็นไปตามประมวลรายวิชาครบถ้วนและการนำเข้าสู่บทเรียนให้ข้อมูลที่เป็นประโยชน์แก่ผู้เรียนครบถ้วน | I7: มีการส่งเสริมให้ผู้เรียนได้ฝึกทักษะการคิดได้อย่างเหมาะสมดีมาก | J7: มีการส่งเสริมให้ผู้เรียนได้ฝึกทักษะการสื่อสารได้อย่างเหมาะสมดีมาก | K7: สอนดีมากครับ
A8: 46212.576 | B8: bnco0906@signalschool.ac.th | C8: ส.อ.ไชยพร รักษากุล | D8: ลักษณะทางทหาร "มีความเหมาะสม" มีความเชื่อมั่นในตนเองปานกลาง | E8: เสียงเบา "แต่" จังหวะการพูดไม่ช้า/เร็วเกินไป | F8: มีประมวลรายวิชา "แต่ไม่มีการ" แนะนำเนื้อหาวิชา | G8: มีการจัดเตรียมสื่อการเรียนการสอน "แต่ไม่ปรากฏ" แหล่งอ้างอิง | H8: มีการจัดการเรียนการสอนเป็นไปตามประมวลรายวิชาบางส่วน "หรือ" การนำเข้าสู่บทเรียนให้ข้อมูลที่เป็นประโยชน์แก่ผู้เรียน (อย่างใดอย่างหนึ่ง) | I8: มีการส่งเสริมให้ผู้เรียนได้ฝึกทักษะการคิดได้อย่างเหมาะสม | J8: มีการส่งเสริมให้ผู้เรียนได้ฝึกทักษะการสื่อสารได้อย่างเหมาะสม
A9: 46212.614 | B9: bnco0955@signalschool.ac.th | C9: อาจารย์ประจำวิชาการจัดหน่วยทหารสื่อสาร | D9: ลักษณะทางทหาร "ดีมาก" มีความเชื่อมั่นในตนเองเป็นแบบอย่างที่ดีแก่ผู้เรียนได้ | E9: เสียงดังฟังชัดและจังหวะการพูดไม่ช้า/เร็วเกินไป | F9: มีประมวลรายวิชาและแนะนำเนื้อหาวิชา | G9: มีการจัดเตรียมสื่อการเรียนการสอนและรวบรวมแหล่งอ้างอิงไว้อย่างเหมาะสม | H9: มีการจัดการเรียนการสอนเป็นไปตามประมวลรายวิชาครบถ้วนและการนำเข้าสู่บทเรียนให้ข้อมูลที่เป็นประโยชน์แก่ผู้เรียนครบถ้วน | I9: มีการส่งเสริมให้ผู้เรียนได้ฝึกทักษะการคิดได้อย่างเหมาะสมดีมาก | J9: มีการส่งเสริมให้ผู้เรียนได้ฝึกทักษะการสื่อสารได้อย่างเหมาะสมดีมาก
A10: 46212.616 | B10: bnco0974@signalschool.ac.th | C10: ร.ท.ศุภรัชฎ หมอกสุข | D10: ลักษณะทางทหาร "มีความเหมาะสม" มีความเชื่อมั่นในตนเองปานกลาง | E10: เสียงดังฟังชัดและจังหวะการพูดไม่ช้า/เร็วเกินไป | F10: มีประมวลรายวิชาและแนะนำเนื้อหาวิชา | G10: มีการจัดเตรียมสื่อการเรียนการสอนและรวบรวมแหล่งอ้างอิงไว้อย่างเหมาะสม | H10: มีการจัดการเรียนการสอนเป็นไปตามประมวลรายวิชาครบถ้วนและการนำเข้าสู่บทเรียนให้ข้อมูลที่เป็นประโยชน์แก่ผู้เรียนครบถ้วน | I10: มีการส่งเสริมให้ผู้เรียนได้ฝึกทักษะการคิดได้อย่างเหมาะสมดีมาก | J10: มีการส่งเสริมให้ผู้เรียนได้ฝึกทักษะการสื่อสารได้อย่างเหมาะสมดีมาก | K10: -
A11: 46212.617 | B11: bnco0919@signalschool.ac.th | C11: ร.ท.ศุภรัชฎ หมอกสุข | D11: ลักษณะทางทหาร "ดีมาก" มีความเชื่อมั่นในตนเองเป็นแบบอย่างที่ดีแก่ผู้เรียนได้ | E11: เสียงดังฟังชัดและจังหวะการพูดไม่ช้า/เร็วเกินไป | F11: มีประมวลรายวิชาและแนะนำเนื้อหาวิชา | G11: มีการจัดเตรียมสื่อการเรียนการสอนและรวบรวมแหล่งอ้างอิงไว้อย่างเหมาะสม | H11: มีการจัดการเรียนการสอนเป็นไปตามประมวลรายวิชาครบถ้วนและการนำเข้าสู่บทเรียนให้ข้อมูลที่เป็นประโยชน์แก่ผู้เรียนครบถ้วน | I11: มีการส่งเสริมให้ผู้เรียนได้ฝึกทักษะการคิดได้อย่างเหมาะสมดีมาก | J11: มีการส่งเสริมให้ผู้เรียนได้ฝึกทักษะการสื่อสารได้อย่างเหมาะสมดีมาก
A12: 46212.617 | B12: bnco0937@signalschool.ac.th | C12: ร.ท.ศุภรัชฎ หมอกสุข | D12: ลักษณะทางทหาร "ดีมาก" มีความเชื่อมั่นในตนเองเป็นแบบอย่างที่ดีแก่ผู้เรียนได้ | E12: เสียงดังฟังชัดและจังหวะการพูดไม่ช้า/เร็วเกินไป | F12: มีประมวลรายวิชาและแนะนำเนื้อหาวิชา | G12: มีการจัดเตรียมสื่อการเรียนการสอนและรวบรวมแหล่งอ้างอิงไว้อย่างเหมาะสม | H12: มีการจัดการเรียนการสอนเป็นไปตามประมวลรายวิชาครบถ้วนและการนำเข้าสู่บทเรียนให้ข้อมูลที่เป็นประโยชน์แก่ผู้เรียนครบถ้วน | I12: มีการส่งเสริมให้ผู้เรียนได้ฝึกทักษะการคิดได้อย่างเหมาะสมดีมาก | J12: มีการส่งเสริมให้ผู้เรียนได้ฝึกทักษะการสื่อสารได้อย่างเหมาะสมดีมาก
A13: 46212.617 | B13: bnco0970@signalschool.ac.th | C13: ส.อ.ภาณุพงศ์ อุทธิยา | D13: ลักษณะทางทหาร "ดีมาก" มีความเชื่อมั่นในตนเองเป็นแบบอย่างที่ดีแก่ผู้เรียนได้ | E13: เสียงดังฟังชัดและจังหวะการพูดไม่ช้า/เร็วเกินไป | F13: มีประมวลรายวิชาและแนะนำเนื้อหาวิชา | G13: มีการจัดเตรียมสื่อการเรียนการสอนและรวบรวมแหล่งอ้างอิงไว้อย่างเหมาะสม | H13: มีการจัดการเรียนการสอนเป็นไปตามประมวลรายวิชาครบถ้วนและการนำเข้าสู่บทเรียนให้ข้อมูลที่เป็นประโยชน์แก่ผู้เรียนครบถ้วน | I13: มีการส่งเสริมให้ผู้เรียนได้ฝึกทักษะการคิดได้อย่างเหมาะสมดีมาก | J13: มีการส่งเสริมให้ผู้เรียนได้ฝึกทักษะการสื่อสารได้อย่างเหมาะสมดีมาก | K13: ไม่มีครับ
A14: 46212.617 | B14: bnco0973@signalschool.ac.th | C14: ร.ท.ศุภรัชฎ หมอกสุข | D14: ลักษณะทางทหาร "ดีมาก" มีความเชื่อมั่นในตนเองเป็นแบบอย่างที่ดีแก่ผู้เรียนได้ | E14: เสียงดังฟังชัดและจังหวะการพูดไม่ช้า/เร็วเกินไป | F14: มีประมวลรายวิชาและแนะนำเนื้อหาวิชา | G14: มีการจัดเตรียมสื่อการเรียนการสอนและรวบรวมแหล่งอ้างอิงไว้อย่างเหมาะสม | H14: มีการจัดการเรียนการสอนเป็นไปตามประมวลรายวิชาครบถ้วนและการนำเข้าสู่บทเรียนให้ข้อมูลที่เป็นประโยชน์แก่ผู้เรียนครบถ้วน | I14: มีการส่งเสริมให้ผู้เรียนได้ฝึกทักษะการคิดได้อย่างเหมาะสมดีมาก | J14: มีการส่งเสริมให้ผู้เรียนได้ฝึกทักษะการสื่อสารได้อย่างเหมาะสมดีมาก
A15: 46212.617 | B15: bnco0938@signalschool.ac.th | C15: ร.ท.ศุภรัชฏ หมอกสุข | D15: ลักษณะทางทหาร "มีความเหมาะสม" มีความเชื่อมั่นในตนเองปานกลาง | E15: เสียงเบา "แต่" จังหวะการพูดไม่ช้า/เร็วเกินไป | F15: มีประมวลรายวิชาและแนะนำเนื้อหาวิชา | G15: มีการจัดเตรียมสื่อการเรียนการสอน "แต่ไม่ปรากฏ" แหล่งอ้างอิง | H15: มีการจัดการเรียนการสอนเป็นไปตามประมวลรายวิชาบางส่วน "หรือ" การนำเข้าสู่บทเรียนให้ข้อมูลที่เป็นประโยชน์แก่ผู้เรียน (อย่างใดอย่างหนึ่ง) | I15: มีการส่งเสริมให้ผู้เรียนได้ฝึกทักษะการคิดได้อย่างเหมาะสมดีมาก | J15: มีการส่งเสริมให้ผู้เรียนได้ฝึกทักษะการสื่อสารได้อย่างเหมาะสมดีมาก
A16: 46212.617 | B16: bnco0958@signalschool.ac.th | C16: ร.ท.ศุภรัชฎ หมอกสุข | D16: ลักษณะทางทหาร "ดีมาก" มีความเชื่อมั่นในตนเองเป็นแบบอย่างที่ดีแก่ผู้เรียนได้ | E16: เสียงดังฟังชัดและจังหวะการพูดไม่ช้า/เร็วเกินไป | F16: มีประมวลรายวิชาและแนะนำเนื้อหาวิชา | G16: มีการจัดเตรียมสื่อการเรียนการสอนและรวบรวมแหล่งอ้างอิงไว้อย่างเหมาะสม | H16: มีการจัดการเรียนการสอนเป็นไปตามประมวลรายวิชาครบถ้วนและการนำเข้าสู่บทเรียนให้ข้อมูลที่เป็นประโยชน์แก่ผู้เรียนครบถ้วน | I16: มีการส่งเสริมให้ผู้เรียนได้ฝึกทักษะการคิดได้อย่างเหมาะสมดีมาก | J16: มีการส่งเสริมให้ผู้เรียนได้ฝึกทักษะการสื่อสารได้อย่างเหมาะสมดีมาก
A17: 46212.617 | B17: bnco0935@signalschool.ac.th | C17: ร.ท.ศุภรัชฎ หมอกสุข | D17: ลักษณะทางทหาร "ดีมาก" มีความเชื่อมั่นในตนเองเป็นแบบอย่างที่ดีแก่ผู้เรียนได้ | E17: เสียงดังฟังชัดและจังหวะการพูดไม่ช้า/เร็วเกินไป | F17: มีประมวลรายวิชาและแนะนำเนื้อหาวิชา | G17: มีการจัดเตรียมสื่อการเรียนการสอนและรวบรวมแหล่งอ้างอิงไว้อย่างเหมาะสม | H17: มีการจัดการเรียนการสอนเป็นไปตามประมวลรายวิชาครบถ้วนและการนำเข้าสู่บทเรียนให้ข้อมูลที่เป็นประโยชน์แก่ผู้เรียนครบถ้วน | I17: มีการส่งเสริมให้ผู้เรียนได้ฝึกทักษะการคิดได้อย่างเหมาะสมดีมาก | J17: มีการส่งเสริมให้ผู้เรียนได้ฝึกทักษะการสื่อสารได้อย่างเหมาะสมดีมาก
A18: 46212.617 | B18: bnco0905@signalschool.ac.th | C18: ร.ท. ศุภรัชฎ หมอกสุข | D18: ลักษณะทางทหาร "ดีมาก" มีความเชื่อมั่นในตนเองเป็นแบบอย่างที่ดีแก่ผู้เรียนได้ | E18: เสียงดังฟังชัดและจังหวะการพูดไม่ช้า/เร็วเกินไป | F18: มีประมวลรายวิชาและแนะนำเนื้อหาวิชา | G18: มีการจัดเตรียมสื่อการเรียนการสอนและรวบรวมแหล่งอ้างอิงไว้อย่างเหมาะสม | H18: มีการจัดการเรียนการสอนเป็นไปตามประมวลรายวิชาครบถ้วนและการนำเข้าสู่บทเรียนให้ข้อมูลที่เป็นประโยชน์แก่ผู้เรียนครบถ้วน | I18: มีการส่งเสริมให้ผู้เรียนได้ฝึกทักษะการคิดได้อย่างเหมาะสมดีมาก | J18: มีการส่งเสริมให้ผู้เรียนได้ฝึกทักษะการสื่อสารได้อย่างเหมาะสมดีมาก
A19: 46212.617 | B19: bnco0933@signalschool.ac.th | C19: ร.ท.ศุภรัชฏ หมอกสุข | D19: ลักษณะทางทหาร "ดีมาก" มีความเชื่อมั่นในตนเองเป็นแบบอย่างที่ดีแก่ผู้เรียนได้ | E19: เสียงดังฟังชัดและจังหวะการพูดไม่ช้า/เร็วเกินไป | F19: มีประมวลรายวิชาและแนะนำเนื้อหาวิชา | G19: มีการจัดเตรียมสื่อการเรียนการสอนและรวบรวมแหล่งอ้างอิงไว้อย่างเหมาะสม | H19: มีการจัดการเรียนการสอนเป็นไปตามประมวลรายวิชาครบถ้วนและการนำเข้าสู่บทเรียนให้ข้อมูลที่เป็นประโยชน์แก่ผู้เรียนครบถ้วน | I19: มีการส่งเสริมให้ผู้เรียนได้ฝึกทักษะการคิดได้อย่างเหมาะสมดีมาก | J19: มีการส่งเสริมให้ผู้เรียนได้ฝึกทักษะการสื่อสารได้อย่างเหมาะสมดีมาก
A20: 46212.617 | B20: bnco0903@signalschool.ac.th | C20: ร.ท.ศุภรัชฎ หมอกสุข | D20: ลักษณะทางทหาร "ดีมาก" มีความเชื่อมั่นในตนเองเป็นแบบอย่างที่ดีแก่ผู้เรียนได้ | E20: เสียงดังฟังชัดและจังหวะการพูดไม่ช้า/เร็วเกินไป | F20: มีประมวลรายวิชาและแนะนำเนื้อหาวิชา | G20: มีการจัดเตรียมสื่อการเรียนการสอนและรวบรวมแหล่งอ้างอิงไว้อย่างเหมาะสม | H20: มีการจัดการเรียนการสอนเป็นไปตามประมวลรายวิชาครบถ้วนและการนำเข้าสู่บทเรียนให้ข้อมูลที่เป็นประโยชน์แก่ผู้เรียนครบถ้วน | I20: มีการส่งเสริมให้ผู้เรียนได้ฝึกทักษะการคิดได้อย่างเหมาะสมดีมาก | J20: มีการส่งเสริมให้ผู้เรียนได้ฝึกทักษะการสื่อสารได้อย่างเหมาะสมดีมาก
A21: 46212.617 | B21: bnco0923@signalschool.ac.th | C21: ร.ท.ศุภรัชฎ หมอกสุข | D21: ลักษณะทางทหาร "ดีมาก" มีความเชื่อมั่นในตนเองเป็นแบบอย่างที่ดีแก่ผู้เรียนได้ | E21: เสียงดังฟังชัดและจังหวะการพูดไม่ช้า/เร็วเกินไป | F21: มีประมวลรายวิชาและแนะนำเนื้อหาวิชา | G21: มีการจัดเตรียมสื่อการเรียนการสอนและรวบรวมแหล่งอ้างอิงไว้อย่างเหมาะสม | H21: มีการจัดการเรียนการสอนเป็นไปตามประมวลรายวิชาครบถ้วนและการนำเข้าสู่บทเรียนให้ข้อมูลที่เป็นประโยชน์แก่ผู้เรียนครบถ้วน | I21: มีการส่งเสริมให้ผู้เรียนได้ฝึกทักษะการคิดได้อย่างเหมาะสมดีมาก | J21: มีการส่งเสริมให้ผู้เรียนได้ฝึกทักษะการสื่อสารได้อย่างเหมาะสมดีมาก
A22: 46212.617 | B22: bnco0962@signalschool.ac.th | C22: ร.ท.ศุภรัชฎ หมอกสุข | D22: ลักษณะทางทหาร "ดีมาก" มีความเชื่อมั่นในตนเองเป็นแบบอย่างที่ดีแก่ผู้เรียนได้ | E22: เสียงดังฟังชัดและจังหวะการพูดไม่ช้า/เร็วเกินไป | F22: มีประมวลรายวิชาและแนะนำเนื้อหาวิชา | G22: มีการจัดเตรียมสื่อการเรียนการสอนและรวบรวมแหล่งอ้างอิงไว้อย่างเหมาะสม | H22: มีการจัดการเรียนการสอนเป็นไปตามประมวลรายวิชาครบถ้วนและการนำเข้าสู่บทเรียนให้ข้อมูลที่เป็นประโยชน์แก่ผู้เรียนครบถ้วน | I22: มีการส่งเสริมให้ผู้เรียนได้ฝึกทักษะการคิดได้อย่างเหมาะสมดีมาก | J22: มีการส่งเสริมให้ผู้เรียนได้ฝึกทักษะการสื่อสารได้อย่างเหมาะสมดีมาก
A23: 46212.617 | B23: bnco0932@signalschool.ac.th | C23: ร.ท.ศุภรัชฎ หมอกสุข | D23: ลักษณะทางทหาร "ดีมาก" มีความเชื่อมั่นในตนเองเป็นแบบอย่างที่ดีแก่ผู้เรียนได้ | E23: เสียงดังฟังชัดและจังหวะการพูดไม่ช้า/เร็วเกินไป | F23: มีประมวลรายวิชาและแนะนำเนื้อหาวิชา | G23: มีการจัดเตรียมสื่อการเรียนการสอนและรวบรวมแหล่งอ้างอิงไว้อย่างเหมาะสม | H23: มีการจัดการเรียนการสอนเป็นไปตามประมวลรายวิชาครบถ้วนและการนำเข้าสู่บทเรียนให้ข้อมูลที่เป็นประโยชน์แก่ผู้เรียนครบถ้วน | I23: มีการส่งเสริมให้ผู้เรียนได้ฝึกทักษะการคิดได้อย่างเหมาะสมดีมาก | J23: มีการส่งเสริมให้ผู้เรียนได้ฝึกทักษะการสื่อสารได้อย่างเหมาะสมดีมาก
A24: 46212.617 | B24: bnco0941@signalschool.ac.th | C24: ร.ท.ศุภรัชภ หมอกสุช | D24: ลักษณะทางทหาร "ดีมาก" มีความเชื่อมั่นในตนเองเป็นแบบอย่างที่ดีแก่ผู้เรียนได้ | E24: เสียงดังฟังชัดและจังหวะการพูดไม่ช้า/เร็วเกินไป | F24: มีประมวลรายวิชาและแนะนำเนื้อหาวิชา | G24: มีการจัดเตรียมสื่อการเรียนการสอนและรวบรวมแหล่งอ้างอิงไว้อย่างเหมาะสม | H24: มีการจัดการเรียนการสอนเป็นไปตามประมวลรายวิชาครบถ้วนและการนำเข้าสู่บทเรียนให้ข้อมูลที่เป็นประโยชน์แก่ผู้เรียนครบถ้วน | I24: มีการส่งเสริมให้ผู้เรียนได้ฝึกทักษะการคิดได้อย่างเหมาะสมดีมาก | J24: มีการส่งเสริมให้ผู้เรียนได้ฝึกทักษะการสื่อสารได้อย่างเหมาะสมดีมาก
A25: 46212.617 | B25: bnco0934@signalschool.ac.th | C25: ร.ท.ศุภรัฎ หมอกสุข | D25: ลักษณะทางทหาร "ดีมาก" มีความเชื่อมั่นในตนเองเป็นแบบอย่างที่ดีแก่ผู้เรียนได้ | E25: เสียงดังฟังชัดและจังหวะการพูดไม่ช้า/เร็วเกินไป | F25: มีประมวลรายวิชาและแนะนำเนื้อหาวิชา | G25: มีการจัดเตรียมสื่อการเรียนการสอนและรวบรวมแหล่งอ้างอิงไว้อย่างเหมาะสม | H25: มีการจัดการเรียนการสอนเป็นไปตามประมวลรายวิชาครบถ้วนและการนำเข้าสู่บทเรียนให้ข้อมูลที่เป็นประโยชน์แก่ผู้เรียนครบถ้วน | I25: มีการส่งเสริมให้ผู้เรียนได้ฝึกทักษะการคิดได้อย่างเหมาะสมดีมาก | J25: มีการส่งเสริมให้ผู้เรียนได้ฝึกทักษะการสื่อสารได้อย่างเหมาะสมดีมาก
... A27: 46212.618 | B27: bnco0963@signalschool.ac.th | C27: ร.ท.ศุภรัชฎ หมอกสุข | D27: ลักษณะทางทหาร "ดีมาก" มีความเชื่อมั่นในตนเองเป็นแบบอย่างที่ดีแก่ผู้เรียนได้ | E27: เสียงดังฟังชัดและจังหวะการพูดไม่ช้า/เร็วเกินไป | F27: มีประมวลรายวิชาและแนะนำเนื้อหาวิชา | G27: มีการจัดเตรียมสื่อการเรียนการสอนและรวบรวมแหล่งอ้างอิงไว้อย่างเหมาะสม | H27: มีการจัดการเรียนการสอนเป็นไปตามประมวลรายวิชาครบถ้วนและการนำเข้าสู่บทเรียนให้ข้อมูลที่เป็นประโยชน์แก่ผู้เรียนครบถ้วน | I27: มีการส่งเสริมให้ผู้เรียนได้ฝึกทักษะการคิดได้อย่างเหมาะสมดีมาก | J27: มีการส่งเสริมให้ผู้เรียนได้ฝึกทักษะการสื่อสารได้อย่างเหมาะสมดีมาก
A28: 46212.618 | B28: bnco0922@signalschool.ac.th | C28: ร.ท.ศุภรัชฎ หมอกสุข | D28: ลักษณะทางทหาร "ดีมาก" มีความเชื่อมั่นในตนเองเป็นแบบอย่างที่ดีแก่ผู้เรียนได้ | E28: เสียงดังฟังชัดและจังหวะการพูดไม่ช้า/เร็วเกินไป | F28: มีประมวลรายวิชาและแนะนำเนื้อหาวิชา | G28: มีการจัดเตรียมสื่อการเรียนการสอนและรวบรวมแหล่งอ้างอิงไว้อย่างเหมาะสม | H28: มีการจัดการเรียนการสอนเป็นไปตามประมวลรายวิชาครบถ้วนและการนำเข้าสู่บทเรียนให้ข้อมูลที่เป็นประโยชน์แก่ผู้เรียนครบถ้วน | I28: มีการส่งเสริมให้ผู้เรียนได้ฝึกทักษะการคิดได้อย่างเหมาะสมดีมาก | J28: มีการส่งเสริมให้ผู้เรียนได้ฝึกทักษะการสื่อสารได้อย่างเหมาะสมดีมาก | K28: -
A29: 46212.618 | B29: bnco0924@signalschool.ac.th | C29: ร.ท.ศุภรัชฎ หมอกสุข | D29: ลักษณะทางทหาร "ดีมาก" มีความเชื่อมั่นในตนเองเป็นแบบอย่างที่ดีแก่ผู้เรียนได้ | E29: เสียงดังฟังชัดและจังหวะการพูดไม่ช้า/เร็วเกินไป | F29: มีประมวลรายวิชาและแนะนำเนื้อหาวิชา | G29: มีการจัดเตรียมสื่อการเรียนการสอนและรวบรวมแหล่งอ้างอิงไว้อย่างเหมาะสม | H29: มีการจัดการเรียนการสอนเป็นไปตามประมวลรายวิชาครบถ้วนและการนำเข้าสู่บทเรียนให้ข้อมูลที่เป็นประโยชน์แก่ผู้เรียนครบถ้วน | I29: มีการส่งเสริมให้ผู้เรียนได้ฝึกทักษะการคิดได้อย่างเหมาะสมดีมาก | J29: มีการส่งเสริมให้ผู้เรียนได้ฝึกทักษะการสื่อสารได้อย่างเหมาะสมดีมาก
A30: 46212.618 | B30: bnco0952@signalschool.ac.th | C30: ร.ท.ศุภรัชฎ หมอกสุข | D30: ลักษณะทางทหาร "ดีมาก" มีความเชื่อมั่นในตนเองเป็นแบบอย่างที่ดีแก่ผู้เรียนได้ | E30: เสียงดังฟังชัดและจังหวะการพูดไม่ช้า/เร็วเกินไป | F30: มีประมวลรายวิชาและแนะนำเนื้อหาวิชา | G30: มีการจัดเตรียมสื่อการเรียนการสอนและรวบรวมแหล่งอ้างอิงไว้อย่างเหมาะสม | H30: มีการจัดการเรียนการสอนเป็นไปตามประมวลรายวิชาครบถ้วนและการนำเข้าสู่บทเรียนให้ข้อมูลที่เป็นประโยชน์แก่ผู้เรียนครบถ้วน | I30: มีการส่งเสริมให้ผู้เรียนได้ฝึกทักษะการคิดได้อย่างเหมาะสมดีมาก | J30: มีการส่งเสริมให้ผู้เรียนได้ฝึกทักษะการสื่อสารได้อย่างเหมาะสมดีมาก
A31: 46212.618 | B31: bnco0904@signalschool.ac.th | C31: ร.ท.ศุภรัชฎ หมอกสุข | D31: ลักษณะทางทหาร "ดีมาก" มีความเชื่อมั่นในตนเองเป็นแบบอย่างที่ดีแก่ผู้เรียนได้ | E31: เสียงดังฟังชัดและจังหวะการพูดไม่ช้า/เร็วเกินไป | F31: มีประมวลรายวิชาและแนะนำเนื้อหาวิชา | G31: มีการจัดเตรียมสื่อการเรียนการสอนและรวบรวมแหล่งอ้างอิงไว้อย่างเหมาะสม | H31: มีการจัดการเรียนการสอนเป็นไปตามประมวลรายวิชาครบถ้วนและการนำเข้าสู่บทเรียนให้ข้อมูลที่เป็นประโยชน์แก่ผู้เรียนครบถ้วน | I31: มีการส่งเสริมให้ผู้เรียนได้ฝึกทักษะการคิดได้อย่างเหมาะสมดีมาก | J31: มีการส่งเสริมให้ผู้เรียนได้ฝึกทักษะการสื่อสารได้อย่างเหมาะสมดีมาก
A32: 46212.618 | B32: bnco0978@signalschool.ac.th | C32: ร.ท.ศุภรัชฎ หมอกสุข | D32: ลักษณะทางทหาร "ดีมาก" มีความเชื่อมั่นในตนเองเป็นแบบอย่างที่ดีแก่ผู้เรียนได้ | E32: เสียงดังฟังชัดและจังหวะการพูดไม่ช้า/เร็วเกินไป | F32: มีประมวลรายวิชาและแนะนำเนื้อหาวิชา | G32: มีการจัดเตรียมสื่อการเรียนการสอนและรวบรวมแหล่งอ้างอิงไว้อย่างเหมาะสม | H32: มีการจัดการเรียนการสอนเป็นไปตามประมวลรายวิชาครบถ้วนและการนำเข้าสู่บทเรียนให้ข้อมูลที่เป็นประโยชน์แก่ผู้เรียนครบถ้วน | I32: มีการส่งเสริมให้ผู้เรียนได้ฝึกทักษะการคิดได้อย่างเหมาะสมดีมาก | J32: มีการส่งเสริมให้ผู้เรียนได้ฝึกทักษะการสื่อสารได้อย่างเหมาะสมดีมาก
A33: 46212.618 | B33: bnco0916@signalschool.ac.th | C33: ร.ท.ศุภรัชฎ หมอกสุข | D33: ลักษณะทางทหาร "ดีมาก" มีความเชื่อมั่นในตนเองเป็นแบบอย่างที่ดีแก่ผู้เรียนได้ | E33: เสียงดังฟังชัดและจังหวะการพูดไม่ช้า/เร็วเกินไป | F33: มีประมวลรายวิชาและแนะนำเนื้อหาวิชา | G33: มีการจัดเตรียมสื่อการเรียนการสอนและรวบรวมแหล่งอ้างอิงไว้อย่างเหมาะสม | H33: มีการจัดการเรียนการสอนเป็นไปตามประมวลรายวิชาครบถ้วนและการนำเข้าสู่บทเรียนให้ข้อมูลที่เป็นประโยชน์แก่ผู้เรียนครบถ้วน | I33: มีการส่งเสริมให้ผู้เรียนได้ฝึกทักษะการคิดได้อย่างเหมาะสมดีมาก | J33: มีการส่งเสริมให้ผู้เรียนได้ฝึกทักษะการสื่อสารได้อย่างเหมาะสมดีมาก
A34: 46212.618 | B34: bnco0914@signalschool.ac.th | C34: ร.ท.ศุภรัชฏ หมอกสุข | D34: ลักษณะทางทหาร "ดีมาก" มีความเชื่อมั่นในตนเองเป็นแบบอย่างที่ดีแก่ผู้เรียนได้ | E34: เสียงดังฟังชัดและจังหวะการพูดไม่ช้า/เร็วเกินไป | F34: มีประมวลรายวิชาและแนะนำเนื้อหาวิชา | G34: มีการจัดเตรียมสื่อการเรียนการสอนและรวบรวมแหล่งอ้างอิงไว้อย่างเหมาะสม | H34: มีการจัดการเรียนการสอนเป็นไปตามประมวลรายวิชาครบถ้วนและการนำเข้าสู่บทเรียนให้ข้อมูลที่เป็นประโยชน์แก่ผู้เรียนครบถ้วน | I34: มีการส่งเสริมให้ผู้เรียนได้ฝึกทักษะการคิดได้อย่างเหมาะสมดีมาก | J34: มีการส่งเสริมให้ผู้เรียนได้ฝึกทักษะการสื่อสารได้อย่างเหมาะสมดีมาก
A35: 46212.618 | B35: bnco0911@signalschool.ac.th | C35: ร.ท.ศุภรัชฎ หมอกสุข | D35: ลักษณะทางทหาร "ดีมาก" มีความเชื่อมั่นในตนเองเป็นแบบอย่างที่ดีแก่ผู้เรียนได้ | E35: เสียงดังฟังชัดและจังหวะการพูดไม่ช้า/เร็วเกินไป | F35: มีประมวลรายวิชาและแนะนำเนื้อหาวิชา | G35: มีการจัดเตรียมสื่อการเรียนการสอนและรวบรวมแหล่งอ้างอิงไว้อย่างเหมาะสม | H35: มีการจัดการเรียนการสอนเป็นไปตามประมวลรายวิชาครบถ้วนและการนำเข้าสู่บทเรียนให้ข้อมูลที่เป็นประโยชน์แก่ผู้เรียนครบถ้วน | I35: มีการส่งเสริมให้ผู้เรียนได้ฝึกทักษะการคิดได้อย่างเหมาะสมดีมาก | J35: มีการส่งเสริมให้ผู้เรียนได้ฝึกทักษะการสื่อสารได้อย่างเหมาะสมดีมาก
A36: 46212.618 | B36: bnco0971@signalschool.ac.th | C36: ร.ท.ศุภรัชฎ หมอกสุข | D36: ลักษณะทางทหาร "ดีมาก" มีความเชื่อมั่นในตนเองเป็นแบบอย่างที่ดีแก่ผู้เรียนได้ | E36: เสียงดังฟังชัดและจังหวะการพูดไม่ช้า/เร็วเกินไป | F36: มีประมวลรายวิชาและแนะนำเนื้อหาวิชา | G36: มีการจัดเตรียมสื่อการเรียนการสอนและรวบรวมแหล่งอ้างอิงไว้อย่างเหมาะสม | H36: มีการจัดการเรียนการสอนเป็นไปตามประมวลรายวิชาครบถ้วนและการนำเข้าสู่บทเรียนให้ข้อมูลที่เป็นประโยชน์แก่ผู้เรียนครบถ้วน | I36: มีการส่งเสริมให้ผู้เรียนได้ฝึกทักษะการคิดได้อย่างเหมาะสมดีมาก | J36: มีการส่งเสริมให้ผู้เรียนได้ฝึกทักษะการสื่อสารได้อย่างเหมาะสมดีมาก
A37: 46212.618 | B37: bnco0972@signalschool.ac.th | C37: ร.ท.ศุภรัชฎ หมอกสุข | D37: ลักษณะทางทหาร "ดีมาก" มีความเชื่อมั่นในตนเองเป็นแบบอย่างที่ดีแก่ผู้เรียนได้ | E37: เสียงดังฟังชัดและจังหวะการพูดไม่ช้า/เร็วเกินไป | F37: มีประมวลรายวิชาและแนะนำเนื้อหาวิชา | G37: มีการจัดเตรียมสื่อการเรียนการสอนและรวบรวมแหล่งอ้างอิงไว้อย่างเหมาะสม | H37: มีการจัดการเรียนการสอนเป็นไปตามประมวลรายวิชาครบถ้วนและการนำเข้าสู่บทเรียนให้ข้อมูลที่เป็นประโยชน์แก่ผู้เรียนครบถ้วน | I37: มีการส่งเสริมให้ผู้เรียนได้ฝึกทักษะการคิดได้อย่างเหมาะสมดีมาก | J37: มีการส่งเสริมให้ผู้เรียนได้ฝึกทักษะการสื่อสารได้อย่างเหมาะสมดีมาก
A38: 46212.618 | B38: bnco0926@signalschool.ac.th | C38: ร.ท.ศุภรัชฎ หมอกสุข | D38: ลักษณะทางทหาร "ดีมาก" มีความเชื่อมั่นในตนเองเป็นแบบอย่างที่ดีแก่ผู้เรียนได้ | E38: เสียงดังฟังชัดและจังหวะการพูดไม่ช้า/เร็วเกินไป | F38: มีประมวลรายวิชาและแนะนำเนื้อหาวิชา | G38: มีการจัดเตรียมสื่อการเรียนการสอนและรวบรวมแหล่งอ้างอิงไว้อย่างเหมาะสม | H38: มีการจัดการเรียนการสอนเป็นไปตามประมวลรายวิชาครบถ้วนและการนำเข้าสู่บทเรียนให้ข้อมูลที่เป็นประโยชน์แก่ผู้เรียนครบถ้วน | I38: มีการส่งเสริมให้ผู้เรียนได้ฝึกทักษะการคิดได้อย่างเหมาะสมดีมาก | J38: มีการส่งเสริมให้ผู้เรียนได้ฝึกทักษะการสื่อสารได้อย่างเหมาะสมดีมาก
A39: 46212.618 | B39: bnco0918@signalschool.ac.th | C39: ร.ท.ศุภรัชฎ หมอกสุข | D39: ลักษณะทางทหาร "ดีมาก" มีความเชื่อมั่นในตนเองเป็นแบบอย่างที่ดีแก่ผู้เรียนได้ | E39: เสียงดังฟังชัดและจังหวะการพูดไม่ช้า/เร็วเกินไป | F39: มีประมวลรายวิชาและแนะนำเนื้อหาวิชา | G39: มีการจัดเตรียมสื่อการเรียนการสอนและรวบรวมแหล่งอ้างอิงไว้อย่างเหมาะสม | H39: มีการจัดการเรียนการสอนเป็นไปตามประมวลรายวิชาครบถ้วนและการนำเข้าสู่บทเรียนให้ข้อมูลที่เป็นประโยชน์แก่ผู้เรียนครบถ้วน | I39: มีการส่งเสริมให้ผู้เรียนได้ฝึกทักษะการคิดได้อย่างเหมาะสมดีมาก | J39: มีการส่งเสริมให้ผู้เรียนได้ฝึกทักษะการสื่อสารได้อย่างเหมาะสมดีมาก
A40: 46212.618 | B40: bnco0953@signalschool.ac.th | C40: ร.ท.ศุภรัชฎ หมอกสุข | D40: ลักษณะทางทหาร "ดีมาก" มีความเชื่อมั่นในตนเองเป็นแบบอย่างที่ดีแก่ผู้เรียนได้ | E40: เสียงดังฟังชัดและจังหวะการพูดไม่ช้า/เร็วเกินไป | F40: มีประมวลรายวิชาและแนะนำเนื้อหาวิชา | G40: มีการจัดเตรียมสื่อการเรียนการสอนและรวบรวมแหล่งอ้างอิงไว้อย่างเหมาะสม | H40: มีการจัดการเรียนการสอนเป็นไปตามประมวลรายวิชาครบถ้วนและการนำเข้าสู่บทเรียนให้ข้อมูลที่เป็นประโยชน์แก่ผู้เรียนครบถ้วน | I40: มีการส่งเสริมให้ผู้เรียนได้ฝึกทักษะการคิดได้อย่างเหมาะสมดีมาก | J40: มีการส่งเสริมให้ผู้เรียนได้ฝึกทักษะการสื่อสารได้อย่างเหมาะสมดีมาก
A41: 46212.618 | B41: bnco0968@signalschool.ac.th | C41: ร.ท.ศุภรัชฎ หมอกสุข | D41: ลักษณะทางทหาร "ดีมาก" มีความเชื่อมั่นในตนเองเป็นแบบอย่างที่ดีแก่ผู้เรียนได้ | E41: เสียงดังฟังชัดและจังหวะการพูดไม่ช้า/เร็วเกินไป | F41: มีประมวลรายวิชาและแนะนำเนื้อหาวิชา | G41: มีการจัดเตรียมสื่อการเรียนการสอนและรวบรวมแหล่งอ้างอิงไว้อย่างเหมาะสม | H41: มีการจัดการเรียนการสอนเป็นไปตามประมวลรายวิชาครบถ้วนและการนำเข้าสู่บทเรียนให้ข้อมูลที่เป็นประโยชน์แก่ผู้เรียนครบถ้วน | I41: มีการส่งเสริมให้ผู้เรียนได้ฝึกทักษะการคิดได้อย่างเหมาะสมดีมาก | J41: มีการส่งเสริมให้ผู้เรียนได้ฝึกทักษะการสื่อสารได้อย่างเหมาะสมดีมาก | K41: ไม่มี
...

Sheet ค่า 1.1
A1: ประทับเวลา | B1: ที่อยู่อีเมล | C1: ยศ ชื่อ-สกุล ครู-อาจารย์ผู้สอน | E1: 1. บุคลิกภาพและลักษณะท่าทางของอาจารย์ผู้สอน | F1: 2. การพูดและการใช้นํ้าเสียง | G1: 3. การเตรียมการสอน | H1: 4. การจัดเตรียมสื่อการสอน | I1: 5. การถ่ายทอดความรู้และการนำเข้าสู่บทเรียน | J1: 6. ผู้เรียนได้ฝึกทักษะการคิดวิเคราะห์ หรือการพัฒนาความคิดสร้างสรรค์จากการเรียนรายวิชานี้มากน้อยเพียงใด | K1: 7. ผู้เรียนได้ฝึกทักษะการสื่อสาร การนำเสนอ และการใช้งานเทคโนโลยีสารสนเทศจากการเรียนรายวิชานี้มากน้อยเพียงใด | M1: ตรวจสอบผู้เข้าประเมิน
A2: ='1.1'!A:A -> 46181.522 | B2: ='1.1'!B:B -> bnco0910@signalschool.ac.th | C2: ='1.1'!C:C -> ส.อ.ไชยพร รัก รักษากุล | D2: 1 | E2: =IFERROR(vlookup('1.1'!D:D,lookup!$A$2:$B$4,2,false),0) -> 5 | F2: =IFERROR(vlookup('1.1'!E:E,lookup!$A$6:$B$8,2,false),0) -> 5 | G2: =IFERROR(vlookup('1.1'!F:F,lookup!$A$10:$B$12,2,false),0) -> 5 | H2: =IFERROR(vlookup('1.1'!G:G,lookup!$A$14:$B$16,2,false),0) -> 5 | I2: =IFERROR(vlookup('1.1'!H:H,lookup!$A$18:$B$20,2,false),0) -> 5 | J2: =IFERROR(vlookup('1.1'!I:I,lookup!$A$22:$B$24,2,false),0) -> 5 | K2: =IFERROR(vlookup('1.1'!J:J,lookup!$A$26:$B$28,2,false),0) -> 5 | M2: 1 | N2: =CONCAT(R2,"@signalschool.ac.th") -> bnco0901@signalschool.ac.th | O2: =IFERROR(VLOOKUP(N2,B$2:D$81,3,FALSE),0) -> 1 | R2: bnco0901
A3: ='1.1'!A:A -> 46189.429 | B3: ='1.1'!B:B -> bnco0936@signalschool.ac.th | C3: ='1.1'!C:C -> จ.ส.ต.ภานุพงษ์ ใจเฉื่อย | D3: 1 | E3: =IFERROR(vlookup('1.1'!D:D,lookup!$A$2:$B$4,2,false),0) -> 5 | F3: =IFERROR(vlookup('1.1'!E:E,lookup!$A$6:$B$8,2,false),0) -> 5 | G3: =IFERROR(vlookup('1.1'!F:F,lookup!$A$10:$B$12,2,false),0) -> 5 | H3: =IFERROR(vlookup('1.1'!G:G,lookup!$A$14:$B$16,2,false),0) -> 5 | I3: =IFERROR(vlookup('1.1'!H:H,lookup!$A$18:$B$20,2,false),0) -> 5 | J3: =IFERROR(vlookup('1.1'!I:I,lookup!$A$22:$B$24,2,false),0) -> 5 | K3: =IFERROR(vlookup('1.1'!J:J,lookup!$A$26:$B$28,2,false),0) -> 5 | M3: 2 | N3: =CONCAT(R3,"@signalschool.ac.th") -> bnco0902@signalschool.ac.th | O3: =IFERROR(VLOOKUP(N3,B$2:D$81,3,FALSE),0) -> 1 | R3: bnco0902
A4: ='1.1'!A:A -> 46189.435 | B4: ='1.1'!B:B -> bnco0940@signalschool.ac.th | C4: ='1.1'!C:C -> ส.อ.ไชยพร รักษากุล | D4: 1 | E4: =IFERROR(vlookup('1.1'!D:D,lookup!$A$2:$B$4,2,false),0) -> 5 | F4: =IFERROR(vlookup('1.1'!E:E,lookup!$A$6:$B$8,2,false),0) -> 5 | G4: =IFERROR(vlookup('1.1'!F:F,lookup!$A$10:$B$12,2,false),0) -> 5 | H4: =IFERROR(vlookup('1.1'!G:G,lookup!$A$14:$B$16,2,false),0) -> 5 | I4: =IFERROR(vlookup('1.1'!H:H,lookup!$A$18:$B$20,2,false),0) -> 5 | J4: =IFERROR(vlookup('1.1'!I:I,lookup!$A$22:$B$24,2,false),0) -> 5 | K4: =IFERROR(vlookup('1.1'!J:J,lookup!$A$26:$B$28,2,false),0) -> 5 | M4: 3 | N4: =CONCAT(R4,"@signalschool.ac.th") -> bnco0903@signalschool.ac.th | O4: =IFERROR(VLOOKUP(N4,B$2:D$81,3,FALSE),0) -> 1 | R4: bnco0903
A5: ='1.1'!A:A -> 46204.346 | B5: ='1.1'!B:B -> bnco0950@signalschool.ac.th | C5: ='1.1'!C:C -> ส.อ.ไชยพร รักษากุล | D5: 1 | E5: =IFERROR(vlookup('1.1'!D:D,lookup!$A$2:$B$4,2,false),0) -> 5 | F5: =IFERROR(vlookup('1.1'!E:E,lookup!$A$6:$B$8,2,false),0) -> 5 | G5: =IFERROR(vlookup('1.1'!F:F,lookup!$A$10:$B$12,2,false),0) -> 5 | H5: =IFERROR(vlookup('1.1'!G:G,lookup!$A$14:$B$16,2,false),0) -> 5 | I5: =IFERROR(vlookup('1.1'!H:H,lookup!$A$18:$B$20,2,false),0) -> 5 | J5: =IFERROR(vlookup('1.1'!I:I,lookup!$A$22:$B$24,2,false),0) -> 5 | K5: =IFERROR(vlookup('1.1'!J:J,lookup!$A$26:$B$28,2,false),0) -> 5 | M5: 4 | N5: =CONCAT(R5,"@signalschool.ac.th") -> bnco0904@signalschool.ac.th | O5: =IFERROR(VLOOKUP(N5,B$2:D$81,3,FALSE),0) -> 1 | R5: bnco0904
A6: ='1.1'!A:A -> 46204.467 | B6: ='1.1'!B:B -> bnco0951@signalschool.ac.th | C6: ='1.1'!C:C -> ส.อ.ไชยพร รักษากุล | D6: 1 | E6: =IFERROR(vlookup('1.1'!D:D,lookup!$A$2:$B$4,2,false),0) -> 5 | F6: =IFERROR(vlookup('1.1'!E:E,lookup!$A$6:$B$8,2,false),0) -> 5 | G6: =IFERROR(vlookup('1.1'!F:F,lookup!$A$10:$B$12,2,false),0) -> 5 | H6: =IFERROR(vlookup('1.1'!G:G,lookup!$A$14:$B$16,2,false),0) -> 5 | I6: =IFERROR(vlookup('1.1'!H:H,lookup!$A$18:$B$20,2,false),0) -> 5 | J6: =IFERROR(vlookup('1.1'!I:I,lookup!$A$22:$B$24,2,false),0) -> 5 | K6: =IFERROR(vlookup('1.1'!J:J,lookup!$A$26:$B$28,2,false),0) -> 5 | M6: 5 | N6: =CONCAT(R6,"@signalschool.ac.th") -> bnco0905@signalschool.ac.th | O6: =IFERROR(VLOOKUP(N6,B$2:D$81,3,FALSE),0) -> 1 | R6: bnco0905
A7: ='1.1'!A:A -> 46206.594 | B7: ='1.1'!B:B -> bnco0920@signalschool.ac.th | C7: ='1.1'!C:C -> จ.ส.ท.ณัฐพงษ์ / จ.ส.ต.ภาณุพงษ์ | D7: 1 | E7: =IFERROR(vlookup('1.1'!D:D,lookup!$A$2:$B$4,2,false),0) -> 5 | F7: =IFERROR(vlookup('1.1'!E:E,lookup!$A$6:$B$8,2,false),0) -> 5 | G7: =IFERROR(vlookup('1.1'!F:F,lookup!$A$10:$B$12,2,false),0) -> 5 | H7: =IFERROR(vlookup('1.1'!G:G,lookup!$A$14:$B$16,2,false),0) -> 5 | I7: =IFERROR(vlookup('1.1'!H:H,lookup!$A$18:$B$20,2,false),0) -> 5 | J7: =IFERROR(vlookup('1.1'!I:I,lookup!$A$22:$B$24,2,false),0) -> 5 | K7: =IFERROR(vlookup('1.1'!J:J,lookup!$A$26:$B$28,2,false),0) -> 5 | M7: 6 | N7: =CONCAT(R7,"@signalschool.ac.th") -> bnco0906@signalschool.ac.th | O7: =IFERROR(VLOOKUP(N7,B$2:D$81,3,FALSE),0) -> 1 | R7: bnco0906
A8: ='1.1'!A:A -> 46212.576 | B8: ='1.1'!B:B -> bnco0906@signalschool.ac.th | C8: ='1.1'!C:C -> ส.อ.ไชยพร รักษากุล | D8: 1 | E8: =IFERROR(vlookup('1.1'!D:D,lookup!$A$2:$B$4,2,false),0) -> 3 | F8: =IFERROR(vlookup('1.1'!E:E,lookup!$A$6:$B$8,2,false),0) -> 3 | G8: =IFERROR(vlookup('1.1'!F:F,lookup!$A$10:$B$12,2,false),0) -> 3 | H8: =IFERROR(vlookup('1.1'!G:G,lookup!$A$14:$B$16,2,false),0) -> 3 | I8: =IFERROR(vlookup('1.1'!H:H,lookup!$A$18:$B$20,2,false),0) -> 3 | J8: =IFERROR(vlookup('1.1'!I:I,lookup!$A$22:$B$24,2,false),0) -> 3 | K8: =IFERROR(vlookup('1.1'!J:J,lookup!$A$26:$B$28,2,false),0) -> 3 | M8: 7 | N8: =CONCAT(R8,"@signalschool.ac.th") -> bnco0907@signalschool.ac.th | O8: =IFERROR(VLOOKUP(N8,B$2:D$81,3,FALSE),0) -> 1 | R8: bnco0907
A9: ='1.1'!A:A -> 46212.614 | B9: ='1.1'!B:B -> bnco0955@signalschool.ac.th | C9: ='1.1'!C:C -> อาจารย์ประจำวิชาการจัดหน่วยทหารสื่อสาร | D9: 1 | E9: =IFERROR(vlookup('1.1'!D:D,lookup!$A$2:$B$4,2,false),0) -> 5 | F9: =IFERROR(vlookup('1.1'!E:E,lookup!$A$6:$B$8,2,false),0) -> 5 | G9: =IFERROR(vlookup('1.1'!F:F,lookup!$A$10:$B$12,2,false),0) -> 5 | H9: =IFERROR(vlookup('1.1'!G:G,lookup!$A$14:$B$16,2,false),0) -> 5 | I9: =IFERROR(vlookup('1.1'!H:H,lookup!$A$18:$B$20,2,false),0) -> 5 | J9: =IFERROR(vlookup('1.1'!I:I,lookup!$A$22:$B$24,2,false),0) -> 5 | K9: =IFERROR(vlookup('1.1'!J:J,lookup!$A$26:$B$28,2,false),0) -> 5 | M9: 8 | N9: =CONCAT(R9,"@signalschool.ac.th") -> bnco0908@signalschool.ac.th | O9: =IFERROR(VLOOKUP(N9,B$2:D$81,3,FALSE),0) -> 1 | R9: bnco0908
A10: ='1.1'!A:A -> 46212.616 | B10: ='1.1'!B:B -> bnco0974@signalschool.ac.th | C10: ='1.1'!C:C -> ร.ท.ศุภรัชฎ หมอกสุข | D10: 1 | E10: =IFERROR(vlookup('1.1'!D:D,lookup!$A$2:$B$4,2,false),0) -> 3 | F10: =IFERROR(vlookup('1.1'!E:E,lookup!$A$6:$B$8,2,false),0) -> 5 | G10: =IFERROR(vlookup('1.1'!F:F,lookup!$A$10:$B$12,2,false),0) -> 5 | H10: =IFERROR(vlookup('1.1'!G:G,lookup!$A$14:$B$16,2,false),0) -> 5 | I10: =IFERROR(vlookup('1.1'!H:H,lookup!$A$18:$B$20,2,false),0) -> 5 | J10: =IFERROR(vlookup('1.1'!I:I,lookup!$A$22:$B$24,2,false),0) -> 5 | K10: =IFERROR(vlookup('1.1'!J:J,lookup!$A$26:$B$28,2,false),0) -> 5 | M10: 9 | N10: =CONCAT(R10,"@signalschool.ac.th") -> bnco0909@signalschool.ac.th | O10: =IFERROR(VLOOKUP(N10,B$2:D$81,3,FALSE),0) -> 1 | R10: bnco0909
A11: ='1.1'!A:A -> 46212.617 | B11: ='1.1'!B:B -> bnco0919@signalschool.ac.th | C11: ='1.1'!C:C -> ร.ท.ศุภรัชฎ หมอกสุข | D11: 1 | E11: =IFERROR(vlookup('1.1'!D:D,lookup!$A$2:$B$4,2,false),0) -> 5 | F11: =IFERROR(vlookup('1.1'!E:E,lookup!$A$6:$B$8,2,false),0) -> 5 | G11: =IFERROR(vlookup('1.1'!F:F,lookup!$A$10:$B$12,2,false),0) -> 5 | H11: =IFERROR(vlookup('1.1'!G:G,lookup!$A$14:$B$16,2,false),0) -> 5 | I11: =IFERROR(vlookup('1.1'!H:H,lookup!$A$18:$B$20,2,false),0) -> 5 | J11: =IFERROR(vlookup('1.1'!I:I,lookup!$A$22:$B$24,2,false),0) -> 5 | K11: =IFERROR(vlookup('1.1'!J:J,lookup!$A$26:$B$28,2,false),0) -> 5 | M11: 10 | N11: =CONCAT(R11,"@signalschool.ac.th") -> bnco0910@signalschool.ac.th | O11: =IFERROR(VLOOKUP(N11,B$2:D$81,3,FALSE),0) -> 1 | R11: bnco0910
A12: ='1.1'!A:A -> 46212.617 | B12: ='1.1'!B:B -> bnco0937@signalschool.ac.th | C12: ='1.1'!C:C -> ร.ท.ศุภรัชฎ หมอกสุข | D12: 1 | E12: =IFERROR(vlookup('1.1'!D:D,lookup!$A$2:$B$4,2,false),0) -> 5 | F12: =IFERROR(vlookup('1.1'!E:E,lookup!$A$6:$B$8,2,false),0) -> 5 | G12: =IFERROR(vlookup('1.1'!F:F,lookup!$A$10:$B$12,2,false),0) -> 5 | H12: =IFERROR(vlookup('1.1'!G:G,lookup!$A$14:$B$16,2,false),0) -> 5 | I12: =IFERROR(vlookup('1.1'!H:H,lookup!$A$18:$B$20,2,false),0) -> 5 | J12: =IFERROR(vlookup('1.1'!I:I,lookup!$A$22:$B$24,2,false),0) -> 5 | K12: =IFERROR(vlookup('1.1'!J:J,lookup!$A$26:$B$28,2,false),0) -> 5 | M12: 11 | N12: =CONCAT(R12,"@signalschool.ac.th") -> bnco0911@signalschool.ac.th | O12: =IFERROR(VLOOKUP(N12,B$2:D$81,3,FALSE),0) -> 1 | R12: bnco0911
A13: ='1.1'!A:A -> 46212.617 | B13: ='1.1'!B:B -> bnco0970@signalschool.ac.th | C13: ='1.1'!C:C -> ส.อ.ภาณุพงศ์ อุทธิยา | D13: 1 | E13: =IFERROR(vlookup('1.1'!D:D,lookup!$A$2:$B$4,2,false),0) -> 5 | F13: =IFERROR(vlookup('1.1'!E:E,lookup!$A$6:$B$8,2,false),0) -> 5 | G13: =IFERROR(vlookup('1.1'!F:F,lookup!$A$10:$B$12,2,false),0) -> 5 | H13: =IFERROR(vlookup('1.1'!G:G,lookup!$A$14:$B$16,2,false),0) -> 5 | I13: =IFERROR(vlookup('1.1'!H:H,lookup!$A$18:$B$20,2,false),0) -> 5 | J13: =IFERROR(vlookup('1.1'!I:I,lookup!$A$22:$B$24,2,false),0) -> 5 | K13: =IFERROR(vlookup('1.1'!J:J,lookup!$A$26:$B$28,2,false),0) -> 5 | M13: 12 | N13: =CONCAT(R13,"@signalschool.ac.th") -> bnco0912@signalschool.ac.th | O13: =IFERROR(VLOOKUP(N13,B$2:D$81,3,FALSE),0) -> 1 | R13: bnco0912
... A81: ='1.1'!A:A -> 46213.453 | B81: ='1.1'!B:B -> bnco0975@signalschool.ac.th | C81: ='1.1'!C:C -> ร.ท.ศุภรัชฎ หมอกสุข | D81: 1 | E81: =IFERROR(vlookup('1.1'!D:D,lookup!$A$2:$B$4,2,false),0) -> 5 | F81: =IFERROR(vlookup('1.1'!E:E,lookup!$A$6:$B$8,2,false),0) -> 5 | G81: =IFERROR(vlookup('1.1'!F:F,lookup!$A$10:$B$12,2,false),0) -> 3 | H81: =IFERROR(vlookup('1.1'!G:G,lookup!$A$14:$B$16,2,false),0) -> 5 | I81: =IFERROR(vlookup('1.1'!H:H,lookup!$A$18:$B$20,2,false),0) -> 3 | J81: =IFERROR(vlookup('1.1'!I:I,lookup!$A$22:$B$24,2,false),0) -> 5 | K81: =IFERROR(vlookup('1.1'!J:J,lookup!$A$26:$B$28,2,false),0) -> 5 | M81: 80 | N81: =CONCAT(R81,"@signalschool.ac.th") -> bnco0980@signalschool.ac.th | O81: =IFERROR(VLOOKUP(N81,B$2:D$81,3,FALSE),0) -> 1 | R81: bnco0980
E82: =AVERAGE(E2:E81) -> 4.775 | F82: =AVERAGE(F2:F81) -> 4.875 | G82: =AVERAGE(G2:G81) -> 4.825 | H82: =AVERAGE(H2:H81) -> 4.875 | I82: =AVERAGE(I2:I81) -> 4.875 | J82: =AVERAGE(J2:J81) -> 4.925 | K82: =AVERAGE(K2:K81) -> 4.875 | L82: =AVERAGE(E82:K82) -> 4.8607143 | N82: ยอดผู้เข้าประเมิน | O82: =SUM(O2:O81) -> 80
N83: ภาพรวมร้อยละ | O83: =(O82*100)/80 -> 100

Sheet 1.2
A1: ประทับเวลา | B1: ที่อยู่อีเมล | C1: ยศ ชื่อ-สกุล ครู-อาจารย์ผู้สอน | D1: 1. บุคลิกภาพและลักษณะท่าทางของอาจารย์ผู้สอน | E1: 2. การพูดและการใช้นํ้าเสียง | F1: 3. การเตรียมการสอน | G1: 4. การจัดเตรียมสื่อการสอน | H1: 5. การถ่ายทอดความรู้และการนำเข้าสู่บทเรียน | I1: 6. ผู้เรียนได้ฝึกทักษะการคิดวิเคราะห์ หรือการพัฒนาความคิดสร้างสรรค์จากการเรียนรายวิชานี้มากน้อยเพียงใด | J1: 7. ผู้เรียนได้ฝึกทักษะการสื่อสาร การนำเสนอ และการใช้งานเทคโนโลยีสารสนเทศจากการเรียนรายวิชานี้มากน้อยเพียงใด | K1: ข้อเสนอแนะอื่นๆ
A2: 46153.361 | B2: bnco0958@signalschool.ac.th | C2: ส.อ.พิจักษณ์ คงแสง | D2: ลักษณะทางทหาร "ดีมาก" มีความเชื่อมั่นในตนเองเป็นแบบอย่างที่ดีแก่ผู้เรียนได้ | E2: เสียงดังฟังชัดและจังหวะการพูดไม่ช้า/เร็วเกินไป | F2: มีประมวลรายวิชาและแนะนำเนื้อหาวิชา | G2: มีการจัดเตรียมสื่อการเรียนการสอนและรวบรวมแหล่งอ้างอิงไว้อย่างเหมาะสม | H2: มีการจัดการเรียนการสอนเป็นไปตามประมวลรายวิชาครบถ้วนและการนำเข้าสู่บทเรียนให้ข้อมูลที่เป็นประโยชน์แก่ผู้เรียนครบถ้วน | I2: มีการส่งเสริมให้ผู้เรียนได้ฝึกทักษะการคิดได้อย่างเหมาะสมดีมาก | J2: มีการส่งเสริมให้ผู้เรียนได้ฝึกทักษะการสื่อสารได้อย่างเหมาะสมดีมาก
A3: 46153.361 | B3: bnco0934@signalschool.ac.th | C3: ส.อ.สุขเกษม พิบูลสุขสิน | D3: ลักษณะทางทหาร "ดีมาก" มีความเชื่อมั่นในตนเองเป็นแบบอย่างที่ดีแก่ผู้เรียนได้ | E3: เสียงดังฟังชัดและจังหวะการพูดไม่ช้า/เร็วเกินไป | F3: มีประมวลรายวิชาและแนะนำเนื้อหาวิชา | G3: มีการจัดเตรียมสื่อการเรียนการสอนและรวบรวมแหล่งอ้างอิงไว้อย่างเหมาะสม | H3: มีการจัดการเรียนการสอนเป็นไปตามประมวลรายวิชาครบถ้วนและการนำเข้าสู่บทเรียนให้ข้อมูลที่เป็นประโยชน์แก่ผู้เรียนครบถ้วน | I3: มีการส่งเสริมให้ผู้เรียนได้ฝึกทักษะการคิดได้อย่างเหมาะสมดีมาก | J3: มีการส่งเสริมให้ผู้เรียนได้ฝึกทักษะการสื่อสารได้อย่างเหมาะสมดีมาก
A4: 46153.362 | B4: bnco0971@signalschool.ac.th | C4: ส.อ.วิศวะ กิจสุวรรณ์ | D4: ลักษณะทางทหาร "ดีมาก" มีความเชื่อมั่นในตนเองเป็นแบบอย่างที่ดีแก่ผู้เรียนได้ | E4: เสียงเบา "แต่" จังหวะการพูดไม่ช้า/เร็วเกินไป | F4: มีประมวลรายวิชาและแนะนำเนื้อหาวิชา | G4: มีการจัดเตรียมสื่อการเรียนการสอนและรวบรวมแหล่งอ้างอิงไว้อย่างเหมาะสม | H4: มีการจัดการเรียนการสอนเป็นไปตามประมวลรายวิชาครบถ้วนและการนำเข้าสู่บทเรียนให้ข้อมูลที่เป็นประโยชน์แก่ผู้เรียนครบถ้วน | I4: มีการส่งเสริมให้ผู้เรียนได้ฝึกทักษะการคิดได้อย่างเหมาะสมดีมาก | J4: มีการส่งเสริมให้ผู้เรียนได้ฝึกทักษะการสื่อสารได้อย่างเหมาะสมดีมาก
A5: 46153.363 | B5: bnco0940@signalschool.ac.th | C5: จ.ส.อ.พัลลภ ดวงเดือน | D5: ลักษณะทางทหาร "ดีมาก" มีความเชื่อมั่นในตนเองเป็นแบบอย่างที่ดีแก่ผู้เรียนได้ | E5: เสียงดังฟังชัดและจังหวะการพูดไม่ช้า/เร็วเกินไป | F5: มีประมวลรายวิชาและแนะนำเนื้อหาวิชา | G5: มีการจัดเตรียมสื่อการเรียนการสอนและรวบรวมแหล่งอ้างอิงไว้อย่างเหมาะสม | H5: มีการจัดการเรียนการสอนเป็นไปตามประมวลรายวิชาครบถ้วนและการนำเข้าสู่บทเรียนให้ข้อมูลที่เป็นประโยชน์แก่ผู้เรียนครบถ้วน | I5: มีการส่งเสริมให้ผู้เรียนได้ฝึกทักษะการคิดได้อย่างเหมาะสมดีมาก | J5: มีการส่งเสริมให้ผู้เรียนได้ฝึกทักษะการสื่อสารได้อย่างเหมาะสมดีมาก
A6: 46153.363 | B6: bnco0967@signalschool.ac.th | C6: จ.ส.อ.พัลลภ ดวงเดือน | D6: ลักษณะทางทหาร "ดีมาก" มีความเชื่อมั่นในตนเองเป็นแบบอย่างที่ดีแก่ผู้เรียนได้ | E6: เสียงดังฟังชัดและจังหวะการพูดไม่ช้า/เร็วเกินไป | F6: มีประมวลรายวิชาและแนะนำเนื้อหาวิชา | G6: มีการจัดเตรียมสื่อการเรียนการสอนและรวบรวมแหล่งอ้างอิงไว้อย่างเหมาะสม | H6: มีการจัดการเรียนการสอนเป็นไปตามประมวลรายวิชาครบถ้วนและการนำเข้าสู่บทเรียนให้ข้อมูลที่เป็นประโยชน์แก่ผู้เรียนครบถ้วน | I6: มีการส่งเสริมให้ผู้เรียนได้ฝึกทักษะการคิดได้อย่างเหมาะสมดีมาก | J6: มีการส่งเสริมให้ผู้เรียนได้ฝึกทักษะการสื่อสารได้อย่างเหมาะสมดีมาก
A7: 46153.364 | B7: bnco0906@signalschool.ac.th | C7: จ.ส.อ.พัลลภ ดวงเดือน | D7: ลักษณะทางทหาร "มีความเหมาะสม" มีความเชื่อมั่นในตนเองปานกลาง | E7: เสียงดังฟังชัดและจังหวะการพูดไม่ช้า/เร็วเกินไป | F7: มีประมวลรายวิชาและแนะนำเนื้อหาวิชา | G7: มีการจัดเตรียมสื่อการเรียนการสอนและรวบรวมแหล่งอ้างอิงไว้อย่างเหมาะสม | H7: มีการจัดการเรียนการสอนเป็นไปตามประมวลรายวิชาบางส่วน "หรือ" การนำเข้าสู่บทเรียนให้ข้อมูลที่เป็นประโยชน์แก่ผู้เรียน (อย่างใดอย่างหนึ่ง) | I7: มีการส่งเสริมให้ผู้เรียนได้ฝึกทักษะการคิดได้อย่างเหมาะสม | J7: มีการส่งเสริมให้ผู้เรียนได้ฝึกทักษะการสื่อสารได้อย่างเหมาะสม
A8: 46153.364 | B8: bnco0943@signalschool.ac.th | C8: จ.ส.อ.พัลลภ ดวงเดือน | D8: ลักษณะทางทหาร "ดีมาก" มีความเชื่อมั่นในตนเองเป็นแบบอย่างที่ดีแก่ผู้เรียนได้ | E8: เสียงดังฟังชัดและจังหวะการพูดไม่ช้า/เร็วเกินไป | F8: มีประมวลรายวิชาและแนะนำเนื้อหาวิชา | G8: มีการจัดเตรียมสื่อการเรียนการสอนและรวบรวมแหล่งอ้างอิงไว้อย่างเหมาะสม | H8: มีการจัดการเรียนการสอนเป็นไปตามประมวลรายวิชาครบถ้วนและการนำเข้าสู่บทเรียนให้ข้อมูลที่เป็นประโยชน์แก่ผู้เรียนครบถ้วน | I8: มีการส่งเสริมให้ผู้เรียนได้ฝึกทักษะการคิดได้อย่างเหมาะสมดีมาก | J8: มีการส่งเสริมให้ผู้เรียนได้ฝึกทักษะการสื่อสารได้อย่างเหมาะสมดีมาก
A9: 46153.364 | B9: bnco0924@signalschool.ac.th | C9: จ.ส.อ. พัลลภ ดวงเดือน | D9: ลักษณะทางทหาร "ดีมาก" มีความเชื่อมั่นในตนเองเป็นแบบอย่างที่ดีแก่ผู้เรียนได้ | E9: เสียงดังฟังชัดและจังหวะการพูดไม่ช้า/เร็วเกินไป | F9: มีประมวลรายวิชาและแนะนำเนื้อหาวิชา | G9: มีการจัดเตรียมสื่อการเรียนการสอนและรวบรวมแหล่งอ้างอิงไว้อย่างเหมาะสม | H9: มีการจัดการเรียนการสอนเป็นไปตามประมวลรายวิชาครบถ้วนและการนำเข้าสู่บทเรียนให้ข้อมูลที่เป็นประโยชน์แก่ผู้เรียนครบถ้วน | I9: มีการส่งเสริมให้ผู้เรียนได้ฝึกทักษะการคิดได้อย่างเหมาะสมดีมาก | J9: มีการส่งเสริมให้ผู้เรียนได้ฝึกทักษะการสื่อสารได้อย่างเหมาะสมดีมาก
A10: 46153.364 | B10: bnco0939@signalschool.ac.th | C10: จ.ส.อ.พัลลภ ดวงเดือน | D10: ลักษณะทางทหาร "ดีมาก" มีความเชื่อมั่นในตนเองเป็นแบบอย่างที่ดีแก่ผู้เรียนได้ | E10: เสียงดังฟังชัดและจังหวะการพูดไม่ช้า/เร็วเกินไป | F10: มีประมวลรายวิชาและแนะนำเนื้อหาวิชา | G10: มีการจัดเตรียมสื่อการเรียนการสอนและรวบรวมแหล่งอ้างอิงไว้อย่างเหมาะสม | H10: มีการจัดการเรียนการสอนเป็นไปตามประมวลรายวิชาครบถ้วนและการนำเข้าสู่บทเรียนให้ข้อมูลที่เป็นประโยชน์แก่ผู้เรียนครบถ้วน | I10: มีการส่งเสริมให้ผู้เรียนได้ฝึกทักษะการคิดได้อย่างเหมาะสมดีมาก | J10: มีการส่งเสริมให้ผู้เรียนได้ฝึกทักษะการสื่อสารได้อย่างเหมาะสมดีมาก
A11: 46153.364 | B11: bnco0925@signalschool.ac.th | C11: ส.อ. กานต์ เรณู ณ อยุธยา | D11: ลักษณะทางทหาร "ดีมาก" มีความเชื่อมั่นในตนเองเป็นแบบอย่างที่ดีแก่ผู้เรียนได้ | E11: เสียงดังฟังชัดและจังหวะการพูดไม่ช้า/เร็วเกินไป | F11: มีประมวลรายวิชาและแนะนำเนื้อหาวิชา | G11: มีการจัดเตรียมสื่อการเรียนการสอนและรวบรวมแหล่งอ้างอิงไว้อย่างเหมาะสม | H11: มีการจัดการเรียนการสอนเป็นไปตามประมวลรายวิชาครบถ้วนและการนำเข้าสู่บทเรียนให้ข้อมูลที่เป็นประโยชน์แก่ผู้เรียนครบถ้วน | I11: มีการส่งเสริมให้ผู้เรียนได้ฝึกทักษะการคิดได้อย่างเหมาะสม | J11: มีการส่งเสริมให้ผู้เรียนได้ฝึกทักษะการสื่อสารได้อย่างเหมาะสม
A12: 46153.364 | B12: bnco0910@signalschool.ac.th | C12: จ.ส.อ.พัลลภ ดวงเดือน | D12: ลักษณะทางทหาร "ดีมาก" มีความเชื่อมั่นในตนเองเป็นแบบอย่างที่ดีแก่ผู้เรียนได้ | E12: เสียงดังฟังชัดและจังหวะการพูดไม่ช้า/เร็วเกินไป | F12: มีประมวลรายวิชาและแนะนำเนื้อหาวิชา | G12: มีการจัดเตรียมสื่อการเรียนการสอนและรวบรวมแหล่งอ้างอิงไว้อย่างเหมาะสม | H12: มีการจัดการเรียนการสอนเป็นไปตามประมวลรายวิชาครบถ้วนและการนำเข้าสู่บทเรียนให้ข้อมูลที่เป็นประโยชน์แก่ผู้เรียนครบถ้วน | I12: มีการส่งเสริมให้ผู้เรียนได้ฝึกทักษะการคิดได้อย่างเหมาะสมดีมาก | J12: มีการส่งเสริมให้ผู้เรียนได้ฝึกทักษะการสื่อสารได้อย่างเหมาะสมดีมาก
A13: 46153.365 | B13: bnco0936@signalschool.ac.th | C13: จ.ส.อ.พัลลภ ดวงเดือน | D13: ลักษณะทางทหาร "ดีมาก" มีความเชื่อมั่นในตนเองเป็นแบบอย่างที่ดีแก่ผู้เรียนได้ | E13: เสียงดังฟังชัดและจังหวะการพูดไม่ช้า/เร็วเกินไป | F13: มีประมวลรายวิชาและแนะนำเนื้อหาวิชา | G13: มีการจัดเตรียมสื่อการเรียนการสอนและรวบรวมแหล่งอ้างอิงไว้อย่างเหมาะสม | H13: มีการจัดการเรียนการสอนเป็นไปตามประมวลรายวิชาครบถ้วนและการนำเข้าสู่บทเรียนให้ข้อมูลที่เป็นประโยชน์แก่ผู้เรียนครบถ้วน | I13: มีการส่งเสริมให้ผู้เรียนได้ฝึกทักษะการคิดได้อย่างเหมาะสม | J13: มีการส่งเสริมให้ผู้เรียนได้ฝึกทักษะการสื่อสารได้อย่างเหมาะสมดีมาก
... A15: 46153.365 | B15: bnco0952@signalschool.ac.th | C15: จ.ส.อ.พัลลภ ดวงเดือน | D15: ลักษณะทางทหาร "ดีมาก" มีความเชื่อมั่นในตนเองเป็นแบบอย่างที่ดีแก่ผู้เรียนได้ | E15: เสียงดังฟังชัดและจังหวะการพูดไม่ช้า/เร็วเกินไป | F15: มีประมวลรายวิชาและแนะนำเนื้อหาวิชา | G15: มีการจัดเตรียมสื่อการเรียนการสอนและรวบรวมแหล่งอ้างอิงไว้อย่างเหมาะสม | H15: มีการจัดการเรียนการสอนเป็นไปตามประมวลรายวิชาครบถ้วนและการนำเข้าสู่บทเรียนให้ข้อมูลที่เป็นประโยชน์แก่ผู้เรียนครบถ้วน | I15: มีการส่งเสริมให้ผู้เรียนได้ฝึกทักษะการคิดได้อย่างเหมาะสมดีมาก | J15: มีการส่งเสริมให้ผู้เรียนได้ฝึกทักษะการสื่อสารได้อย่างเหมาะสมดีมาก
A16: 46153.365 | B16: bnco0955@signalschool.ac.th | C16: จ.ส.อ.พัลลภ ดวงเดือน | D16: ลักษณะทางทหาร "ดีมาก" มีความเชื่อมั่นในตนเองเป็นแบบอย่างที่ดีแก่ผู้เรียนได้ | E16: เสียงดังฟังชัดและจังหวะการพูดไม่ช้า/เร็วเกินไป | F16: มีประมวลรายวิชาและแนะนำเนื้อหาวิชา | G16: มีการจัดเตรียมสื่อการเรียนการสอนและรวบรวมแหล่งอ้างอิงไว้อย่างเหมาะสม | H16: มีการจัดการเรียนการสอนเป็นไปตามประมวลรายวิชาครบถ้วนและการนำเข้าสู่บทเรียนให้ข้อมูลที่เป็นประโยชน์แก่ผู้เรียนครบถ้วน | I16: มีการส่งเสริมให้ผู้เรียนได้ฝึกทักษะการคิดได้อย่างเหมาะสมดีมาก | J16: มีการส่งเสริมให้ผู้เรียนได้ฝึกทักษะการสื่อสารได้อย่างเหมาะสมดีมาก | K16: อาจารย์สอนเนื้อหาดี การเรียนการสอนสนุกครับ
A17: 46153.365 | B17: bnco0951@signalschool.ac.th | C17: จ.ส.อ.พัลลภ ดวงเดือน | D17: ลักษณะทางทหาร "ดีมาก" มีความเชื่อมั่นในตนเองเป็นแบบอย่างที่ดีแก่ผู้เรียนได้ | E17: เสียงดังฟังชัดและจังหวะการพูดไม่ช้า/เร็วเกินไป | F17: มีประมวลรายวิชาและแนะนำเนื้อหาวิชา | G17: มีการจัดเตรียมสื่อการเรียนการสอนและรวบรวมแหล่งอ้างอิงไว้อย่างเหมาะสม | H17: มีการจัดการเรียนการสอนเป็นไปตามประมวลรายวิชาครบถ้วนและการนำเข้าสู่บทเรียนให้ข้อมูลที่เป็นประโยชน์แก่ผู้เรียนครบถ้วน | I17: มีการส่งเสริมให้ผู้เรียนได้ฝึกทักษะการคิดได้อย่างเหมาะสมดีมาก | J17: มีการส่งเสริมให้ผู้เรียนได้ฝึกทักษะการสื่อสารได้อย่างเหมาะสมดีมาก | K17: อาจารย์สอนได้ความรู้ดีมากครับ
A18: 46153.367 | B18: bnco0901@signalschool.ac.th | C18: จ.ส.อ.พัลลภ ดวงเดือน | D18: ลักษณะทางทหาร "ดีมาก" มีความเชื่อมั่นในตนเองเป็นแบบอย่างที่ดีแก่ผู้เรียนได้ | E18: เสียงดังฟังชัดและจังหวะการพูดไม่ช้า/เร็วเกินไป | F18: มีประมวลรายวิชาและแนะนำเนื้อหาวิชา | G18: มีการจัดเตรียมสื่อการเรียนการสอนและรวบรวมแหล่งอ้างอิงไว้อย่างเหมาะสม | H18: มีการจัดการเรียนการสอนเป็นไปตามประมวลรายวิชาครบถ้วนและการนำเข้าสู่บทเรียนให้ข้อมูลที่เป็นประโยชน์แก่ผู้เรียนครบถ้วน | I18: มีการส่งเสริมให้ผู้เรียนได้ฝึกทักษะการคิดได้อย่างเหมาะสมดีมาก | J18: มีการส่งเสริมให้ผู้เรียนได้ฝึกทักษะการสื่อสารได้อย่างเหมาะสม
A19: 46153.367 | B19: bnco0932@signalschool.ac.th | C19: ส.อ. ทศพล จุลดาลัย | D19: ลักษณะทางทหาร "ดีมาก" มีความเชื่อมั่นในตนเองเป็นแบบอย่างที่ดีแก่ผู้เรียนได้ | E19: เสียงดังฟังชัดและจังหวะการพูดไม่ช้า/เร็วเกินไป | F19: มีประมวลรายวิชาและแนะนำเนื้อหาวิชา | G19: มีการจัดเตรียมสื่อการเรียนการสอนและรวบรวมแหล่งอ้างอิงไว้อย่างเหมาะสม | H19: มีการจัดการเรียนการสอนเป็นไปตามประมวลรายวิชาครบถ้วนและการนำเข้าสู่บทเรียนให้ข้อมูลที่เป็นประโยชน์แก่ผู้เรียนครบถ้วน | I19: มีการส่งเสริมให้ผู้เรียนได้ฝึกทักษะการคิดได้อย่างเหมาะสมดีมาก | J19: มีการส่งเสริมให้ผู้เรียนได้ฝึกทักษะการสื่อสารได้อย่างเหมาะสมดีมาก | K19: ขอขอบคุณอาจารย์ที่ได้ถ่ายทอดความรู้ครับ
A20: 46153.367 | B20: bnco0919@signalschool.ac.th | C20: จ.ส.อ.พัลลภ ดวงเดือน | D20: ลักษณะทางทหาร "ดีมาก" มีความเชื่อมั่นในตนเองเป็นแบบอย่างที่ดีแก่ผู้เรียนได้ | E20: เสียงดังฟังชัดและจังหวะการพูดไม่ช้า/เร็วเกินไป | F20: มีประมวลรายวิชาและแนะนำเนื้อหาวิชา | G20: มีการจัดเตรียมสื่อการเรียนการสอนและรวบรวมแหล่งอ้างอิงไว้อย่างเหมาะสม | H20: มีการจัดการเรียนการสอนเป็นไปตามประมวลรายวิชาครบถ้วนและการนำเข้าสู่บทเรียนให้ข้อมูลที่เป็นประโยชน์แก่ผู้เรียนครบถ้วน | I20: มีการส่งเสริมให้ผู้เรียนได้ฝึกทักษะการคิดได้อย่างเหมาะสม | J20: มีการส่งเสริมให้ผู้เรียนได้ฝึกทักษะการสื่อสารได้อย่างเหมาะสม
A21: 46153.367 | B21: bnco0974@signalschool.ac.th | C21: จ.ส.อ.พัลลภ ดวงเดือน | D21: ลักษณะทางทหาร "ดีมาก" มีความเชื่อมั่นในตนเองเป็นแบบอย่างที่ดีแก่ผู้เรียนได้ | E21: เสียงดังฟังชัดและจังหวะการพูดไม่ช้า/เร็วเกินไป | F21: มีประมวลรายวิชาและแนะนำเนื้อหาวิชา | G21: มีการจัดเตรียมสื่อการเรียนการสอนและรวบรวมแหล่งอ้างอิงไว้อย่างเหมาะสม | H21: มีการจัดการเรียนการสอนเป็นไปตามประมวลรายวิชาครบถ้วนและการนำเข้าสู่บทเรียนให้ข้อมูลที่เป็นประโยชน์แก่ผู้เรียนครบถ้วน | I21: มีการส่งเสริมให้ผู้เรียนได้ฝึกทักษะการคิดได้อย่างเหมาะสม | J21: มีการส่งเสริมให้ผู้เรียนได้ฝึกทักษะการสื่อสารได้อย่างเหมาะสม | K21: อาจารย์ใช้คำพูดที่เข้าใจง่าย สอนสนุกครับ เป็นกันเองมากๆ
A22: 46153.367 | B22: bnco0949@signalschool.ac.th | C22: จ.ส.อ.พัลลภ ดวงเดือน | D22: ลักษณะทางทหาร "ดีมาก" มีความเชื่อมั่นในตนเองเป็นแบบอย่างที่ดีแก่ผู้เรียนได้ | E22: เสียงดังฟังชัดและจังหวะการพูดไม่ช้า/เร็วเกินไป | F22: มีประมวลรายวิชาและแนะนำเนื้อหาวิชา | G22: มีการจัดเตรียมสื่อการเรียนการสอนและรวบรวมแหล่งอ้างอิงไว้อย่างเหมาะสม | H22: มีการจัดการเรียนการสอนเป็นไปตามประมวลรายวิชาครบถ้วนและการนำเข้าสู่บทเรียนให้ข้อมูลที่เป็นประโยชน์แก่ผู้เรียนครบถ้วน | I22: มีการส่งเสริมให้ผู้เรียนได้ฝึกทักษะการคิดได้อย่างเหมาะสมดีมาก | J22: มีการส่งเสริมให้ผู้เรียนได้ฝึกทักษะการสื่อสารได้อย่างเหมาะสมดีมาก
A23: 46153.367 | B23: bnco0911@signalschool.ac.th | C23: จ.ส.อ.พัลลภ ดวงเดือน | D23: ลักษณะทางทหาร "ดีมาก" มีความเชื่อมั่นในตนเองเป็นแบบอย่างที่ดีแก่ผู้เรียนได้ | E23: เสียงดังฟังชัดและจังหวะการพูดไม่ช้า/เร็วเกินไป | F23: มีประมวลรายวิชาและแนะนำเนื้อหาวิชา | G23: มีการจัดเตรียมสื่อการเรียนการสอนและรวบรวมแหล่งอ้างอิงไว้อย่างเหมาะสม | H23: มีการจัดการเรียนการสอนเป็นไปตามประมวลรายวิชาครบถ้วนและการนำเข้าสู่บทเรียนให้ข้อมูลที่เป็นประโยชน์แก่ผู้เรียนครบถ้วน | I23: มีการส่งเสริมให้ผู้เรียนได้ฝึกทักษะการคิดได้อย่างเหมาะสมดีมาก | J23: มีการส่งเสริมให้ผู้เรียนได้ฝึกทักษะการสื่อสารได้อย่างเหมาะสมดีมาก
A24: 46153.367 | B24: bnco0965@signalschool.ac.th | C24: จ.ส.อ. พัลลภ ดวงเดือน | D24: ลักษณะทางทหาร "ดีมาก" มีความเชื่อมั่นในตนเองเป็นแบบอย่างที่ดีแก่ผู้เรียนได้ | E24: เสียงดังฟังชัดและจังหวะการพูดไม่ช้า/เร็วเกินไป | F24: มีประมวลรายวิชาและแนะนำเนื้อหาวิชา | G24: มีการจัดเตรียมสื่อการเรียนการสอนและรวบรวมแหล่งอ้างอิงไว้อย่างเหมาะสม | H24: มีการจัดการเรียนการสอนเป็นไปตามประมวลรายวิชาครบถ้วนและการนำเข้าสู่บทเรียนให้ข้อมูลที่เป็นประโยชน์แก่ผู้เรียนครบถ้วน | I24: มีการส่งเสริมให้ผู้เรียนได้ฝึกทักษะการคิดได้อย่างเหมาะสมดีมาก | J24: มีการส่งเสริมให้ผู้เรียนได้ฝึกทักษะการสื่อสารได้อย่างเหมาะสมดีมาก | K24: ขอบคุณครับอาจารย์
A25: 46153.367 | B25: bnco0948@signalschool.ac.th | C25: ส.อ.สุริยา มาลาคำ | D25: ลักษณะทางทหาร "ดีมาก" มีความเชื่อมั่นในตนเองเป็นแบบอย่างที่ดีแก่ผู้เรียนได้ | E25: เสียงดังฟังชัดและจังหวะการพูดไม่ช้า/เร็วเกินไป | F25: มีประมวลรายวิชาและแนะนำเนื้อหาวิชา | G25: มีการจัดเตรียมสื่อการเรียนการสอนและรวบรวมแหล่งอ้างอิงไว้อย่างเหมาะสม | H25: มีการจัดการเรียนการสอนเป็นไปตามประมวลรายวิชาครบถ้วนและการนำเข้าสู่บทเรียนให้ข้อมูลที่เป็นประโยชน์แก่ผู้เรียนครบถ้วน | I25: มีการส่งเสริมให้ผู้เรียนได้ฝึกทักษะการคิดได้อย่างเหมาะสมดีมาก | J25: มีการส่งเสริมให้ผู้เรียนได้ฝึกทักษะการสื่อสารได้อย่างเหมาะสมดีมาก
A26: 46153.367 | B26: bnco0977@signalschool.ac.th | C26: จ.ส.อ. พัลลภ ดวงเดือน, ส.อ. สิทธิศักดิ์ รินไธสง | D26: ลักษณะทางทหาร "ดีมาก" มีความเชื่อมั่นในตนเองเป็นแบบอย่างที่ดีแก่ผู้เรียนได้ | E26: เสียงดังฟังชัดและจังหวะการพูดไม่ช้า/เร็วเกินไป | F26: มีประมวลรายวิชาและแนะนำเนื้อหาวิชา | G26: มีการจัดเตรียมสื่อการเรียนการสอนและรวบรวมแหล่งอ้างอิงไว้อย่างเหมาะสม | H26: มีการจัดการเรียนการสอนเป็นไปตามประมวลรายวิชาครบถ้วนและการนำเข้าสู่บทเรียนให้ข้อมูลที่เป็นประโยชน์แก่ผู้เรียนครบถ้วน | I26: มีการส่งเสริมให้ผู้เรียนได้ฝึกทักษะการคิดได้อย่างเหมาะสมดีมาก | J26: มีการส่งเสริมให้ผู้เรียนได้ฝึกทักษะการสื่อสารได้อย่างเหมาะสมดีมาก
A27: 46153.367 | B27: bnco0960@signalschool.ac.th | C27: จ.ส.อ. พัลลภ ดวงเดือน | D27: ลักษณะทางทหาร "ดีมาก" มีความเชื่อมั่นในตนเองเป็นแบบอย่างที่ดีแก่ผู้เรียนได้ | E27: เสียงดังฟังชัดและจังหวะการพูดไม่ช้า/เร็วเกินไป | F27: มีประมวลรายวิชาและแนะนำเนื้อหาวิชา | G27: มีการจัดเตรียมสื่อการเรียนการสอนและรวบรวมแหล่งอ้างอิงไว้อย่างเหมาะสม | H27: มีการจัดการเรียนการสอนเป็นไปตามประมวลรายวิชาครบถ้วนและการนำเข้าสู่บทเรียนให้ข้อมูลที่เป็นประโยชน์แก่ผู้เรียนครบถ้วน | I27: มีการส่งเสริมให้ผู้เรียนได้ฝึกทักษะการคิดได้อย่างเหมาะสมดีมาก | J27: มีการส่งเสริมให้ผู้เรียนได้ฝึกทักษะการสื่อสารได้อย่างเหมาะสมดีมาก
A28: 46153.367 | B28: bnco0968@signalschool.ac.th | C28: จ.ส.อ.พัลลภ ดวงเดือน | D28: ลักษณะทางทหาร "ดีมาก" มีความเชื่อมั่นในตนเองเป็นแบบอย่างที่ดีแก่ผู้เรียนได้ | E28: เสียงดังฟังชัดและจังหวะการพูดไม่ช้า/เร็วเกินไป | F28: มีประมวลรายวิชาและแนะนำเนื้อหาวิชา | G28: มีการจัดเตรียมสื่อการเรียนการสอนและรวบรวมแหล่งอ้างอิงไว้อย่างเหมาะสม | H28: มีการจัดการเรียนการสอนเป็นไปตามประมวลรายวิชาครบถ้วนและการนำเข้าสู่บทเรียนให้ข้อมูลที่เป็นประโยชน์แก่ผู้เรียนครบถ้วน | I28: มีการส่งเสริมให้ผู้เรียนได้ฝึกทักษะการคิดได้อย่างเหมาะสมดีมาก | J28: มีการส่งเสริมให้ผู้เรียนได้ฝึกทักษะการสื่อสารได้อย่างเหมาะสมดีมาก
A29: 46153.368 | B29: bnco0916@signalschool.ac.th | C29: จ.ส.อ.พัลลพ ดวงเดือน | D29: ลักษณะทางทหาร "ดีมาก" มีความเชื่อมั่นในตนเองเป็นแบบอย่างที่ดีแก่ผู้เรียนได้ | E29: เสียงดังฟังชัดและจังหวะการพูดไม่ช้า/เร็วเกินไป | F29: มีประมวลรายวิชาและแนะนำเนื้อหาวิชา | G29: มีการจัดเตรียมสื่อการเรียนการสอนและรวบรวมแหล่งอ้างอิงไว้อย่างเหมาะสม | H29: มีการจัดการเรียนการสอนเป็นไปตามประมวลรายวิชาครบถ้วนและการนำเข้าสู่บทเรียนให้ข้อมูลที่เป็นประโยชน์แก่ผู้เรียนครบถ้วน | I29: มีการส่งเสริมให้ผู้เรียนได้ฝึกทักษะการคิดได้อย่างเหมาะสมดีมาก | J29: มีการส่งเสริมให้ผู้เรียนได้ฝึกทักษะการสื่อสารได้อย่างเหมาะสมดีมาก
A30: 46153.368 | B30: bnco0903@signalschool.ac.th | C30: จ.ส.อ. พัลลภ ดวงเดือน, ส.อ. สิทธิศักดิ์ รินไธสง | D30: ลักษณะทางทหาร "ดีมาก" มีความเชื่อมั่นในตนเองเป็นแบบอย่างที่ดีแก่ผู้เรียนได้ | E30: เสียงดังฟังชัดและจังหวะการพูดไม่ช้า/เร็วเกินไป | F30: มีประมวลรายวิชาและแนะนำเนื้อหาวิชา | G30: มีการจัดเตรียมสื่อการเรียนการสอนและรวบรวมแหล่งอ้างอิงไว้อย่างเหมาะสม | H30: มีการจัดการเรียนการสอนเป็นไปตามประมวลรายวิชาครบถ้วนและการนำเข้าสู่บทเรียนให้ข้อมูลที่เป็นประโยชน์แก่ผู้เรียนครบถ้วน | I30: มีการส่งเสริมให้ผู้เรียนได้ฝึกทักษะการคิดได้อย่างเหมาะสมดีมาก | J30: มีการส่งเสริมให้ผู้เรียนได้ฝึกทักษะการสื่อสารได้อย่างเหมาะสมดีมาก | K30: อาจารย์สอนไม่กดดันเข้าใจง่ายมากค่ะ
A31: 46153.368 | B31: bnco0933@signalschool.ac.th | C31: จ.ส.อ.พัลลภ ดวงเดือน | D31: ลักษณะทางทหาร "ดีมาก" มีความเชื่อมั่นในตนเองเป็นแบบอย่างที่ดีแก่ผู้เรียนได้ | E31: เสียงดังฟังชัดและจังหวะการพูดไม่ช้า/เร็วเกินไป | F31: มีประมวลรายวิชาและแนะนำเนื้อหาวิชา | G31: มีการจัดเตรียมสื่อการเรียนการสอนและรวบรวมแหล่งอ้างอิงไว้อย่างเหมาะสม | H31: มีการจัดการเรียนการสอนเป็นไปตามประมวลรายวิชาครบถ้วนและการนำเข้าสู่บทเรียนให้ข้อมูลที่เป็นประโยชน์แก่ผู้เรียนครบถ้วน | I31: มีการส่งเสริมให้ผู้เรียนได้ฝึกทักษะการคิดได้อย่างเหมาะสมดีมาก | J31: มีการส่งเสริมให้ผู้เรียนได้ฝึกทักษะการสื่อสารได้อย่างเหมาะสมดีมาก
A32: 46153.368 | B32: bnco0959@signalschool.ac.th | C32: จ.ส.อ.พัลลภ ดวงเดือน | D32: ลักษณะทางทหาร "ดีมาก" มีความเชื่อมั่นในตนเองเป็นแบบอย่างที่ดีแก่ผู้เรียนได้ | E32: เสียงดังฟังชัดและจังหวะการพูดไม่ช้า/เร็วเกินไป | F32: มีประมวลรายวิชาและแนะนำเนื้อหาวิชา | G32: มีการจัดเตรียมสื่อการเรียนการสอนและรวบรวมแหล่งอ้างอิงไว้อย่างเหมาะสม | H32: มีการจัดการเรียนการสอนเป็นไปตามประมวลรายวิชาครบถ้วนและการนำเข้าสู่บทเรียนให้ข้อมูลที่เป็นประโยชน์แก่ผู้เรียนครบถ้วน | I32: มีการส่งเสริมให้ผู้เรียนได้ฝึกทักษะการคิดได้อย่างเหมาะสมดีมาก | J32: มีการส่งเสริมให้ผู้เรียนได้ฝึกทักษะการสื่อสารได้อย่างเหมาะสมดีมาก | K32: การจัดการเรียนการสอนมีการพูดคุยโต้ตอบ สร้างบรรยากาศได้ดีมาก ทำให้กระตุ้นการเรียนรู้และสนุกกับการเรียนครับ
A33: 46153.368 | B33: bnco0921@signalschool.ac.th | C33: จ.ส.อ. พัลลภ ดวงเดือน, ส.อ. สิทธิศักดิ์ รินไธสง | D33: ลักษณะทางทหาร "ดีมาก" มีความเชื่อมั่นในตนเองเป็นแบบอย่างที่ดีแก่ผู้เรียนได้ | E33: เสียงดังฟังชัดและจังหวะการพูดไม่ช้า/เร็วเกินไป | F33: มีประมวลรายวิชาและแนะนำเนื้อหาวิชา | G33: มีการจัดเตรียมสื่อการเรียนการสอนและรวบรวมแหล่งอ้างอิงไว้อย่างเหมาะสม | H33: มีการจัดการเรียนการสอนเป็นไปตามประมวลรายวิชาครบถ้วนและการนำเข้าสู่บทเรียนให้ข้อมูลที่เป็นประโยชน์แก่ผู้เรียนครบถ้วน | I33: มีการส่งเสริมให้ผู้เรียนได้ฝึกทักษะการคิดได้อย่างเหมาะสมดีมาก | J33: มีการส่งเสริมให้ผู้เรียนได้ฝึกทักษะการสื่อสารได้อย่างเหมาะสมดีมาก
A34: 46153.368 | B34: bnco0920@signalschool.ac.th | C34: จ.ส.อ. พัลลภ ดวงเดือน, ส.อ. สิทธิศักดิ์ รินไธสง | D34: ลักษณะทางทหาร "ดีมาก" มีความเชื่อมั่นในตนเองเป็นแบบอย่างที่ดีแก่ผู้เรียนได้ | E34: เสียงดังฟังชัดและจังหวะการพูดไม่ช้า/เร็วเกินไป | F34: มีประมวลรายวิชาและแนะนำเนื้อหาวิชา | G34: มีการจัดเตรียมสื่อการเรียนการสอนและรวบรวมแหล่งอ้างอิงไว้อย่างเหมาะสม | H34: มีการจัดการเรียนการสอนเป็นไปตามประมวลรายวิชาครบถ้วนและการนำเข้าสู่บทเรียนให้ข้อมูลที่เป็นประโยชน์แก่ผู้เรียนครบถ้วน | I34: มีการส่งเสริมให้ผู้เรียนได้ฝึกทักษะการคิดได้อย่างเหมาะสมดีมาก | J34: มีการส่งเสริมให้ผู้เรียนได้ฝึกทักษะการสื่อสารได้อย่างเหมาะสมดีมาก | K34: อาจารย์สอนเข้าใจมาก มีการยกตัวอย่างให้เห็นอย่างชัดเจน สามารถตอบข้อปัญหาข้อสงสัยต่างๆของนักเรียนได้เป็นอย่างดีครับ
A35: 46153.368 | B35: bnco0926@signalschool.ac.th | C35: จ.ส.อ.พัลลภ ดวงเดือน | D35: ลักษณะทางทหาร "ดีมาก" มีความเชื่อมั่นในตนเองเป็นแบบอย่างที่ดีแก่ผู้เรียนได้ | E35: เสียงดังฟังชัดและจังหวะการพูดไม่ช้า/เร็วเกินไป | F35: มีประมวลรายวิชาและแนะนำเนื้อหาวิชา | G35: มีการจัดเตรียมสื่อการเรียนการสอนและรวบรวมแหล่งอ้างอิงไว้อย่างเหมาะสม | H35: มีการจัดการเรียนการสอนเป็นไปตามประมวลรายวิชาครบถ้วนและการนำเข้าสู่บทเรียนให้ข้อมูลที่เป็นประโยชน์แก่ผู้เรียนครบถ้วน | I35: มีการส่งเสริมให้ผู้เรียนได้ฝึกทักษะการคิดได้อย่างเหมาะสมดีมาก | J35: มีการส่งเสริมให้ผู้เรียนได้ฝึกทักษะการสื่อสารได้อย่างเหมาะสมดีมาก
A36: 46153.368 | B36: bnco0973@signalschool.ac.th | C36: จ.ส.อ.พัลลภ ดวงเดือน | D36: ลักษณะทางทหาร "ดีมาก" มีความเชื่อมั่นในตนเองเป็นแบบอย่างที่ดีแก่ผู้เรียนได้ | E36: เสียงดังฟังชัดและจังหวะการพูดไม่ช้า/เร็วเกินไป | F36: มีประมวลรายวิชาและแนะนำเนื้อหาวิชา | G36: มีการจัดเตรียมสื่อการเรียนการสอนและรวบรวมแหล่งอ้างอิงไว้อย่างเหมาะสม | H36: มีการจัดการเรียนการสอนเป็นไปตามประมวลรายวิชาครบถ้วนและการนำเข้าสู่บทเรียนให้ข้อมูลที่เป็นประโยชน์แก่ผู้เรียนครบถ้วน | I36: มีการส่งเสริมให้ผู้เรียนได้ฝึกทักษะการคิดได้อย่างเหมาะสมดีมาก | J36: มีการส่งเสริมให้ผู้เรียนได้ฝึกทักษะการสื่อสารได้อย่างเหมาะสมดีมาก
A37: 46153.368 | B37: bnco0966@signalschool.ac.th | C37: จ.ส.อ.พัลลภ ดวงเดือน, ส.อ.สิทธิศักดิ์ รินไธสง | D37: ลักษณะทางทหาร "ดีมาก" มีความเชื่อมั่นในตนเองเป็นแบบอย่างที่ดีแก่ผู้เรียนได้ | E37: เสียงดังฟังชัดและจังหวะการพูดไม่ช้า/เร็วเกินไป | F37: มีประมวลรายวิชาและแนะนำเนื้อหาวิชา | G37: มีการจัดเตรียมสื่อการเรียนการสอนและรวบรวมแหล่งอ้างอิงไว้อย่างเหมาะสม | H37: มีการจัดการเรียนการสอนเป็นไปตามประมวลรายวิชาครบถ้วนและการนำเข้าสู่บทเรียนให้ข้อมูลที่เป็นประโยชน์แก่ผู้เรียนครบถ้วน | I37: มีการส่งเสริมให้ผู้เรียนได้ฝึกทักษะการคิดได้อย่างเหมาะสมดีมาก | J37: มีการส่งเสริมให้ผู้เรียนได้ฝึกทักษะการสื่อสารได้อย่างเหมาะสมดีมาก
A38: 46153.368 | B38: bnco0953@signalschool.ac.th | C38: ส.อ.จารุเดช เปรมจิตต์ | D38: ลักษณะทางทหาร "ดีมาก" มีความเชื่อมั่นในตนเองเป็นแบบอย่างที่ดีแก่ผู้เรียนได้ | E38: เสียงดังฟังชัดและจังหวะการพูดไม่ช้า/เร็วเกินไป | F38: มีประมวลรายวิชาและแนะนำเนื้อหาวิชา | G38: มีการจัดเตรียมสื่อการเรียนการสอนและรวบรวมแหล่งอ้างอิงไว้อย่างเหมาะสม | H38: มีการจัดการเรียนการสอนเป็นไปตามประมวลรายวิชาครบถ้วนและการนำเข้าสู่บทเรียนให้ข้อมูลที่เป็นประโยชน์แก่ผู้เรียนครบถ้วน | I38: มีการส่งเสริมให้ผู้เรียนได้ฝึกทักษะการคิดได้อย่างเหมาะสมดีมาก | J38: มีการส่งเสริมให้ผู้เรียนได้ฝึกทักษะการสื่อสารได้อย่างเหมาะสม
A39: 46153.368 | B39: bnco0976@signalschool.ac.th | C39: ส.อ.ธนากร ศรีน้อย | D39: ลักษณะทางทหาร "ดีมาก" มีความเชื่อมั่นในตนเองเป็นแบบอย่างที่ดีแก่ผู้เรียนได้ | E39: เสียงดังฟังชัดและจังหวะการพูดไม่ช้า/เร็วเกินไป | F39: มีประมวลรายวิชาและแนะนำเนื้อหาวิชา | G39: มีการจัดเตรียมสื่อการเรียนการสอนและรวบรวมแหล่งอ้างอิงไว้อย่างเหมาะสม | H39: มีการจัดการเรียนการสอนเป็นไปตามประมวลรายวิชาครบถ้วนและการนำเข้าสู่บทเรียนให้ข้อมูลที่เป็นประโยชน์แก่ผู้เรียนครบถ้วน | I39: มีการส่งเสริมให้ผู้เรียนได้ฝึกทักษะการคิดได้อย่างเหมาะสมดีมาก | J39: มีการส่งเสริมให้ผู้เรียนได้ฝึกทักษะการสื่อสารได้อย่างเหมาะสมดีมาก
A40: 46153.368 | B40: bnco0944@signalschool.ac.th | C40: จ.ส.อ.พัลลภ ดวงเดือน | D40: ลักษณะทางทหาร "ดีมาก" มีความเชื่อมั่นในตนเองเป็นแบบอย่างที่ดีแก่ผู้เรียนได้ | E40: เสียงดังฟังชัดและจังหวะการพูดไม่ช้า/เร็วเกินไป | F40: มีประมวลรายวิชาและแนะนำเนื้อหาวิชา | G40: มีการจัดเตรียมสื่อการเรียนการสอนและรวบรวมแหล่งอ้างอิงไว้อย่างเหมาะสม | H40: มีการจัดการเรียนการสอนเป็นไปตามประมวลรายวิชาครบถ้วนและการนำเข้าสู่บทเรียนให้ข้อมูลที่เป็นประโยชน์แก่ผู้เรียนครบถ้วน | I40: มีการส่งเสริมให้ผู้เรียนได้ฝึกทักษะการคิดได้อย่างเหมาะสมดีมาก | J40: มีการส่งเสริมให้ผู้เรียนได้ฝึกทักษะการสื่อสารได้อย่างเหมาะสมดีมาก
A41: 46153.368 | B41: bnco0922@signalschool.ac.th | C41: จ.ส.อ.พัลลภ ดวงเดือน | D41: ลักษณะทางทหาร "ดีมาก" มีความเชื่อมั่นในตนเองเป็นแบบอย่างที่ดีแก่ผู้เรียนได้ | E41: เสียงดังฟังชัดและจังหวะการพูดไม่ช้า/เร็วเกินไป | F41: มีประมวลรายวิชาและแนะนำเนื้อหาวิชา | G41: มีการจัดเตรียมสื่อการเรียนการสอนและรวบรวมแหล่งอ้างอิงไว้อย่างเหมาะสม | H41: มีการจัดการเรียนการสอนเป็นไปตามประมวลรายวิชาครบถ้วนและการนำเข้าสู่บทเรียนให้ข้อมูลที่เป็นประโยชน์แก่ผู้เรียนครบถ้วน | I41: มีการส่งเสริมให้ผู้เรียนได้ฝึกทักษะการคิดได้อย่างเหมาะสมดีมาก | J41: มีการส่งเสริมให้ผู้เรียนได้ฝึกทักษะการสื่อสารได้อย่างเหมาะสมดีมาก | K41: -
...

Sheet ค่า 1.2
A1: ประทับเวลา | B1: ที่อยู่อีเมล | C1: ยศ ชื่อ-สกุล ครู-อาจารย์ผู้สอน | E1: 1. บุคลิกภาพและลักษณะท่าทางของอาจารย์ผู้สอน | F1: 2. การพูดและการใช้นํ้าเสียง | G1: 3. การเตรียมการสอน | H1: 4. การจัดเตรียมสื่อการสอน | I1: 5. การถ่ายทอดความรู้และการนำเข้าสู่บทเรียน | J1: 6. ผู้เรียนได้ฝึกทักษะการคิดวิเคราะห์ หรือการพัฒนาความคิดสร้างสรรค์จากการเรียนรายวิชานี้มากน้อยเพียงใด | K1: 7. ผู้เรียนได้ฝึกทักษะการสื่อสาร การนำเสนอ และการใช้งานเทคโนโลยีสารสนเทศจากการเรียนรายวิชานี้มากน้อยเพียงใด | M1: ตรวจสอบผู้เข้าประเมิน
